Workbook

Sheet OCT2012
C1: Amount | L1: Amount | M1: UNCLAIMED
A2: Numbers | C2: sold | L2: left | M2: =SUM(L6:L80) -> 585
C3: =SUM(C6:C80) -> 17750 | L3: =SUM(L6:L79) -> 585 | M3: =SUM(L3/C3) -> 0.032957746
B4: Unit | C4: Sales | J4: Service(s) | K4: Value | O4: Customer | P4: Phone
A5: No | B5: Price | C5: Price | D5: (USED) | J5: left | K5: left | L5: Value amount left | M5: issued on | N5: expires at | O5: Name | Q5: e-mail
A6: 335 | B6: 45 | C6: 225 | D6: 0 | E6: 0 | F6: 0 | G6: 0 | H6: 0 | I6: 1 | J6: =SUM(D6:I6) -> 1 | K6: =SUM(J6-1) -> 0 | L6: =SUM(K6*B6) -> 0 | M6: Oct 20/12 | N6: Oct 20/14
A7: 355 | B7: 100 | C7: 100 | D7: 0 | J7: =SUM(D7:I7) -> 0 | K7: 0 | L7: =SUM(K7*B7) -> 0 | M7: Oct 20/12 | N7: Oct 20/14 | Q7: Finished
A8: 354 | B8: 60 | C8: 300 | D8: 0 | E8: 0 | F8: 0 | G8: 0 | H8: 0 | I8: 1 | J8: =SUM(D8:I8) -> 1 | K8: =SUM(J8-1) -> 0 | L8: =SUM(K8*B8) -> 0 | M8: Oct 20/12 | N8: Oct 20/14 | Q8: lost
A9: 478 | B9: 50 | C9: 250 | D9: 0 | E9: 0 | F9: 0 | G9: 0 | H9: 0 | I9: 0 | J9: =SUM(D9:I9) -> 0 | K9: 0 | L9: =SUM(K9*B9) -> 0 | M9: Oct 25/12 | N9: Oct 25/14
A10: 499 | B10: 45 | C10: 225 | D10: 0 | E10: 0 | F10: 0 | G10: 0 | H10: 1 | I10: 1 | J10: =SUM(D10:I10) -> 2 | K10: =SUM(J10-1) -> 1 | L10: =SUM(K10*B10) -> 45 | M10: Oct 26/12 | N10: Oct 26/14
A11: 609 | B11: 60 | C11: 300 | D11: 0 | E11: 0 | F11: 0 | G11: 0 | H11: 0 | I11: 0 | J11: =SUM(D11:I11) -> 0 | K11: 0 | L11: =SUM(K11*B11) -> 0 | M11: Oct 26/12 | N11: Oct 26/14
A12: 709(120002) | B12: 45 | C12: 225 | D12: 0 | E12: 0 | F12: 0 | G12: 0 | H12: 0 | I12: 0 | J12: =SUM(D12:I12) -> 0 | K12: 0 | L12: =SUM(K12*B12) -> 0 | M12: Oct 28/12 | N12: Oct 28/14
A13: 120001 | D13: S | E13: A | F13: M | G13: P | H13: L | I13: E | K13: 0 | L13: =SUM(K13*B13) -> 0
A14: 120003 | B14: 60 | C14: 300 | D14: 0 | E14: 0 | F14: 0 | G14: 0 | H14: 0 | I14: 0 | J14: =SUM(D14:I14) -> 0 | K14: 0 | L14: =SUM(K14*B14) -> 0 | M14: Oct 29/12 | N14: Oct 29/14
A15: 120004 | B15: 45 | C15: 225 | D15: 0 | E15: 0 | F15: 0 | G15: 0 | H15: 0 | I15: 0 | J15: =SUM(D15:I15) -> 0 | K15: 0 | L15: =SUM(K15*B15) -> 0 | M15: Oct 29/12 | N15: Oct 29/14
A16: 120005 | B16: 45 | C16: 225 | D16: 0 | E16: 0 | F16: 0 | G16: 0 | H16: 0 | I16: 0 | J16: =SUM(D16:I16) -> 0 | K16: 0 | L16: =SUM(K16*B16) -> 0 | M16: Oct 29/12 | N16: Oct 29/14 | O16: R8 | P16: Alex
A17: 120006 | B17: 45 | C17: 225 | D17: 0 | E17: 0 | F17: 0 | G17: 0 | H17: 0 | I17: 0 | J17: =SUM(D17:I17) -> 0 | K17: 0 | L17: =SUM(K17*B17) -> 0 | M17: Oct 29/12 | N17: Oct 29/14 | O17: C68 | P17: Daniel
A18: 120007 | B18: 60 | C18: 300 | D18: 0 | E18: 0 | F18: 0 | G18: 0 | H18: 0 | I18: 0 | J18: =SUM(D18:I18) -> 0 | K18: 0 | L18: =SUM(K18*B18) -> 0 | M18: Oct 29/12 | N18: Oct 29/14
A19: 120008 | B19: 45 | C19: 225 | D19: 0 | E19: 0 | F19: 0 | G19: 0 | H19: 0 | I19: 1 | J19: =SUM(D19:I19) -> 1 | K19: =SUM(J19-1) -> 0 | L19: =SUM(K19*B19) -> 0 | M19: Oct 30/12 | N19: Oct 30/14 | Q19: =SUM(C6:C19) -> 3125 | R19: 13장+Sample 1장 | S19: 10월 합계
A20: 120009 | B20: 80 | C20: 400 | D20: 0 | E20: 0 | F20: 0 | G20: 0 | H20: 0 | I20: 0 | J20: =SUM(D20:I20) -> 0 | K20: 0 | L20: =SUM(K20*B20) -> 0 | M20: Nov 01/12 | N20: Nov 01/14
A21: 120010 | B21: COMP | G21: 0 | H21: 0 | I21: 1 | J21: =SUM(G21:I21) -> 1 | K21: 0 | L21: 0 | M21: Nov 01/12 | N21: Nov 01/14 | O21: Dent damage | P21: 권부장
A22: 120012 | B22: 45 | C22: 225 | D22: 0 | E22: 0 | F22: 0 | G22: 0 | H22: 0 | I22: 0 | J22: 0 | K22: 0 | L22: =SUM(K22*B22) -> 0 | M22: Nov 02/12 | N22: Nov 02/14
A23: 120013 | B23: 60 | C23: =B23*5 -> 300 | D23: 0 | E23: 0 | F23: 0 | G23: 0 | H23: 0 | I23: 0 | J23: =SUM(D23:I23) -> 0 | K23: 0 | L23: =SUM(K23*B23) -> 0 | M23: Nov 02/12 | N23: Nov 02/14
A24: 120011 | B24: 45 | C24: =B24*5 -> 225 | D24: 0 | E24: 0 | F24: 0 | G24: 1 | H24: 1 | I24: 1 | J24: =SUM(D24:I24) -> 3 | K24: =SUM(J24-1) -> 2 | L24: =SUM(K24*B24) -> 90 | M24: Nov 02/12 | N24: Nov 02/14
A25: 120014 | B25: 45 | C25: 225 | D25: 0 | E25: 0 | F25: 0 | G25: 0 | H25: 0 | I25: 0 | J25: =SUM(D25:I25) -> 0 | K25: 0 | L25: =SUM(K25*B25) -> 0 | M25: Nov 02/12 | N25: Nov 02/14
A26: 120015 | B26: 60 | C26: 300 | D26: 0 | E26: 0 | F26: 0 | G26: 0 | H26: 0 | I26: 1 | J26: =SUM(D26:I26) -> 1 | K26: =SUM(J26-1) -> 0 | L26: =SUM(K26*B26) -> 0 | M26: Nov 04/12 | N26: Nov 04/14
A27: 120016 | B27: 40 | C27: 200 | D27: 0 | E27: 0 | F27: 0 | G27: 0 | H27: 0 | I27: 0 | J27: =SUM(D27:I27) -> 0 | K27: 0 | L27: =SUM(K27*B27) -> 0 | M27: Nov 04/12 | N27: Nov 04/14
A28: 120017 | B28: 45 | C28: 225 | D28: 0 | E28: 0 | F28: 0 | G28: 0 | H28: 0 | I28: 0 | J28: =SUM(G28:I28) -> 0 | K28: 0 | L28: 0 | M28: Nov 04/12 | N28: Nov 04/14
A29: 120018 | B29: 60 | C29: 300 | D29: 0 | E29: 0 | F29: 0 | G29: 0 | H29: 0 | I29: 0 | J29: =SUM(D29:I29) -> 0 | K29: 0 | L29: =SUM(K29*B29) -> 0 | M29: Nov 05/12 | N29: Nov 05/14
A30: 120019 | B30: 60 | C30: 300 | D30: 0 | E30: 0 | F30: 0 | G30: 1 | H30: 1 | I30: 1 | J30: =SUM(D30:I30) -> 3 | K30: =SUM(J30-1) -> 2 | L30: =SUM(K30*B30) -> 120 | M30: Nov 05/12 | N30: Nov 05/14
A31: 120020 | C31: 525 | J31: =SUM(D31:I31) -> 0 | K31: 0 | L31: =SUM(K31*B31) -> 0 | M31: Nov. 08/12 | N31: Feb 08/13 | O31: Chris MULTI-DLX, 1 BUFF
A32: 120021 | B32: 45 | C32: 225 | D32: 0 | E32: 1 | F32: 1 | G32: 1 | H32: 1 | I32: 1 | J32: =SUM(D32:I32) -> 5 | K32: =SUM(J32-1) -> 4 | L32: =SUM(K32*B32) -> 180 | M32: Nov 08/12 | N32: Nov 08/14 | O32: 분실/회수 | Q32: 우편물로 GV만 배달 11/02/13
A33: 120022 | B33: 50 | C33: 250 | D33: 0 | E33: 0 | F33: 0 | G33: 0 | H33: 0 | I33: 0 | J33: =SUM(D33:I33) -> 0 | K33: 0 | L33: =SUM(K33*B33) -> 0 | M33: Nov 08/12 | N33: Nov 08/14
A34: 120023 | B34: 35 | C34: 175 | D34: 0 | E34: 0 | F34: 0 | G34: 0 | H34: 0 | I34: 0 | J34: =SUM(D34:I34) -> 0 | K34: 0 | L34: =SUM(K34*B34) -> 0 | M34: Nov 08/12 | N34: Nov 08/14
A35: 120024 | B35: 45 | C35: 225 | D35: 0 | E35: 0 | F35: 0 | G35: 0 | H35: 0 | I35: 0 | J35: =SUM(D35:I35) -> 0 | K35: 0 | L35: =SUM(K35*B35) -> 0 | M35: Nov 08/12 | N35: Nov 08/14
A36: 120025 | B36: 50 | C36: 250 | D36: 0 | E36: 0 | F36: 0 | G36: 0 | H36: 0 | I36: 0 | J36: =SUM(D36:I36) -> 0 | K36: 0 | L36: =SUM(K36*B36) -> 0 | M36: Nov 09/12 | N36: Nov 09/14 | O36: Audi
A37: 120026 | B37: 45 | C37: 225 | D37: 0 | E37: 0 | F37: 0 | G37: 0 | H37: 0 | I37: 0 | J37: =SUM(D37:I37) -> 0 | K37: 0 | L37: =SUM(K37*B37) -> 0 | M37: Nov 10/12 | N37: Nov 10/14 | O37: MICHELLE | P37: 8078 6047 | Q37: michelleb@eapro.com.au
A38: 120027 | B38: 45 | C38: 225 | D38: 0 | E38: 0 | F38: 0 | G38: 0 | H38: 0 | I38: 0 | J38: =SUM(D38:I38) -> 0 | K38: 0 | L38: =SUM(K38*B38) -> 0 | M38: Nov 10/12 | N38: Nov 10/14 | O38: 한국부부
A39: 120028 | B39: 50 | C39: 250 | D39: 0 | E39: 0 | F39: 0 | G39: 0 | H39: 0 | I39: 1 | J39: =SUM(D39:I39) -> 1 | K39: =SUM(J39-1) -> 0 | L39: =SUM(K39*B39) -> 0 | M39: Nov 10/12 | N39: Nov 10/14 | O39: HELEN
A40: 120029 | B40: 45 | C40: 225 | D40: 0 | E40: 0 | F40: 0 | G40: 0 | H40: 0 | I40: 0 | J40: =SUM(D40:I40) -> 0 | K40: 0 | L40: =SUM(K40*B40) -> 0 | M40: Nov 10/12 | N40: Nov 10/14 | O40: HELEN
...

Sheet 2013
C1: Amount | L1: Amount | M1: UNCLAIMED
A2: Numbers | C2: sold | L2: Unclaimed | M2: Percentage
C3: =SUM(C7:C245) -> 52043 | L3: =SUM(L7:L245) -> 2040 | M3: =L3/C3 -> 0.039198355
B4: Unit | C4: Sales | J4: Service(s) | K4: Value | O4: Customer | P4: Phone
A5: No | B5: Price | C5: Price | D5: (USED) | J5: left | K5: left | L5: Value amount left | M5: issued on | N5: expires at | O5: Name | Q5: e-mail
A6: 2013년
A7: 120070 | B7: 45 | C7: =SUM(B7*5) -> 225 | D7: 0 | E7: 0 | F7: 0 | G7: 0 | H7: 0 | I7: 0 | J7: =SUM(D7:I7) -> 0 | K7: 0 | L7: =K7*B7 -> 0 | M7: JAN 09/13 | N7: JAN 09/15
A8: 120071 | B8: 45 | C8: =SUM(B8*5) -> 225 | D8: 0 | E8: 0 | F8: 0 | G8: 0 | H8: 0 | I8: 0 | J8: =SUM(D8:I8) -> 0 | K8: 0 | L8: =K8*B8 -> 0 | M8: JAN 12/13 | N8: JAN 12/15
A9: 120072 | B9: 45 | C9: =SUM(B9*5) -> 225 | D9: 0 | E9: 0 | F9: 0 | G9: 0 | H9: 1 | I9: 1 | J9: =SUM(D9:I9) -> 2 | K9: =J9-1 -> 1 | L9: =SUM(K9*B9) -> 45 | M9: JAN 12/13 | N9: JAN 12/15
A10: 120073 | B10: 45 | C10: =SUM(B10*5) -> 225 | D10: 0 | E10: 0 | F10: 0 | G10: 0 | H10: 1 | I10: 1 | J10: =SUM(D10:I10) -> 2 | K10: =J10-1 -> 1 | L10: =SUM(K10*B10) -> 45 | M10: JAN 12/13 | N10: JAN 12/15
A11: 120074 | B11: 45 | C11: =SUM(B11*5) -> 225 | D11: 0 | E11: 0 | F11: 0 | G11: 0 | H11: 0 | I11: 1 | J11: =SUM(D11:I11) -> 1 | K11: =J11-1 -> 0 | L11: =SUM(B11*K11) -> 0 | M11: JAN 15/13 | N11: JAN 15/15
A12: 120075 | B12: 45 | C12: =SUM(B12*5) -> 225 | D12: 0 | E12: 0 | F12: 0 | G12: 0 | H12: 0 | I12: 0 | J12: =SUM(D12:I12) -> 0 | K12: 0 | L12: =SUM(B12*K12) -> 0 | M12: JAN 24/13 | N12: JAN 24/15 | O12: Diana
A13: 120076 | B13: 45 | C13: =SUM(B13*5) -> 225 | D13: 0 | E13: 0 | F13: 0 | G13: 0 | H13: 0 | I13: 0 | J13: =SUM(D13:I13) -> 0 | K13: 0 | L13: =SUM(B13*K13) -> 0 | M13: JAN 17/13 | N13: JAN 17/15
A14: 120077 | C14: 938 | J14: =SUM(D14:I14) -> 0 | K14: 0 | L14: 0 | M14: JAN 19/13 | N14: JUL 19/13 | O14: Bob
A15: 120078 | B15: 60 | C15: =SUM(B15*5) -> 300 | D15: 0 | E15: 0 | F15: 0 | G15: 0 | H15: 0 | I15: 0 | J15: =SUM(D15:I15) -> 0 | K15: 0 | L15: =SUM(B15*K15) -> 0 | M15: JAN 19/13 | N15: JAN 19/15
A16: 120079 | B16: 60 | C16: =SUM(B16*5) -> 300 | D16: 0 | E16: 0 | F16: 0 | G16: 0 | H16: 0 | I16: 0 | J16: =SUM(D16:I16) -> 0 | K16: 0 | L16: 0 | M16: JAN 20/13 | N16: JAN 20/15
A17: 130001 | B17: 45 | C17: =SUM(B17*5) -> 225 | D17: 0 | E17: 0 | F17: 0 | G17: 0 | H17: 0 | I17: 0 | J17: =SUM(D17:I17) -> 0 | K17: 0 | L17: =SUM(B17*K17) -> 0 | M17: JAN 20/13 | N17: JAN 20/15
A18: 130002 | B18: 50 | C18: =SUM(B18*5) -> 250 | D18: 0 | E18: 0 | F18: 0 | G18: 0 | H18: 0 | I18: 0 | J18: =SUM(D18:I18) -> 0 | K18: 0 | L18: =SUM(B18*K18) -> 0 | M18: JAN 22/13 | N18: JAN 22/15 | O18: May
A19: 130003 | B19: COMP. | J19: =SUM(D19:I19) -> 0 | K19: 0 | L19: 0 | M19: JAN 22/13 | N19: JAN 22/15 | O19: Mark
A20: 130004 | B20: 45 | C20: =SUM(B20*5) -> 225 | D20: 0 | E20: 0 | F20: 0 | G20: 0 | H20: 0 | I20: 0 | J20: =SUM(D20:I20) -> 0 | K20: 0 | L20: =SUM(B20*K20) -> 0 | M20: JAN 29/13 | N20: JAN 29/15 | S20: 1월 합계 | T20: 14장
A21: 130005 | B21: GA 불출 | J21: =SUM(D21:I21) -> 0 | K21: 0 | L21: 0
A22: 130006 | B22: GA 불출 | J22: =SUM(D22:I22) -> 0 | K22: 0 | L22: 0
A23: 130007 | B23: GA 불출 | J23: =SUM(D23:I23) -> 0 | K23: 0 | L23: 0
A24: 130008 | B24: GA 불출 | J24: =SUM(D24:I24) -> 0 | K24: 0 | L24: 0
A25: 130009 | B25: GA 불출 | J25: =SUM(D25:I25) -> 0 | K25: 0 | L25: 0
A26: 130010 | B26: GA 불출 | J26: =SUM(D26:I26) -> 0 | K26: 0 | L26: 0
A27: 130011 | B27: 45 | C27: =SUM(B27*5) -> 225 | D27: 0 | E27: 0 | F27: 0 | G27: 0 | H27: 0 | I27: 0 | J27: =SUM(D27:I27) -> 0 | K27: 0 | L27: =SUM(B27*K27) -> 0 | M27: FEB 04/13 | N27: FEB 04/15 | O27: LEX 1SERI | Q27: 12//12 | R27: 24/02현재
A28: 130012 | B28: 45 | C28: =SUM(B28*5) -> 225 | D28: 0 | E28: 0 | F28: 0 | G28: 0 | H28: 0 | I28: 0 | J28: =SUM(D28:I28) -> 0 | K28: 0 | L28: 0 | M28: FEB 07/13 | N28: FEB 07/15 | O28: beatle yellow | Q28: korean girl
A29: 130013 | B29: 60 | C29: =SUM(B29*5) -> 300 | D29: 0 | E29: 0 | F29: 0 | G29: 0 | H29: 0 | I29: 0 | J29: =SUM(D29:I29) -> 0 | K29: 0 | L29: =SUM(B29*K29) -> 0 | M29: FEB 09/13 | N29: FEB 09/15
A30: 130014 | B30: 45 | C30: =SUM(B30*5) -> 225 | D30: 0 | E30: 0 | F30: 0 | G30: 0 | H30: 0 | I30: 0 | J30: =SUM(D30:I30) -> 0 | K30: 0 | L30: =SUM(B30*K30) -> 0 | M30: FEB 11/13 | N30: FEB 11/15 | O30: Mits red | Q30: Indian lady
A31: 130015 | B31: 50 | C31: =SUM(B31*5) -> 250 | D31: 0 | E31: 0 | F31: 0 | G31: 0 | H31: 0 | I31: 0 | J31: =SUM(D31:I31) -> 0 | K31: 0 | L31: =SUM(B31*K31) -> 0 | M31: FEB 15/13 | N31: FEB 15/15 | O31: Merc silver | Q31: Aus lady
A32: 130016 | B32: 45 | C32: =SUM(B32*5) -> 225 | D32: 0 | E32: 0 | F32: 0 | G32: 0 | H32: 0 | I32: 0 | J32: =SUM(D32:I32) -> 0 | K32: 0 | L32: =SUM(B32*K32) -> 0 | M32: FEB 19/13 | N32: FEB 19/15 | O32: R8 | Q32: Alex
A33: 130017 | B33: 45 | C33: =SUM(B33*5) -> 225 | D33: 0 | E33: 0 | F33: 0 | G33: 0 | H33: 0 | I33: 0 | J33: =SUM(D33:I33) -> 0 | K33: 0 | L33: =SUM(B33*K33) -> 0 | M33: FEB 19/13 | N33: FEB 19/15
A34: 130018 | B34: 45 | C34: =SUM(B34*5) -> 225 | D34: 0 | E34: 0 | F34: 0 | G34: 0 | H34: 0 | I34: 0 | J34: =SUM(D34:I34) -> 0 | K34: 0 | L34: =SUM(B34*K34) -> 0 | M34: FEB 24/13 | N34: FEB 24/15
A35: 130019 | B35: 50 | C35: =SUM(B35*5) -> 250 | D35: 0 | E35: 0 | F35: 0 | G35: 0 | H35: 0 | I35: 0 | J35: =SUM(D35:I35) -> 0 | K35: 0 | L35: =SUM(B35*K35) -> 0 | M35: FEB 25/13 | N35: FEB 25/15 | O35: White MZD
A36: 130020 | B36: 45 | C36: =SUM(B36*5) -> 225 | D36: 0 | E36: 0 | F36: 0 | G36: 0 | H36: 0 | I36: 0 | J36: =SUM(D36:I36) -> 0 | K36: 0 | L36: =SUM(B36*K36) -> 0 | M36: FEB 27/13 | N36: FEB 27/15 | O36: Gray Merc. | Q36: Janus Wong | S36: 2월 합계 | T36: 16장
A37: 130021 | B37: 60 | C37: =SUM(B37*5) -> 300 | D37: 0 | E37: 0 | F37: 0 | G37: 0 | H37: 0 | I37: 0 | J37: =SUM(D37:I37) -> 0 | K37: 0 | L37: =SUM(B37*K37) -> 0 | M37: MAR01/13 | N37: MAR01/15
A38: 130022 | B38: 45 | C38: =SUM(B38*5) -> 225 | D38: 0 | E38: 0 | F38: 0 | G38: 0 | H38: 1 | I38: 1 | J38: =SUM(D38:I38) -> 2 | K38: =J38-1 -> 1 | L38: =SUM(B38*K38) -> 45 | M38: MAR03/13 | N38: MAR03/15
A39: 130023 | B39: 45 | C39: =SUM(B39*5) -> 225 | D39: 0 | E39: 0 | F39: 0 | G39: 0 | H39: 0 | I39: 0 | J39: =SUM(D39:I39) -> 0 | K39: 0 | L39: =SUM(B39*K39) -> 0 | M39: MAR03/13 | N39: MAR03/15
A40: 130024 | B40: 45 | C40: =SUM(B40*5) -> 225 | D40: 0 | E40: 0 | F40: 0 | G40: 0 | H40: 0 | I40: 1 | J40: =SUM(D40:I40) -> 1 | K40: =J40-1 -> 0 | L40: =SUM(B40*K40) -> 0 | M40: MAR04/13 | N40: MAR04/15 | O40: blue bmw
...

Sheet 2014
C1: Amount | L1: Amount | N1: UNCLAIMED
A2: Numbers | C2: sold | L2: Unclaimed | N2: Percentage
C3: =SUM(C7:C305) -> 71420 | L3: =SUM(L7:L305) -> 4740 | N3: =L3/C3 -> 0.066367964
A4: No | B4: Unit | C4: Sales | J4: Service(s) | K4: Value | L4: $ | M4: issued on | N4: expires at | O4: Customer | P4: Phone | Q4: e-mail
B5: Price | C5: Price | D5: (USED) | J5: left | K5: left | L5: left | O5: Name
A6: JAN - JUN 2014
A7: 140231 | B7: 60 | C7: =SUM(B7*5) -> 300 | D7: 0 | E7: 0 | F7: 0 | G7: 0 | H7: 0 | I7: 0 | J7: =SUM(D7:I7) -> 0 | K7: =SUM(D7:H7) -> 0 | L7: =B7*K7 -> 0 | M7: JAN 02/14 | N7: JAN 02/16
A8: 140232 | B8: 60 | C8: =SUM(B8*5) -> 300 | D8: 0 | E8: 0 | F8: 0 | G8: 0 | H8: 0 | I8: 1 | J8: =SUM(D8:I8) -> 1 | K8: =SUM(D8:H8) -> 0 | L8: =B8*K8 -> 0 | M8: JAN 02/14 | N8: JAN 02/16
A9: 140233 | B9: 45 | C9: =SUM(B9*5) -> 225 | D9: 0 | E9: 0 | F9: 0 | G9: 0 | H9: 0 | I9: 0 | J9: =SUM(D9:I9) -> 0 | K9: =SUM(D9:H9) -> 0 | L9: =B9*K9 -> 0 | M9: JAN 05/14 | N9: JAN 05/16
A10: 140234 | B10: 45 | C10: =SUM(B10*5) -> 225 | D10: 0 | E10: 0 | F10: 0 | G10: 0 | H10: 0 | I10: 0 | J10: =SUM(D10:I10) -> 0 | K10: =SUM(D10:H10) -> 0 | L10: =B10*K10 -> 0 | M10: JAN 05/14 | N10: JAN 05/16
A11: 140235 | B11: 45 | C11: =SUM(B11*5) -> 225 | D11: 0 | E11: 0 | F11: 0 | G11: 0 | H11: 0 | I11: 0 | J11: =SUM(D11:I11) -> 0 | K11: =SUM(D11:H11) -> 0 | L11: =B11*K11 -> 0 | M11: JAN 12/14 | N11: JAN 12/16
A12: 140236 | B12: 90 | C12: 90 | I12: 0 | J12: =SUM(D12:I12) -> 0 | K12: =SUM(D12:H12) -> 0 | L12: =B12*K12 -> 0 | M12: JAN 15/14 | N12: JAN 15/16 | O12: HP FOR 1
A13: 140237 | B13: 45 | C13: =SUM(B13*5) -> 225 | D13: 0 | E13: 0 | F13: 0 | G13: 0 | H13: 0 | I13: 0 | J13: =SUM(D13:I13) -> 0 | K13: =SUM(D13:H13) -> 0 | L13: =B13*K13 -> 0 | M13: JAN 18/14 | N13: JAN 18/16
A14: 140238 | B14: 45 | C14: =SUM(B14*5) -> 225 | D14: 0 | E14: 0 | F14: 0 | G14: 0 | H14: 0 | I14: 0 | J14: =SUM(D14:I14) -> 0 | K14: =SUM(D14:H14) -> 0 | L14: =B14*K14 -> 0 | M14: JAN 19/14 | N14: JAN 19/16
A15: 140239 | B15: 45 | C15: =SUM(B15*5) -> 225 | D15: 0 | E15: 0 | F15: 0 | G15: 0 | H15: 0 | I15: 0 | J15: =SUM(D15:I15) -> 0 | K15: =SUM(D15:H15) -> 0 | L15: =B15*K15 -> 0 | M15: JAN 23/14 | N15: JAN 23/16 | O15: 0/7
A16: 140240 | B16: 45 | C16: =SUM(B16*5) -> 225 | D16: 0 | E16: 0 | F16: 0 | G16: 0 | H16: 0 | I16: 0 | J16: =SUM(D16:I16) -> 0 | K16: =SUM(D16:H16) -> 0 | L16: =B16*K16 -> 0 | M16: JAN 25/14 | N16: JAN 25/16
A17: 140241 | B17: 45 | C17: =SUM(B17*5) -> 225 | D17: 0 | E17: 0 | F17: 1 | G17: 1 | H17: 1 | I17: 1 | J17: =SUM(D17:I17) -> 4 | K17: =SUM(D17:H17) -> 3 | L17: =B17*K17 -> 135 | M17: JAN 27/14 | N17: JAN 27/16
A18: 140242 | B18: 60 | C18: =SUM(B18*5) -> 300 | D18: 0 | E18: 0 | F18: 0 | G18: 1 | H18: 1 | I18: 1 | J18: =SUM(D18:I18) -> 3 | K18: =SUM(D18:H18) -> 2 | L18: =B18*K18 -> 120 | M18: JAN 28/14 | N18: JAN 28/16
A19: 140243 | B19: 45 | C19: =SUM(B19*5) -> 225 | D19: 0 | E19: 0 | F19: 1 | G19: 1 | H19: 1 | I19: 1 | J19: =SUM(D19:I19) -> 4 | K19: =SUM(D19:H19) -> 3 | L19: =B19*K19 -> 135 | M19: FEB 01/14 | N19: FEB01/16
A20: 140244 | B20: 45 | C20: =SUM(B20*5) -> 225 | D20: 0 | E20: 0 | F20: 0 | G20: 1 | H20: 1 | I20: 1 | J20: =SUM(D20:I20) -> 3 | K20: =SUM(D20:H20) -> 2 | L20: =B20*K20 -> 90 | M20: FEB 01/14 | N20: FEB01/16
A21: 140245 | B21: 60 | C21: =SUM(B21*5) -> 300 | D21: 0 | E21: 0 | F21: 0 | G21: 1 | H21: 1 | I21: 1 | J21: =SUM(D21:I21) -> 3 | K21: =SUM(D21:H21) -> 2 | L21: =B21*K21 -> 120 | M21: FEB 03/14 | N21: FEB 03/16
A22: 140246 | B22: 45 | C22: =SUM(B22*5) -> 225 | D22: 0 | E22: 0 | F22: 0 | G22: 0 | H22: 0 | I22: 0 | J22: =SUM(D22:I22) -> 0 | K22: =SUM(D22:H22) -> 0 | L22: =B22*K22 -> 0 | M22: FEB 07/14 | N22: FEB 07/16
A23: 140247 | B23: 45 | C23: =SUM(B23*5) -> 225 | D23: 0 | E23: 0 | F23: 0 | G23: 0 | H23: 0 | I23: 1 | J23: =SUM(D23:I23) -> 1 | K23: =SUM(D23:H23) -> 0 | L23: =B23*K23 -> 0 | M23: FEB 07/14 | N23: FEB 07/16
A24: 140248 | B24: 60 | C24: =SUM(B24*5) -> 300 | D24: 0 | E24: 0 | F24: 0 | G24: 0 | H24: 0 | I24: 0 | J24: =SUM(D24:I24) -> 0 | K24: =SUM(D24:H24) -> 0 | L24: =B24*K24 -> 0 | M24: FEB 09/14 | N24: FEB 09/16
A25: 140249 | B25: 45 | C25: =SUM(B25*5) -> 225 | D25: 0 | E25: 0 | F25: 0 | G25: 0 | H25: 0 | I25: 0 | J25: =SUM(D25:I25) -> 0 | K25: =SUM(D25:H25) -> 0 | L25: =B25*K25 -> 0 | M25: FEB 09/14 | N25: FEB 09/16
A26: 140250 | B26: 45 | C26: =SUM(B26*5) -> 225 | D26: 0 | E26: 0 | F26: 0 | G26: 0 | H26: 0 | I26: 0 | J26: =SUM(D26:I26) -> 0 | K26: =SUM(D26:H26) -> 0 | L26: =B26*K26 -> 0 | M26: FEB 09/14 | N26: FEB 09/16
A27: 140251 | B27: 45 | C27: =SUM(B27*5) -> 225 | D27: 0 | E27: 0 | F27: 0 | G27: 0 | H27: 0 | I27: 0 | J27: =SUM(D27:I27) -> 0 | K27: =SUM(D27:H27) -> 0 | L27: =B27*K27 -> 0 | M27: FEB 10/14 | N27: FEB 10/16
... A38: 140262 | B38: 60 | C38: =SUM(B38*5) -> 300 | D38: 0 | E38: 0 | F38: 0 | G38: 0 | H38: 0 | I38: 0 | J38: =SUM(D38:I38) -> 0 | K38: =SUM(D38:H38) -> 0 | L38: =B38*K38 -> 0 | M38: MAR 04/14 | N38: MAR 04/16
A39: 140263 | D39: Comp. DLX once for complaint | M39: MAR 05/14 | N39: MAR 05/16 | P39: Done 15/07/14
A40: 140264 | B40: 45 | C40: =SUM(B40*5) -> 225 | D40: 0 | E40: 0 | F40: 0 | G40: 0 | H40: 0 | I40: 0 | J40: =SUM(D40:I40) -> 0 | K40: =SUM(D40:H40) -> 0 | L40: =B40*K40 -> 0 | M40: MAR 07/14 | N40: MAR 07/16
A41: 140265 | B41: 60 | C41: =SUM(B41*5) -> 300 | D41: 0 | E41: 0 | F41: 0 | G41: 0 | H41: 0 | I41: 0 | J41: =SUM(D41:I41) -> 0 | K41: =SUM(D41:H41) -> 0 | L41: =B41*K41 -> 0 | M41: MAR 08/14 | N41: MAR 08/16
A42: 140266 | B42: 45 | C42: =SUM(B42*5) -> 225 | D42: 0 | E42: 0 | F42: 0 | G42: 0 | H42: 0 | I42: 1 | J42: =SUM(D42:I42) -> 1 | K42: =SUM(D42:H42) -> 0 | L42: =B42*K42 -> 0 | M42: MAR 08/14 | N42: MAR 08/16
A43: 140267 | B43: 45 | C43: =SUM(B43*5) -> 225 | D43: 0 | E43: 0 | F43: 0 | G43: 0 | H43: 0 | I43: 0 | J43: =SUM(D43:I43) -> 0 | K43: =SUM(D43:H43) -> 0 | L43: =B43*K43 -> 0 | M43: MAR 08/14 | N43: MAR 08/16
A44: 140268 | B44: 70 | C44: =SUM(B44*5) -> 350 | D44: 0 | E44: 0 | F44: 0 | G44: 0 | H44: 0 | I44: 0 | J44: =SUM(D44:I44) -> 0 | K44: =SUM(D44:H44) -> 0 | L44: =B44*K44 -> 0 | M44: MAR 11/14 | N44: MAR 11/16
A45: 140269 | B45: 45 | C45: =SUM(B45*5) -> 225 | D45: 0 | E45: 0 | F45: 0 | G45: 0 | H45: 0 | I45: 0 | J45: =SUM(D45:I45) -> 0 | K45: =SUM(D45:H45) -> 0 | L45: =B45*K45 -> 0 | M45: MAR 12/14 | N45: MAR 12/16
A46: 140270 | B46: 50 | C46: =SUM(B46*5) -> 250 | D46: 0 | E46: 0 | F46: 0 | G46: 0 | H46: 0 | I46: 0 | J46: =SUM(D46:I46) -> 0 | K46: =SUM(D46:H46) -> 0 | L46: =B46*K46 -> 0 | M46: MAR 13/14 | N46: MAR 13/16
A47: 140271 | B47: 45 | C47: =SUM(B47*5) -> 225 | D47: 0 | E47: 0 | F47: 0 | G47: 0 | H47: 0 | I47: 0 | J47: =SUM(D47:I47) -> 0 | K47: =SUM(D47:H47) -> 0 | L47: =B47*K47 -> 0 | M47: MAR 14/14 | N47: MAR 14/16
A48: 140272 | B48: 60 | C48: =SUM(B48*5) -> 300 | D48: 0 | E48: 0 | F48: 0 | G48: 0 | H48: 0 | I48: 0 | J48: =SUM(D48:I48) -> 0 | K48: =SUM(D48:H48) -> 0 | L48: =B48*K48 -> 0 | M48: MAR 15/14 | N48: MAR 15/16
A49: 140273 | B49: 45 | C49: =SUM(B49*5) -> 225 | D49: 0 | E49: 0 | F49: 0 | G49: 0 | H49: 0 | I49: 0 | J49: =SUM(D49:I49) -> 0 | K49: =SUM(D49:H49) -> 0 | L49: =B49*K49 -> 0 | M49: MAR 15/14 | N49: MAR 15/16
A50: 140274 | B50: 45 | C50: =SUM(B50*5) -> 225 | D50: 0 | E50: 0 | F50: 0 | G50: 0 | H50: 1 | I50: 1 | J50: =SUM(D50:I50) -> 2 | K50: =SUM(D50:H50) -> 1 | L50: =B50*K50 -> 45 | M50: MAR 15/14 | N50: MAR 15/16 | O50: 45
...

Sheet 2015
C1: Amount | L1: Amount | N1: UNCLAIMED
A2: Numbers | C2: sold | L2: Unclaimed | N2: Percentage
C3: =SUM(C7:C332) -> 78825 | L3: =SUM(L7:L332)-180 -> 4909 | N3: =L3/C3 -> 0.062277196
A4: No | B4: Unit | C4: Sales | J4: Service(s) | K4: Value | L4: $ | M4: issued on | N4: expires at | O4: Customer | P4: Phone | Q4: e-mail
B5: Price | C5: Price | D5: (USED) | J5: left | K5: left | L5: left | O5: Name
A7: 140526 | B7: 60 | C7: =SUM(B7*5) -> 300 | D7: 0 | E7: 0 | F7: 0 | G7: 0 | H7: 0 | I7: 1 | J7: =SUM(D7:I7) -> 1 | K7: =SUM(D7:H7) -> 0 | L7: =B7*K7 -> 0 | M7: JAN02/2015 | N7: JAN02/2017
A8: 140527 | B8: 50 | C8: =SUM(B8*5) -> 250 | D8: 0 | E8: 0 | F8: 0 | G8: 0 | H8: 0 | I8: 0 | J8: =SUM(D8:I8) -> 0 | K8: =SUM(D8:H8) -> 0 | L8: =B8*K8 -> 0 | M8: JAN02/2015 | N8: JAN02/2017
A9: 140528 | B9: 60 | C9: =SUM(B9*5) -> 300 | D9: 0 | E9: 0 | F9: 0 | G9: 0 | H9: 0 | I9: 1 | J9: =SUM(D9:I9) -> 1 | K9: =SUM(D9:H9) -> 0 | L9: =B9*K9 -> 0 | M9: JAN02/2015 | N9: JAN02/2017
A10: 140529 | B10: 60 | C10: =SUM(B10*5) -> 300 | D10: 0 | E10: 0 | F10: 0 | G10: 0 | H10: 0 | I10: 1 | J10: =SUM(D10:I10) -> 1 | K10: =SUM(D10:H10) -> 0 | L10: =B10*K10 -> 0 | M10: JAN03/2015 | N10: JAN03/2017
A11: 140530 | B11: 50 | C11: =SUM(B11*5) -> 250 | D11: 0 | E11: 0 | F11: 0 | G11: 0 | H11: 0 | I11: 0 | J11: =SUM(D11:I11) -> 0 | K11: =SUM(D11:H11) -> 0 | L11: =B11*K11 -> 0 | M11: JAN08/2015 | N11: JAN08/2017
A12: 140531 | B12: 45 | C12: =SUM(B12*5) -> 225 | D12: 0 | E12: 0 | F12: 0 | G12: 0 | H12: 0 | I12: 0 | J12: =SUM(D12:I12) -> 0 | K12: =SUM(D12:H12) -> 0 | L12: =B12*K12 -> 0 | M12: JAN10/2015 | N12: JAN10/2017
A13: 140532 | B13: 60 | C13: =SUM(B13*5) -> 300 | D13: 0 | E13: 0 | F13: 0 | G13: 0 | H13: 0 | I13: 1 | J13: =SUM(D13:I13) -> 1 | K13: =SUM(D13:H13) -> 0 | L13: =B13*K13 -> 0 | M13: JAN15/2015 | N13: JAN15/2017
A14: 140533 | B14: 45 | C14: =SUM(B14*5) -> 225 | D14: 0 | E14: 0 | F14: 0 | G14: 0 | H14: 0 | I14: 0 | J14: =SUM(D14:I14) -> 0 | K14: =SUM(D14:H14) -> 0 | L14: =B14*K14 -> 0 | M14: JAN16/2015 | N14: JAN16/2017
A15: 140534 | B15: 50 | C15: =SUM(B15*5) -> 250 | D15: 0 | E15: 0 | F15: 0 | G15: 0 | H15: 0 | I15: 0 | J15: =SUM(D15:I15) -> 0 | K15: =SUM(D15:H15) -> 0 | L15: =B15*K15 -> 0 | M15: JAN16/2015 | N15: JAN16/2017
A16: 140535 | B16: 60 | C16: =SUM(B16*5) -> 300 | D16: 0 | E16: 0 | F16: 0 | G16: 0 | H16: 0 | I16: 0 | J16: =SUM(D16:I16) -> 0 | K16: =SUM(D16:H16) -> 0 | L16: =B16*K16 -> 0 | M16: JAN16/2015 | N16: JAN16/2017
A17: 140536 | B17: 60 | C17: =SUM(B17*5) -> 300 | D17: 0 | E17: 0 | F17: 0 | G17: 0 | H17: 0 | I17: 0 | J17: =SUM(D17:I17) -> 0 | K17: =SUM(D17:H17) -> 0 | L17: =B17*K17 -> 0 | M17: JAN16/2015 | N17: JAN16/2017 | R17: `
A18: 140537 | B18: 45 | C18: =SUM(B18*5) -> 225 | D18: 0 | E18: 0 | F18: 0 | G18: 0 | H18: 0 | I18: 0 | J18: =SUM(D18:I18) -> 0 | K18: =SUM(D18:H18) -> 0 | L18: =B18*K18 -> 0 | M18: JAN16/2015 | N18: JAN16/2017
A19: 140538 | B19: 45 | C19: =SUM(B19*5) -> 225 | D19: 0 | E19: 0 | F19: 0 | G19: 0 | H19: 0 | I19: 0 | J19: =SUM(D19:I19) -> 0 | K19: =SUM(D19:H19) -> 0 | L19: =B19*K19 -> 0 | M19: JAN17/2015 | N19: JAN17/2017
A20: 140539 | C20: =SUM(B20*5) -> 0 | D20: 0 | E20: 0 | F20: 0 | J20: =SUM(D20:I20) -> 0 | K20: =SUM(D20:H20) -> 0 | L20: =B20*K20 -> 0 | M20: JAN18/2015 | N20: JAN18/2017 | O20: COMP
A21: 150540 | B21: 60 | C21: =SUM(B21*5) -> 300 | D21: 0 | E21: 0 | F21: 0 | G21: 0 | H21: 0 | I21: 0 | J21: =SUM(D21:I21) -> 0 | K21: =SUM(D21:H21) -> 0 | L21: =B21*K21 -> 0 | M21: JAN18/2015 | N21: JAN18/2017
A22: 150541 | B22: 45 | C22: =SUM(B22*5) -> 225 | D22: 0 | E22: 0 | F22: 0 | G22: 0 | H22: 0 | I22: 0 | J22: =SUM(D22:I22) -> 0 | K22: =SUM(D22:H22) -> 0 | L22: =B22*K22 -> 0 | M22: JAN18/2015 | N22: JAN18/2017
A23: 150542 | B23: 45 | C23: =SUM(B23*5) -> 225 | D23: 0 | E23: 0 | F23: 0 | G23: 0 | H23: 0 | I23: 0 | J23: =SUM(D23:I23) -> 0 | K23: =SUM(D23:H23) -> 0 | L23: =B23*K23 -> 0 | M23: JAN18/2015 | N23: JAN18/2017
A24: 150543 | B24: 60 | C24: =SUM(B24*5) -> 300 | D24: 0 | E24: 0 | F24: 0 | G24: 0 | H24: 0 | I24: 1 | J24: =SUM(D24:I24) -> 1 | K24: =SUM(D24:H24) -> 0 | L24: =B24*K24 -> 0 | M24: JAN20/2015 | N24: JAN20/2017
A25: 150544 | B25: 45 | C25: =SUM(B25*5) -> 225 | D25: 0 | E25: 0 | F25: 0 | G25: 0 | H25: 0 | I25: 0 | J25: =SUM(D25:I25) -> 0 | K25: =SUM(D25:H25) -> 0 | L25: =B25*K25 -> 0 | M25: JAN21/2015 | N25: JAN21/2017
A26: 150545 | B26: 45 | C26: =SUM(B26*5) -> 225 | D26: 0 | E26: 0 | F26: 0 | G26: 0 | H26: 0 | I26: 0 | J26: =SUM(D26:I26) -> 0 | K26: =SUM(D26:H26) -> 0 | L26: =B26*K26 -> 0 | M26: JAN25/2015 | N26: JAN25/2017
A27: 150546 | B27: 60 | C27: =SUM(B27*5) -> 300 | D27: 0 | E27: 0 | F27: 0 | G27: 0 | H27: 0 | I27: 0 | J27: =SUM(D27:I27) -> 0 | K27: =SUM(D27:H27) -> 0 | L27: =B27*K27 -> 0 | M27: JAN25/2015 | N27: JAN25/2017
A28: 150547 | B28: 60 | C28: =SUM(B28*5) -> 300 | D28: 0 | E28: 0 | F28: 0 | G28: 0 | H28: 0 | I28: 1 | J28: =SUM(D28:I28) -> 1 | K28: =SUM(D28:H28) -> 0 | L28: =B28*K28 -> 0 | M28: JAN29/2015 | N28: JAN29/2017
A29: 150548 | B29: 60 | C29: =SUM(B29*5) -> 300 | D29: 0 | E29: 0 | F29: 0 | G29: 0 | H29: 0 | I29: 0 | J29: =SUM(D29:I29) -> 0 | K29: =SUM(D29:H29) -> 0 | L29: =B29*K29 -> 0 | M29: JAN29/2015 | N29: JAN29/2017
A30: 150549 | B30: 60 | C30: =SUM(B30*5) -> 300 | D30: 0 | E30: 0 | F30: 0 | G30: 0 | H30: 0 | I30: 1 | J30: =SUM(D30:I30) -> 1 | K30: =SUM(D30:H30) -> 0 | L30: =B30*K30 -> 0 | M30: JAN29/2015 | N30: JAN29/2017
A31: 150550 | B31: 50 | C31: =SUM(B31*5) -> 250 | D31: 0 | E31: 0 | F31: 0 | G31: 0 | H31: 0 | I31: 0 | J31: =SUM(D31:I31) -> 0 | K31: =SUM(D31:H31) -> 0 | L31: =B31*K31 -> 0 | M31: JAN29/2015 | N31: JAN29/2017
A32: 150551 | B32: 45 | C32: =SUM(B32*5) -> 225 | D32: 0 | E32: 0 | F32: 0 | G32: 0 | H32: 0 | I32: 0 | J32: =SUM(D32:I32) -> 0 | K32: =SUM(D32:H32) -> 0 | L32: =B32*K32 -> 0 | M32: JAN31/2015 | N32: JAN31/2017
... A50: 150569 | B50: 60 | C50: =SUM(B50*5) -> 300 | D50: 0 | E50: 0 | F50: 0 | G50: 0 | H50: 0 | I50: 0 | J50: =SUM(D50:I50) -> 0 | K50: =SUM(D50:H50) -> 0 | L50: =B50*K50 -> 0 | M50: FEB21/2015 | N50: FEB21/2017
A51: 150570 | B51: 36 | C51: =B51*10 -> 360 | D51: 0 | E51: 0 | F51: 0 | G51: 0 | H51: 0 | I51: 1 | J51: =SUM(D51:I52) -> 7 | K51: =SUM(D51:I52) -> 7 | L51: =315 -> 315 | M51: FEB23/2015 | N51: FEB23/2017
D52: 1 | E52: 1 | F52: 1 | G52: 1 | H52: 1 | I52: 1
A53: 150571 | B53: 45 | C53: =SUM(B53*5) -> 225 | D53: 0 | E53: 0 | F53: 0 | G53: 0 | H53: 0 | I53: 0 | J53: =SUM(D53:I53) -> 0 | K53: =SUM(D53:H53) -> 0 | L53: =B53*K53 -> 0 | M53: FEB24/2015 | N53: FEB24/2017
A54: 150572 | B54: 45 | C54: =SUM(B54*5) -> 225 | D54: 0 | E54: 1 | F54: 1 | G54: 1 | H54: 1 | I54: 1 | J54: =SUM(D54:I54) -> 5 | K54: =SUM(D54:H54) -> 4 | L54: =B54*K54 -> 180 | M54: FEB24/2015 | N54: FEB24/2017
A55: 150573 | B55: 60 | C55: =SUM(B55*5) -> 300 | D55: 0 | E55: 0 | F55: 0 | G55: 0 | H55: 1 | I55: 1 | J55: =SUM(D55:I55) -> 2 | K55: =SUM(D55:H55) -> 1 | L55: =B55*K55 -> 60 | M55: FEB26/2015 | N55: FEB26/2017
A56: 150574 | B56: 45 | C56: =SUM(B56*5) -> 225 | D56: 0 | E56: 0 | F56: 0 | G56: 0 | H56: 0 | I56: 0 | J56: =SUM(D56:I56) -> 0 | K56: =SUM(D56:H56) -> 0 | L56: =B56*K56 -> 0 | M56: FEB26/2015 | N56: FEB26/2017
A57: 150575 | C57: =SUM(B57*5) -> 0 | D57: 0 | E57: 0 | F57: 0 | G57: 0 | H57: 0 | I57: 0 | J57: =SUM(D57:I57) -> 0 | K57: =SUM(D57:H57) -> 0 | L57: =B57*K57 -> 0 | M57: COMP $30 VOUCHER | O57: DONE on 04/09/15
A58: 150576 | B58: 45 | C58: =SUM(B58*5) -> 225 | D58: 0 | E58: 0 | F58: 0 | G58: 0 | H58: 0 | I58: 0 | J58: =SUM(D58:I58) -> 0 | K58: =SUM(D58:H58) -> 0 | L58: =B58*K58 -> 0 | M58: MAR01/2015 | N58: MAR01/2017
...

Sheet 2016
C1: Amount | L1: Amount | N1: UNCLAIMED
A2: Numbers | C2: sold | L2: Unclaimed | N2: Percentage
C3: =SUM(C6:C371) -> 84775 | L3: =SUM(L6:L371) -> 6530 | N3: =L3/C3 -> 0.077027426
A4: No | B4: Unit | C4: Sales | J4: Service(s) | K4: Value | L4: $ | M4: issued on | N4: expires at | O4: Customer | P4: Phone | Q4: e-mail
B5: Price | C5: Price | D5: (USED) | J5: left | K5: left | L5: left | O5: Name
A6: 150851 | B6: 60 | C6: =SUM(B6*5) -> 300 | D6: 0 | E6: 0 | F6: 1 | G6: 1 | H6: 1 | I6: 1 | J6: =SUM(D6:I6) -> 4 | K6: =SUM(D6:H6) -> 3 | L6: =B6*K6 -> 180 | M6: JAN08/2016 | N6: JAN08/2018 | O6: CANCELLED BY SELLING SUV, RE-ISSUED #160926 WASH ONLY
A7: 150852 | B7: 60 | C7: =SUM(B7*5) -> 300 | D7: 0 | E7: 0 | F7: 0 | G7: 0 | H7: 0 | I7: 0 | J7: =SUM(D7:I7) -> 0 | K7: =SUM(D7:H7) -> 0 | L7: =B7*K7 -> 0 | M7: ?? | N7: ??
A8: 150853 | B8: 45 | C8: =SUM(B8*5) -> 225 | D8: 0 | E8: 0 | F8: 0 | G8: 0 | H8: 0 | I8: 1 | J8: =SUM(D8:I8) -> 1 | K8: =SUM(D8:H8) -> 0 | L8: =B8*K8 -> 0 | M8: JAN 11/2016 | N8: JAN 11/2018
A9: 150854 | B9: 45 | C9: =SUM(B9*5) -> 225 | D9: 0 | E9: 0 | F9: 0 | G9: 0 | H9: 0 | I9: 0 | J9: =SUM(D9:I9) -> 0 | K9: =SUM(D9:H9) -> 0 | L9: =B9*K9 -> 0 | M9: JAN 11/2016 | N9: JAN 11/2018
A10: 150855 | B10: 50 | C10: =SUM(B10*5) -> 250 | D10: 0 | E10: 0 | F10: 0 | G10: 0 | H10: 0 | I10: 0 | J10: =SUM(D10:I10) -> 0 | K10: =SUM(D10:H10) -> 0 | L10: =B10*K10 -> 0 | M10: JAN 14/2016 | N10: JAN 14/2018 | O10: extended
A11: 150856 | B11: 45 | C11: =SUM(B11*5) -> 225 | D11: 0 | E11: 0 | F11: 0 | G11: 0 | H11: 0 | I11: 0 | J11: =SUM(D11:I11) -> 0 | K11: =SUM(D11:H11) -> 0 | L11: =B11*K11 -> 0 | M11: JAN 16/2016 | N11: JAN 16/2018
A12: 150857 | B12: 45 | C12: =SUM(B12*5) -> 225 | D12: 0 | E12: 0 | F12: 0 | G12: 0 | H12: 0 | I12: 0 | J12: =SUM(D12:I12) -> 0 | K12: =SUM(D12:H12) -> 0 | L12: =B12*K12 -> 0 | M12: JAN 16/2016 | N12: JAN 16/2018
A13: 150858 | B13: 60 | C13: =SUM(B13*5) -> 300 | D13: 0 | E13: 0 | F13: 0 | G13: 0 | H13: 0 | I13: 0 | J13: =SUM(D13:I13) -> 0 | K13: =SUM(D13:H13) -> 0 | L13: =B13*K13 -> 0 | M13: JAN 18/2016 | N13: JAN 18/2018
A14: 150859 | B14: 45 | C14: =SUM(B14*5) -> 225 | D14: 0 | E14: 0 | F14: 0 | G14: 0 | H14: 0 | I14: 0 | J14: =SUM(D14:I14) -> 0 | K14: =SUM(D14:H14) -> 0 | L14: =B14*K14 -> 0 | M14: JAN 20/2016 | N14: JAN 20/2018
A15: 150860 | C15: =SUM(B15*5) -> 0 | D15: 1 | E15: 1 | F15: 1 | G15: 1 | H15: 1 | I15: 1 | J15: =SUM(D15:I15) -> 6 | K15: =SUM(D15:H15) -> 5 | L15: =B15*K15 -> 0 | Q15: GA 지원
A16: 150861 | C16: =SUM(B16*5) -> 0 | D16: 1 | E16: 1 | F16: 1 | G16: 1 | H16: 1 | I16: 1 | J16: =SUM(D16:I16) -> 6 | K16: =SUM(D16:H16) -> 5 | L16: =B16*K16 -> 0 | Q16: GA 지원
A17: 150862 | C17: =SUM(B17*5) -> 0 | D17: 1 | E17: 1 | F17: 1 | G17: 1 | H17: 1 | I17: 1 | J17: =SUM(D17:I17) -> 6 | K17: =SUM(D17:H17) -> 5 | L17: =B17*K17 -> 0 | Q17: GA 지원
A18: 150863 | C18: =SUM(B18*5) -> 0 | D18: 0 | E18: 0 | F18: 0 | G18: 0 | H18: 0 | I18: 1 | J18: =SUM(D18:I18) -> 1 | K18: =SUM(D18:H18) -> 0 | L18: =B18*K18 -> 0 | Q18: GA 지원
A19: 150864 | C19: =SUM(B19*5) -> 0 | D19: 1 | E19: 1 | F19: 1 | G19: 1 | H19: 1 | I19: 1 | J19: =SUM(D19:I19) -> 6 | K19: =SUM(D19:H19) -> 5 | L19: =B19*K19 -> 0 | Q19: GA 지원
A20: 150865 | C20: =SUM(B20*5) -> 0 | D20: 1 | E20: 1 | F20: 1 | G20: 1 | H20: 1 | I20: 1 | J20: =SUM(D20:I20) -> 6 | K20: =SUM(D20:H20) -> 5 | L20: =B20*K20 -> 0 | Q20: GA 지원
A21: 150866 | C21: =SUM(B21*5) -> 0 | D21: 1 | E21: 1 | F21: 1 | G21: 1 | H21: 1 | I21: 1 | J21: =SUM(D21:I21) -> 6 | K21: =SUM(D21:H21) -> 5 | L21: =B21*K21 -> 0 | Q21: GA 지원
A22: 150867 | C22: =SUM(B22*5) -> 0 | D22: 1 | E22: 1 | F22: 1 | G22: 1 | H22: 1 | I22: 1 | J22: =SUM(D22:I22) -> 6 | K22: =SUM(D22:H22) -> 5 | L22: =B22*K22 -> 0 | Q22: GA 지원
A23: 150868 | C23: =SUM(B23*5) -> 0 | D23: 1 | E23: 1 | F23: 1 | G23: 1 | H23: 1 | I23: 1 | J23: =SUM(D23:I23) -> 6 | K23: =SUM(D23:H23) -> 5 | L23: =B23*K23 -> 0 | Q23: GA 지원
A24: 150869 | C24: =SUM(B24*5) -> 0 | D24: 1 | E24: 1 | F24: 1 | G24: 1 | H24: 1 | I24: 1 | J24: =SUM(D24:I24) -> 6 | K24: =SUM(D24:H24) -> 5 | L24: =B24*K24 -> 0 | Q24: GA 지원
A25: 160870 | B25: 45 | C25: =SUM(B25*5) -> 225 | D25: 0 | E25: 0 | F25: 0 | G25: 0 | H25: 0 | I25: 0 | J25: =SUM(D25:I25) -> 0 | K25: =SUM(D25:H25) -> 0 | L25: =B25*K25 -> 0 | M25: JAN 20/2016 | N25: JAN 20/2018
A26: 160871 | B26: 45 | C26: =SUM(B26*5) -> 225 | D26: 0 | E26: 0 | F26: 0 | G26: 0 | H26: 0 | I26: 0 | J26: =SUM(D26:I26) -> 0 | K26: =SUM(D26:H26) -> 0 | L26: =B26*K26 -> 0 | M26: JAN 20/2016 | N26: JAN 20/2018
A27: 160872 | B27: 35 | C27: =SUM(B27*5) -> 175 | D27: 0 | E27: 0 | F27: 0 | G27: 0 | H27: 0 | I27: 0 | J27: =SUM(D27:I27) -> 0 | K27: =SUM(D27:H27) -> 0 | L27: =B27*K27 -> 0 | M27: JAN 20/2016 | N27: JAN 20/2018
A28: 160873 | B28: 60 | C28: =SUM(B28*5) -> 300 | D28: 0 | E28: 0 | F28: 0 | G28: 0 | H28: 0 | I28: 0 | J28: =SUM(D28:I28) -> 0 | K28: =SUM(D28:H28) -> 0 | L28: =B28*K28 -> 0 | M28: JAN 23/2016 | N28: JAN 23/2018
A29: 160874 | B29: 45 | C29: =SUM(B29*5) -> 225 | D29: 0 | E29: 1 | F29: 1 | G29: 1 | H29: 1 | I29: 1 | J29: =SUM(D29:I29) -> 5 | K29: =SUM(D29:H29) -> 4 | L29: =B29*K29 -> 180 | M29: JAN 25/2016 | N29: JAN 25/2018
A30: 160875 | B30: 45 | C30: 225 | D30: 0 | E30: 0 | F30: 0 | G30: 0 | H30: 1 | I30: 1 | J30: =SUM(D30:I30) -> 2 | K30: =SUM(D30:H30) -> 1 | L30: =B30*K30 -> 45 | M30: JAN 25/2016 | N30: JAN 25/2018
A31: 160876 | B31: 60 | C31: =SUM(B31*5) -> 300 | D31: 0 | E31: 0 | F31: 0 | G31: 0 | H31: 0 | I31: 0 | J31: =SUM(D31:I31) -> 0 | K31: =SUM(D31:H31) -> 0 | L31: =B31*K31 -> 0 | M31: JAN 27/2016 | N31: JAN 27/2018
A32: 160877 | B32: 45 | C32: =SUM(B32*5) -> 225 | D32: 0 | E32: 0 | F32: 0 | G32: 0 | H32: 1 | I32: 1 | J32: =SUM(D32:I32) -> 2 | K32: =SUM(D32:H32) -> 1 | L32: =B32*K32 -> 45 | M32: JAN 27/2016 | N32: JAN 27/2018
A33: 160878 | B33: 45 | C33: =SUM(B33*5) -> 225 | D33: 0 | E33: 0 | F33: 1 | G33: 1 | H33: 1 | I33: 1 | J33: =SUM(D33:I33) -> 4 | K33: =SUM(D33:H33) -> 3 | L33: =B33*K33 -> 135 | M33: JAN 29/2016 | N33: JAN 29/2018
A34: 160879 | B34: 45 | C34: =SUM(B34*5) -> 225 | D34: 0 | E34: 0 | F34: 0 | G34: 0 | H34: 0 | I34: 0 | J34: =SUM(D34:I34) -> 0 | K34: =SUM(D34:H34) -> 0 | L34: =B34*K34 -> 0 | M34: JAN 30/2016 | N34: JAN 30/2018
A35: 160880 | B35: 50 | C35: =SUM(B35*5) -> 250 | D35: 0 | E35: 0 | F35: 0 | G35: 0 | H35: 0 | I35: 0 | J35: =SUM(D35:I35) -> 0 | K35: =SUM(D35:H35) -> 0 | L35: =B35*K35 -> 0 | M35: JAN 31/2016 | N35: JAN 31/2018
A36: 160881 | B36: 90 | C36: =SUM(B36*5) -> 450 | D36: 0 | E36: 0 | F36: 0 | G36: 0 | H36: 0 | I36: 0 | J36: =SUM(D36:I36) -> 0 | K36: =SUM(D36:H36) -> 0 | L36: =B36*K36 -> 0 | M36: JAN 31/2016 | N36: JAN 31/2018
A37: 160882 | B37: 60 | C37: =SUM(B37*5) -> 300 | D37: 0 | E37: 0 | F37: 0 | G37: 0 | H37: 0 | I37: 0 | J37: =SUM(D37:I37) -> 0 | K37: =SUM(D37:H37) -> 0 | L37: =B37*K37 -> 0 | M37: FEB 03/2016 | N37: FEB 03/2018
A38: 160883 | B38: 45 | C38: =SUM(B38*5) -> 225 | D38: 0 | E38: 0 | F38: 0 | G38: 0 | H38: 0 | I38: 0 | J38: =SUM(D38:I38) -> 0 | K38: =SUM(D38:H38) -> 0 | L38: =B38*K38 -> 0 | M38: FEB 06/2016 | N38: FEB 06/2018
A39: 160884 | B39: 60 | C39: =SUM(B39*5) -> 300 | D39: 0 | E39: 0 | F39: 0 | G39: 0 | H39: 0 | I39: 0 | J39: =SUM(D39:I39) -> 0 | K39: =SUM(D39:H39) -> 0 | L39: =B39*K39 -> 0 | M39: FEB 06/2016 | N39: FEB 06/2018
A40: 160885 | C40: =SUM(B40*5) -> 0 | D40: 0 | J40: =SUM(D40:I40) -> 0 | K40: =SUM(D40:H40) -> 0 | L40: =B40*K40 -> 0 | M40: FEB 06/2016 | N40: FEB 06/2018 | O40: detail complaint compliment
...

Sheet 2017
C1: Amount | L1: Amount | N1: UNCLAIMED
A2: Numbers | C2: sold | L2: Unclaimed | N2: Percentage
C3: =SUM(C6:C420) -> 102835 | L3: =SUM(L6:L420) -> 7130 | N3: =L3/C3 -> 0.069334371
A4: No | B4: Unit | C4: Sales | J4: Service(s) | K4: Value | L4: $ | M4: issued on | N4: expires at | O4: Customer | P4: Phone | Q4: e-mail
B5: Price | C5: Price | D5: (USED) | J5: left | K5: left | L5: left | O5: Name
A6: 161215 | B6: 50 | C6: =SUM(B6*5) -> 250 | D6: 0 | E6: 0 | F6: 0 | G6: 0 | H6: 0 | I6: 0 | J6: =SUM(D6:I6) -> 0 | K6: =SUM(D6:H6) -> 0 | L6: =B6*K6 -> 0 | M6: JAN 02/2017 | N6: JAN 02/2019
A7: 161216 | B7: 45 | C7: =SUM(B7*5) -> 225 | D7: 0 | E7: 0 | F7: 0 | G7: 0 | H7: 0 | I7: 0 | J7: =SUM(D7:I7) -> 0 | K7: =SUM(D7:H7) -> 0 | L7: =B7*K7 -> 0 | M7: JAN 02/2017 | N7: JAN 02/2019
A8: 161217 | B8: 45 | C8: =SUM(B8*5) -> 225 | D8: 0 | E8: 0 | F8: 0 | G8: 1 | H8: 1 | I8: 1 | J8: =SUM(D8:I8) -> 3 | K8: =SUM(D8:H8) -> 2 | L8: =B8*K8 -> 90 | M8: JAN 04/2017 | N8: JAN 04/2019 | P8: RETURNED
A9: 161218 | B9: 45 | C9: =SUM(B9*5) -> 225 | D9: 0 | E9: 0 | F9: 0 | G9: 0 | H9: 0 | I9: 0 | J9: =SUM(D9:I9) -> 0 | K9: =SUM(D9:H9) -> 0 | L9: =B9*K9 -> 0 | M9: JAN 07/2017 | N9: JAN 07/2019
A10: 161219 | B10: 60 | C10: =SUM(B10*5) -> 300 | D10: 0 | E10: 0 | F10: 0 | G10: 0 | H10: 0 | I10: 0 | J10: =SUM(D10:I10) -> 0 | K10: =SUM(D10:H10) -> 0 | L10: =B10*K10 -> 0 | M10: JAN 08/2017 | N10: JAN 08/2019
A11: 161220 | B11: 45 | C11: =SUM(B11*5) -> 225 | D11: 0 | E11: 0 | F11: 0 | G11: 0 | H11: 0 | I11: 1 | J11: =SUM(D11:I11) -> 1 | K11: =SUM(D11:H11) -> 0 | L11: =B11*K11 -> 0 | M11: JAN 09/2017 | N11: JAN 09/2019
A12: 161221 | B12: 60 | C12: =SUM(B12*5) -> 300 | D12: 0 | E12: 0 | F12: 0 | G12: 0 | H12: 0 | I12: 1 | J12: =SUM(D12:I12) -> 1 | K12: =SUM(D12:H12) -> 0 | L12: =B12*K12 -> 0 | M12: JAN 09/2017 | N12: JAN 09/2019
A13: 161222 | B13: 45 | C13: =SUM(B13*5) -> 225 | D13: 0 | E13: 0 | F13: 0 | G13: 0 | H13: 0 | I13: 1 | J13: =SUM(D13:I13) -> 1 | K13: =SUM(D13:H13) -> 0 | L13: =B13*K13 -> 0 | M13: JAN 10/2017 | N13: JAN 10/2019
A14: 161223 | B14: 60 | C14: =SUM(B14*5) -> 300 | D14: 0 | E14: 0 | F14: 0 | G14: 0 | H14: 0 | I14: 0 | J14: =SUM(D14:I14) -> 0 | K14: =SUM(D14:H14) -> 0 | L14: =B14*K14 -> 0 | M14: JAN 10/2017 | N14: JAN 10/2019
A15: 161224 | B15: 45 | C15: =SUM(B15*5) -> 225 | D15: 0 | E15: 0 | F15: 0 | G15: 0 | H15: 0 | I15: 0 | J15: =SUM(D15:I15) -> 0 | K15: =SUM(D15:H15) -> 0 | L15: =B15*K15 -> 0 | M15: JAN 11/2017 | N15: JAN 11/2019
A16: 161225 | B16: 60 | C16: =SUM(B16*5) -> 300 | D16: 0 | E16: 0 | F16: 0 | G16: 0 | H16: 0 | I16: 0 | J16: =SUM(D16:I16) -> 0 | K16: =SUM(D16:H16) -> 0 | L16: =B16*K16 -> 0 | M16: JAN 11/2017 | N16: JAN 11/2019
A17: 161226 | B17: 60 | C17: =SUM(B17*5) -> 300 | D17: 0 | E17: 0 | F17: 0 | G17: 0 | H17: 1 | I17: 1 | J17: =SUM(D17:I17) -> 2 | K17: =SUM(D17:H17) -> 1 | L17: =B17*K17 -> 60 | M17: JAN 12/2017 | N17: JAN 12/2019
A18: 161227 | B18: 50 | C18: =SUM(B18*5) -> 250 | D18: 0 | E18: 0 | F18: 0 | G18: 0 | H18: 0 | I18: 0 | J18: =SUM(D18:I18) -> 0 | K18: =SUM(D18:H18) -> 0 | L18: =B18*K18 -> 0 | M18: JAN 12/2017 | N18: JAN 12/2019
A19: 161228 | B19: 45 | C19: =SUM(B19*5) -> 225 | D19: 0 | E19: 0 | F19: 0 | G19: 0 | H19: 0 | I19: 0 | J19: =SUM(D19:I19) -> 0 | K19: =SUM(D19:H19) -> 0 | L19: =B19*K19 -> 0 | M19: JAN 13/2017 | N19: JAN 13/2019
A20: 161229 | B20: 45 | C20: =SUM(B20*5) -> 225 | D20: 0 | E20: 0 | F20: 0 | G20: 0 | H20: 0 | I20: 0 | J20: =SUM(D20:I20) -> 0 | K20: =SUM(D20:H20) -> 0 | L20: =B20*K20 -> 0 | M20: JAN 16/2017 | N20: JAN 15/2019
A21: 171230 | B21: 0 | C21: =SUM(B21*5) -> 0 | D21: 0 | J21: =SUM(D21:I21) -> 0 | K21: =SUM(D21:H21) -> 0 | L21: =B21*K21 -> 0 | M21: JAN 15 2017 | N21: JUL 15 2017 | O21: NATHAN | P21: 0461 360 320 | R21: COMP DLX ONCE
A22: 171231 | B22: 50 | C22: =SUM(B22*5) -> 250 | D22: 0 | E22: 0 | F22: 0 | G22: 0 | H22: 0 | I22: 0 | J22: =SUM(D22:I22) -> 0 | K22: =SUM(D22:H22) -> 0 | L22: =B22*K22 -> 0 | M22: JAN 16 2017 | N22: JAN 16 2019
A23: 171232 | B23: 60 | C23: =SUM(B23*5) -> 300 | D23: 0 | E23: 0 | F23: 0 | G23: 0 | H23: 0 | I23: 0 | J23: =SUM(D23:I23) -> 0 | K23: =SUM(D23:H23) -> 0 | L23: =B23*K23 -> 0 | M23: JAN 16 2017 | N23: JAN 16 2019
A24: 171233 | B24: 60 | C24: =SUM(B24*5) -> 300 | D24: 0 | E24: 0 | F24: 0 | G24: 0 | H24: 0 | I24: 0 | J24: =SUM(D24:I24) -> 0 | K24: =SUM(D24:H24) -> 0 | L24: =B24*K24 -> 0 | M24: JAN 18 2017 | N24: JAN 18 2019
A25: 171234 | B25: 60 | C25: =SUM(B25*5) -> 300 | D25: 0 | E25: 0 | F25: 0 | G25: 0 | H25: 0 | I25: 0 | J25: =SUM(D25:I25) -> 0 | K25: =SUM(D25:H25) -> 0 | L25: =B25*K25 -> 0 | M25: JAN 19 2017 | N25: JAN 19 2019
A26: 171235 | B26: 45 | C26: =SUM(B26*5) -> 225 | D26: 0 | E26: 0 | F26: 0 | G26: 0 | H26: 0 | I26: 0 | J26: =SUM(D26:I26) -> 0 | K26: =SUM(D26:H26) -> 0 | L26: =B26*K26 -> 0 | M26: JAN 21 2017 | N26: JAN 21 2019
A27: 171236 | B27: 45 | C27: =SUM(B27*5) -> 225 | D27: 0 | E27: 0 | F27: 0 | G27: 0 | H27: 0 | I27: 0 | J27: =SUM(D27:I27) -> 0 | K27: =SUM(D27:H27) -> 0 | L27: =B27*K27 -> 0 | M27: JAN 21 2017 | N27: JAN 21 2019
A28: 171237 | B28: 45 | C28: =SUM(B28*5) -> 225 | D28: 0 | E28: 0 | F28: 0 | G28: 0 | H28: 0 | I28: 0 | J28: =SUM(D28:I28) -> 0 | K28: =SUM(D28:H28) -> 0 | L28: =B28*K28 -> 0 | M28: JAN 22 2017 | N28: JAN 22 2019
A29: 171238 | B29: 60 | C29: =SUM(B29*5) -> 300 | D29: 0 | E29: 0 | F29: 0 | G29: 0 | H29: 0 | I29: 0 | J29: =SUM(D29:I29) -> 0 | K29: =SUM(D29:H29) -> 0 | L29: =B29*K29 -> 0 | M29: JAN 22 2017 | N29: JAN 22 2019
A30: 171239 | B30: 45 | C30: =SUM(B30*5) -> 225 | D30: 1 | E30: 1 | F30: 1 | G30: 1 | H30: 1 | I30: 1 | J30: =SUM(D30:I30) -> 6 | K30: =SUM(D30:H30) -> 5 | L30: =B30*K30 -> 225 | M30: JAN 22 2017 | N30: JAN 22 2019
A31: 171240 | B31: 45 | C31: =SUM(B31*5) -> 225 | D31: 0 | E31: 0 | F31: 0 | G31: 0 | H31: 0 | I31: 0 | J31: =SUM(D31:I31) -> 0 | K31: =SUM(D31:H31) -> 0 | L31: =B31*K31 -> 0 | M31: JAN 22 2017 | N31: JAN 22 2019
A32: 171241 | B32: 60 | C32: =SUM(B32*5) -> 300 | D32: 0 | E32: 0 | F32: 0 | G32: 0 | H32: 0 | I32: 0 | J32: =SUM(D32:I32) -> 0 | K32: =SUM(D32:H32) -> 0 | L32: =B32*K32 -> 0 | M32: JAN 24 2017 | N32: JAN 24 2019
A33: 171242 | B33: 45 | C33: =SUM(B33*5) -> 225 | D33: 0 | E33: 0 | F33: 0 | G33: 0 | H33: 0 | I33: 0 | J33: =SUM(D33:I33) -> 0 | K33: =SUM(D33:H33) -> 0 | L33: =B33*K33 -> 0 | M33: JAN 24 2017 | N33: JAN 24 2019
... A37: 171246 | B37: 45 | C37: =SUM(B37*5) -> 225 | D37: 0 | E37: 0 | F37: 0 | G37: 0 | H37: 0 | I37: 0 | J37: =SUM(D37:I37) -> 0 | K37: =SUM(D37:H37) -> 0 | L37: =B37*K37 -> 0 | M37: JAN 27 2017 | N37: JAN 27 2019
A38: 171247 | B38: 0 | C38: =SUM(B38*5) -> 0 | D38: 1 | J38: =SUM(D38:I38) -> 1 | K38: =SUM(D38:H38) -> 1 | L38: =B38*K38 -> 0 | M38: JAN 27 2017 | N38: JAN 27 2019 | O38: Customer will pay $70 issude by Kevin
A39: 171248 | B39: 60 | C39: =SUM(B39*5) -> 300 | D39: 0 | E39: 0 | F39: 0 | G39: 0 | H39: 0 | I39: 0 | J39: =SUM(D39:I39) -> 0 | K39: =SUM(D39:H39) -> 0 | L39: =B39*K39 -> 0 | M39: JAN 28 2017 | N39: JAN 28 2019
A40: 171249 | B40: 45 | C40: =SUM(B40*5) -> 225 | D40: 0 | E40: 0 | F40: 0 | G40: 0 | H40: 0 | I40: 0 | J40: =SUM(D40:I40) -> 0 | K40: =SUM(D40:H40) -> 0 | L40: =B40*K40 -> 0 | M40: JAN 29 2017 | N40: JAN 29 2019
A41: 171250 | B41: 45 | C41: =SUM(B41*5) -> 225 | D41: 0 | E41: 0 | F41: 0 | G41: 0 | H41: 0 | I41: 0 | J41: =SUM(D41:I41) -> 0 | K41: =SUM(D41:H41) -> 0 | L41: =B41*K41 -> 0 | M41: FEB 01 2017 | N41: FEB 01 2019
A42: 171251 | B42: 45 | C42: =SUM(B42*5) -> 225 | D42: 0 | E42: 0 | F42: 1 | G42: 1 | H42: 1 | I42: 1 | J42: =SUM(D42:I42) -> 4 | K42: =SUM(D42:H42) -> 3 | L42: =B42*K42 -> 135 | M42: FEB 01 2017 | N42: FEB 01 2019
A43: 171252 | B43: 60 | C43: =SUM(B43*5) -> 300 | D43: 0 | E43: 0 | F43: 0 | G43: 0 | H43: 0 | I43: 0 | J43: =SUM(D43:I43) -> 0 | K43: =SUM(D43:H43) -> 0 | L43: =B43*K43 -> 0 | M43: FEB 02 2017 | N43: FEB 02 2019
...

Sheet 2018
C1: Amount | K1: Amount | L1: Amount | N1: UNCLAIMED
A2: Numbers | C2: sold | K2: expired | L2: Unclaimed | N2: Percentage
C3: =SUM(C6:C485) -> 126435 | K3: =SUM(L6:L374) -> 7560 | L3: =SUM(L6:L485) -> 10480 | N3: =L3/C3 -> 0.082888441
A4: No | B4: Unit | C4: Sales | J4: Service(s) | K4: Value | L4: $ | M4: issued on | N4: expires at | O4: Customer | P4: Phone | Q4: e-mail
B5: Price | C5: Price | D5: (USED) | J5: left | K5: left | L5: left | O5: Name
A6: 171629 | B6: 45 | C6: =SUM(B6*5) -> 225 | D6: 0 | E6: 0 | F6: 0 | G6: 0 | H6: 0 | I6: 0 | J6: =SUM(D6:I6) -> 0 | K6: =SUM(D6:H6) -> 0 | L6: =B6*K6 -> 0 | M6: JAN 06 2018 | N6: JAN 06 2020
A7: 171630 | B7: 60 | C7: =SUM(B7*5) -> 300 | D7: 0 | E7: 0 | F7: 0 | G7: 0 | H7: 0 | I7: 0 | J7: =SUM(D7:I7) -> 0 | K7: =SUM(D7:H7) -> 0 | L7: =B7*K7 -> 0 | M7: JAN 04 2018 | N7: JAN 04 2020
A8: 171631 | B8: 60 | C8: =SUM(B8*5) -> 300 | D8: 0 | E8: 0 | F8: 1 | G8: 1 | H8: 1 | I8: 1 | J8: =SUM(D8:I8) -> 4 | K8: =SUM(D8:H8) -> 3 | L8: =B8*K8 -> 180 | M8: JAN 07 2018 | N8: JAN 07 2020
A9: 171632 | B9: 50 | C9: =SUM(B9*5) -> 250 | D9: 0 | E9: 0 | F9: 0 | G9: 0 | H9: 0 | I9: 0 | J9: =SUM(D9:I9) -> 0 | K9: =SUM(D9:H9) -> 0 | L9: =B9*K9 -> 0 | M9: JAN 07 2018 | N9: JAN 07 2020
A10: 171633 | B10: 60 | C10: =SUM(B10*5) -> 300 | D10: 0 | E10: 0 | F10: 0 | G10: 0 | H10: 0 | I10: 1 | J10: =SUM(D10:I10) -> 1 | K10: =SUM(D10:H10) -> 0 | L10: =B10*K10 -> 0 | M10: JAN 08 2018 | N10: JAN 08 2020
A11: 171634 | B11: 60 | C11: =SUM(B11*5) -> 300 | D11: 0 | E11: 0 | F11: 0 | G11: 0 | H11: 0 | I11: 0 | J11: =SUM(D11:I11) -> 0 | K11: =SUM(D11:H11) -> 0 | L11: =B11*K11 -> 0 | M11: JAN 10 2018 | N11: JAN 10 2020
A12: 171635 | B12: 45 | C12: =SUM(B12*5) -> 225 | D12: 0 | E12: 0 | F12: 0 | G12: 0 | H12: 0 | I12: 0 | J12: =SUM(D12:I12) -> 0 | K12: =SUM(D12:H12) -> 0 | L12: =B12*K12 -> 0 | M12: JAN 12 2018 | N12: JAN 12 2020
A13: 171636 | B13: 60 | C13: =SUM(B13*5) -> 300 | D13: 0 | E13: 0 | F13: 1 | G13: 1 | H13: 1 | I13: 1 | J13: =SUM(D13:I13) -> 4 | K13: =SUM(D13:H13) -> 3 | L13: =B13*K13 -> 180 | M13: JAN 14 2018 | N13: JAN 14 2020
A14: 171637 | B14: 45 | C14: =SUM(B14*5) -> 225 | D14: 0 | E14: 0 | F14: 0 | G14: 0 | H14: 0 | I14: 0 | J14: =SUM(D14:I14) -> 0 | K14: =SUM(D14:H14) -> 0 | L14: =B14*K14 -> 0 | M14: JAN 15 2018 | N14: JAN 15 2020
A15: 171638 | B15: 60 | C15: =SUM(B15*5) -> 300 | D15: 0 | E15: 0 | F15: 0 | G15: 0 | H15: 0 | I15: 0 | J15: =SUM(D15:I15) -> 0 | K15: =SUM(D15:H15) -> 0 | L15: =B15*K15 -> 0 | M15: JAN 15 2018 | N15: JAN 15 2020
A16: 171639 | B16: 35 | C16: =SUM(B16*10) -> 350 | D16: 0 | E16: 0 | F16: 0 | G16: 0 | H16: 0 | I16: 0 | J16: =SUM(D16:I17) -> 1 | K16: =SUM(D16:H17) -> 0 | L16: =B16*K16 -> 0 | M16: JAN 17 2018 | N16: JAN 17 2020
D17: 0 | E17: 0 | F17: 0 | G17: 0 | H17: 0 | I17: 1
A18: 171640 | B18: 60 | C18: =SUM(B18*5) -> 300 | D18: 0 | E18: 0 | F18: 0 | G18: 0 | H18: 0 | I18: 0 | J18: =SUM(D18:I18) -> 0 | K18: =SUM(D18:H18) -> 0 | L18: =B18*K18 -> 0 | M18: JAN 17 2018 | N18: JAN 17 2020
A19: 171641 | B19: 0 | C19: =SUM(B19*5) -> 0 | D19: 0 | E19: 0 | F19: 1 | G19: 1 | J19: =SUM(D19:I19) -> 2 | K19: =SUM(D19:H19) -> 2 | L19: =B19*K19 -> 0 | M19: JAN 18 2018 | N19: JAN 18 2020 | O19: Compliment for Kevin
A20: 171642 | B20: 60 | C20: =SUM(B20*5) -> 300 | D20: 0 | E20: 0 | F20: 0 | G20: 0 | H20: 1 | I20: 1 | J20: =SUM(D20:I20) -> 2 | K20: =SUM(D20:H20) -> 1 | L20: =B20*K20 -> 60 | M20: JAN 18 2018 | N20: JAN 18 2020
A21: 171643 | B21: 90 | C21: =SUM(B21*5) -> 450 | D21: 0 | E21: 0 | F21: 0 | G21: 0 | H21: 0 | I21: 0 | J21: =SUM(D21:I21) -> 0 | K21: =SUM(D21:H21) -> 0 | L21: =B21*K21 -> 0 | M21: JAN 18 2018 | N21: JAN 18 2020
A22: 171644 | B22: 45 | C22: =SUM(B22*5) -> 225 | D22: 0 | E22: 0 | F22: 0 | G22: 0 | H22: 0 | I22: 0 | J22: =SUM(D22:I22) -> 0 | K22: =SUM(D22:H22) -> 0 | L22: =B22*K22 -> 0 | M22: JAN 19 2018 | N22: JAN 19 2020
A23: 171645 | B23: 60 | C23: =SUM(B23*5) -> 300 | D23: 0 | E23: 0 | F23: 1 | G23: 1 | H23: 1 | I23: 1 | J23: =SUM(D23:I23) -> 4 | K23: =SUM(D23:H23) -> 3 | L23: =B23*K23 -> 180 | M23: JAN 20 2018 | N23: JAN 20 2020
A24: 171646 | B24: 45 | C24: =SUM(B24*5) -> 225 | D24: 0 | E24: 0 | F24: 0 | G24: 0 | H24: 0 | I24: 1 | J24: =SUM(D24:I24) -> 1 | K24: =SUM(D24:H24) -> 0 | L24: =B24*K24 -> 0 | M24: JAN 20 2018 | N24: JAN 20 2020
A25: 171647 | B25: 45 | C25: =SUM(B25*5) -> 225 | D25: 0 | E25: 0 | F25: 0 | G25: 0 | H25: 0 | I25: 0 | J25: =SUM(D25:I25) -> 0 | K25: =SUM(D25:H25) -> 0 | L25: =B25*K25 -> 0 | M25: JAN 24 2018 | N25: JAN 24 2020 | O25: Extended 1 year
A26: 171648 | B26: 60 | C26: =SUM(B26*5) -> 300 | D26: 0 | E26: 0 | F26: 0 | G26: 0 | H26: 1 | I26: 1 | J26: =SUM(D26:I26) -> 2 | K26: =SUM(D26:H26) -> 1 | L26: =B26*K26 -> 60 | M26: JAN 24 2018 | N26: JAN 24 2020 | O26: Extended 1 year
A27: 171649 | B27: 60 | C27: =SUM(B27*5) -> 300 | D27: 0 | E27: 0 | F27: 0 | G27: 0 | H27: 0 | I27: 0 | J27: =SUM(D27:I27) -> 0 | K27: =SUM(D27:H27) -> 0 | L27: =B27*K27 -> 0 | M27: JAN 26 2018 | N27: JAN 26 2020
A28: 171650 | B28: 45 | C28: =SUM(B28*5) -> 225 | D28: 0 | E28: 0 | F28: 0 | G28: 0 | H28: 0 | I28: 0 | J28: =SUM(D28:I28) -> 0 | K28: =SUM(D28:H28) -> 0 | L28: =B28*K28 -> 0 | M28: JAN 27 2018 | N28: JAN 27 2020
A29: 171651 | B29: 60 | C29: =SUM(B29*5) -> 300 | D29: 0 | E29: 0 | F29: 0 | G29: 0 | H29: 0 | I29: 0 | J29: =SUM(D29:I29) -> 0 | K29: =SUM(D29:H29) -> 0 | L29: =B29*K29 -> 0 | M29: JAN 27 2018 | N29: JAN 27 2020
A30: 171652 | B30: 45 | C30: =SUM(B30*5) -> 225 | D30: 0 | E30: 0 | F30: 0 | G30: 0 | H30: 0 | I30: 0 | J30: =SUM(D30:I30) -> 0 | K30: =SUM(D30:H30) -> 0 | L30: =B30*K30 -> 0 | M30: JAN 29 2018 | N30: JAN 29 2020
A31: 171653 | B31: 45 | C31: =SUM(B31*5) -> 225 | D31: 0 | E31: 0 | F31: 0 | G31: 0 | H31: 0 | I31: 0 | J31: =SUM(D31:I31) -> 0 | K31: =SUM(D31:H31) -> 0 | L31: =B31*K31 -> 0 | M31: JAN 29 2018 | N31: JAN 29 2020
A32: 171654 | B32: 45 | C32: =SUM(B32*5) -> 225 | D32: 0 | E32: 0 | F32: 0 | G32: 0 | H32: 0 | I32: 1 | J32: =SUM(D32:I32) -> 1 | K32: =SUM(D32:H32) -> 0 | L32: =B32*K32 -> 0 | M32: FEB 01 2018 | N32: FEB 01 2020
A33: 171655 | B33: 45 | C33: =SUM(B33*5) -> 225 | D33: 0 | E33: 0 | F33: 0 | G33: 0 | H33: 0 | I33: 0 | J33: =SUM(D33:I33) -> 0 | K33: =SUM(D33:H33) -> 0 | L33: =B33*K33 -> 0 | M33: FEB 01 2018 | N33: FEB 01 2020
A34: 171656 | B34: 60 | C34: =SUM(B34*5) -> 300 | D34: 0 | E34: 0 | F34: 0 | G34: 0 | H34: 0 | I34: 0 | J34: =SUM(D34:I34) -> 0 | K34: =SUM(D34:H34) -> 0 | L34: =B34*K34 -> 0 | M34: FEB 01 2018 | N34: FEB 01 2020
A35: 171657 | B35: 45 | C35: =SUM(B35*5) -> 225 | D35: 0 | E35: 0 | F35: 0 | G35: 0 | H35: 0 | I35: 0 | J35: =SUM(D35:I35) -> 0 | K35: =SUM(D35:H35) -> 0 | L35: =B35*K35 -> 0 | M35: FEB 02 2018 | N35: FEB 02 2020
A36: 171658 | B36: 60 | C36: =SUM(B36*5) -> 300 | D36: 0 | E36: 0 | F36: 0 | G36: 0 | H36: 1 | I36: 1 | J36: =SUM(D36:I36) -> 2 | K36: =SUM(D36:H36) -> 1 | L36: =B36*K36 -> 60 | M36: FEB 03 2018 | N36: FEB 03 2020
A37: 171659 | B37: 60 | C37: =SUM(B37*5) -> 300 | D37: 0 | E37: 0 | F37: 0 | G37: 0 | H37: 0 | I37: 1 | J37: =SUM(D37:I37) -> 1 | K37: =SUM(D37:H37) -> 0 | L37: =B37*K37 -> 0 | M37: FEB 04 2018 | N37: FEB 04 2020
A38: 171660 | B38: 60 | C38: =SUM(B38*5) -> 300 | D38: 0 | E38: 0 | F38: 0 | G38: 0 | H38: 0 | I38: 0 | J38: =SUM(D38:I38) -> 0 | K38: =SUM(D38:H38) -> 0 | L38: =B38*K38 -> 0 | M38: FEB 04 2018 | N38: FEB 04 2020
... A52: 171674 | B52: 45 | C52: =SUM(B52*5) -> 225 | D52: 0 | E52: 0 | F52: 1 | G52: 1 | H52: 1 | I52: 1 | J52: =SUM(D52:I52) -> 4 | K52: =SUM(D52:H52) -> 3 | L52: =B52*K52 -> 135 | M52: FEB 17 2018 | N52: FEB 17 2020
A53: 171675 | B53: 100 | C53: =SUM(B53*5) -> 500 | D53: 0 | E53: 0 | F53: 0 | G53: 0 | H53: 0 | I53: 0 | J53: =SUM(D53:I53) -> 0 | K53: =SUM(D53:H53) -> 0 | L53: =B53*K53 -> 0 | M53: FEB 17 2018 | N53: FEB 17 2020 | O53: EXTENDED 1 DLX
...

Sheet 2019
C1: Amount | L1: Amount | N1: UNCLAIMED
A2: Numbers | C2: sold | L2: Unclaimed | N2: Percentage
C3: =SUM(C6:C824) -> 162030 | L3: =SUM(L6:L621) -> 21735 | N3: =L3/C3 -> 0.13414183
A4: No | B4: Unit | C4: Sales | J4: Service(s) | K4: Value | L4: $ | M4: issued on | N4: expires at | O4: Customer | P4: Phone | Q4: e-mail
B5: Price | C5: Price | D5: (USED) | J5: left | K5: left | L5: left | O5: Name
A6: 182107 | B6: 60 | C6: =SUM(B6*5) -> 300 | D6: 0 | E6: 0 | F6: 0 | G6: 0 | H6: 0 | I6: 1 | J6: =SUM(D6:I6) -> 1 | K6: =SUM(D6:H6) -> 0 | L6: =B6*K6 -> 0 | M6: JAN 03 2019 | N6: JAN 03 2021
A7: 182108 | B7: 60 | C7: =SUM(B7*5) -> 300 | D7: 0 | E7: 0 | F7: 0 | G7: 0 | H7: 0 | I7: 0 | J7: =SUM(D7:I7) -> 0 | K7: =SUM(D7:H7) -> 0 | L7: =B7*K7 -> 0 | M7: JAN 05 2019 | N7: JAN 05 2021 | O7: EXTRA 1 DLX
A8: 182109 | B8: 90 | C8: =SUM(B8*5) -> 450 | D8: 0 | E8: 0 | F8: 1 | G8: 1 | H8: 1 | I8: 1 | J8: =SUM(D8:I8) -> 4 | K8: =SUM(D8:H8) -> 3 | L8: =B8*K8 -> 270 | M8: JAN 05 2019 | N8: JAN 05 2021
A9: 182110 | B9: 45 | C9: =SUM(B9*5) -> 225 | D9: 0 | E9: 0 | F9: 0 | G9: 0 | H9: 0 | I9: 0 | J9: =SUM(D9:I9) -> 0 | K9: =SUM(D9:H9) -> 0 | L9: =B9*K9 -> 0 | M9: JAN 06 2019 | N9: JAN 06 2021
A10: 182111 | B10: 45 | C10: =SUM(B10*5) -> 225 | D10: 0 | E10: 0 | F10: 0 | G10: 0 | H10: 0 | I10: 0 | J10: =SUM(D10:I10) -> 0 | K10: =SUM(D10:H10) -> 0 | L10: =B10*K10 -> 0 | M10: JAN 09 2019 | N10: JAN 09 2021
A11: 182112 | B11: 50 | C11: =SUM(B11*5) -> 250 | D11: 0 | E11: 0 | F11: 0 | G11: 0 | H11: 0 | I11: 0 | J11: =SUM(D11:I11) -> 0 | K11: =SUM(D11:H11) -> 0 | L11: =B11*K11 -> 0 | M11: JAN 09 2019 | N11: JAN 09 2021
A12: 182113 | B12: 60 | C12: =SUM(B12*5) -> 300 | D12: 0 | E12: 0 | F12: 0 | G12: 0 | H12: 0 | I12: 0 | J12: =SUM(D12:I12) -> 0 | K12: =SUM(D12:H12) -> 0 | L12: =B12*K12 -> 0 | M12: JAN 10 2019 | N12: JAN 10 2021
A13: 182114 | B13: 60 | C13: =SUM(B13*5) -> 300 | D13: 0 | E13: 0 | F13: 0 | G13: 0 | H13: 0 | I13: 1 | J13: =SUM(D13:I13) -> 1 | K13: =SUM(D13:H13) -> 0 | L13: =B13*K13 -> 0 | M13: JAN 11 2019 | N13: JAN 11 2021
A14: 182115 | B14: 45 | C14: =SUM(B14*5) -> 225 | D14: 0 | E14: 0 | F14: 0 | G14: 0 | H14: 0 | I14: 0 | J14: =SUM(D14:I14) -> 0 | K14: =SUM(D14:H14) -> 0 | L14: =B14*K14 -> 0 | M14: JAN 12 2019 | N14: JAN 12 2021
A15: 182116 | B15: 45 | C15: =SUM(B15*5) -> 225 | D15: 0 | E15: 0 | F15: 0 | G15: 0 | H15: 0 | I15: 0 | J15: =SUM(D15:I15) -> 0 | K15: =SUM(D15:H15) -> 0 | L15: =B15*K15 -> 0 | M15: JAN 12 2019 | N15: JAN 12 2021
A16: 182117 | B16: 60 | C16: =SUM(B16*5) -> 300 | D16: 0 | E16: 0 | F16: 0 | G16: 0 | H16: 0 | I16: 0 | J16: =SUM(D16:I16) -> 0 | K16: =SUM(D16:H16) -> 0 | L16: =B16*K16 -> 0 | M16: JAN 12 2019 | N16: JAN 12 2021
A17: 182118 | B17: 45 | C17: =SUM(B17*5) -> 225 | D17: 0 | E17: 0 | F17: 0 | G17: 0 | H17: 0 | I17: 1 | J17: =SUM(D17:I17) -> 1 | K17: =SUM(D17:H17) -> 0 | L17: =B17*K17 -> 0 | M17: JAN 13 2019 | N17: JAN 13 2021
A18: 182119 | B18: 90 | C18: =SUM(B18*5) -> 450 | D18: 0 | E18: 0 | F18: 0 | G18: 0 | H18: 0 | I18: 0 | J18: =SUM(D18:I18) -> 0 | K18: =SUM(D18:H18) -> 0 | L18: =B18*K18 -> 0 | M18: JAN 14 2019 | N18: JAN 14 2021
A19: 182120 | B19: 45 | C19: =SUM(B19*5) -> 225 | D19: 0 | E19: 0 | F19: 0 | G19: 0 | H19: 1 | I19: 1 | J19: =SUM(D19:I19) -> 2 | K19: =SUM(D19:H19) -> 1 | L19: =B19*K19 -> 45 | M19: JAN 15 2019 | N19: JAN 15 2021
... A42: 192143 | B42: 60 | C42: =SUM(B42*5) -> 300 | D42: 0 | E42: 0 | F42: 0 | G42: 0 | H42: 0 | I42: 0 | J42: =SUM(D42:I42) -> 0 | K42: =SUM(D42:H42) -> 0 | L42: =B42*K42 -> 0 | M42: JAN 27 2019 | N42: JAN 27 2021
A43: 192144 | C43: =SUM(B43*5) -> 0 | D43: 1 | E43: 1 | F43: 1 | G43: 1 | H43: 1 | I43: 1 | J43: =SUM(D43:I43) -> 6 | K43: =SUM(D43:H43) -> 5 | L43: =B43*K43 -> 0 | M43: Cancel to buy, returned
A44: 192145 | B44: 45 | C44: =SUM(B44*5) -> 225 | D44: 0 | E44: 0 | F44: 0 | G44: 0 | H44: 0 | I44: 0 | J44: =SUM(D44:I44) -> 0 | K44: =SUM(D44:H44) -> 0 | L44: =B44*K44 -> 0 | M44: JAN 28 2019 | N44: JAN 28 2021
A45: 192146 | B45: 45 | C45: =SUM(B45*5) -> 225 | D45: 0 | E45: 0 | F45: 0 | G45: 0 | H45: 0 | I45: 0 | J45: =SUM(D45:I45) -> 0 | K45: =SUM(D45:H45) -> 0 | L45: =B45*K45 -> 0 | M45: JAN 29 2019 | N45: JAN 29 2021
A46: 192147 | B46: 45 | C46: =SUM(B46*5) -> 225 | D46: 0 | E46: 0 | F46: 0 | G46: 0 | H46: 0 | I46: 0 | J46: =SUM(D46:I46) -> 0 | K46: =SUM(D46:H46) -> 0 | L46: =B46*K46 -> 0 | M46: JAN 30 2019 | N46: JAN 30 2021
A47: 192148 | B47: 60 | C47: =SUM(B47*5) -> 300 | D47: 0 | E47: 0 | F47: 0 | G47: 0 | H47: 0 | I47: 0 | J47: =SUM(D47:I47) -> 0 | K47: =SUM(D47:H47) -> 0 | L47: =B47*K47 -> 0 | M47: JAN 30 2019 | N47: JAN 30 2021
A48: 192149 | B48: 60 | C48: =SUM(B48*5) -> 300 | D48: 0 | E48: 0 | F48: 0 | G48: 0 | H48: 0 | I48: 0 | J48: =SUM(D48:I48) -> 0 | K48: =SUM(D48:H48) -> 0 | L48: =B48*K48 -> 0 | M48: JAN 31 2019 | N48: JAN 31 2021
A49: 192150 | B49: 60 | C49: =SUM(B49*5) -> 300 | D49: 0 | E49: 0 | F49: 1 | G49: 1 | H49: 1 | I49: 1 | J49: =SUM(D49:I49) -> 4 | K49: =SUM(D49:H49) -> 3 | L49: =B49*K49 -> 180 | M49: FEB 01 2019 | N49: FEB 01 2021
A50: 192151 | B50: 45 | C50: =SUM(B50*5) -> 225 | D50: 0 | E50: 0 | F50: 0 | G50: 0 | H50: 0 | I50: 0 | J50: =SUM(D50:I50) -> 0 | K50: =SUM(D50:H50) -> 0 | L50: =B50*K50 -> 0 | M50: FEB 01 2019 | N50: FEB 01 2021
A51: 192152 | B51: 45 | C51: =SUM(B51*5) -> 225 | D51: 0 | E51: 0 | F51: 0 | G51: 0 | H51: 0 | I51: 0 | J51: =SUM(D51:I51) -> 0 | K51: =SUM(D51:H51) -> 0 | L51: =B51*K51 -> 0 | M51: FEB 01 2019 | N51: FEB 01 2021
A52: 192153 | B52: 60 | C52: =SUM(B52*5) -> 300 | D52: 0 | E52: 0 | F52: 0 | G52: 0 | H52: 0 | I52: 0 | J52: =SUM(D52:I52) -> 0 | K52: =SUM(D52:H52) -> 0 | L52: =B52*K52 -> 0 | M52: FEB 02 2019 | N52: FEB 02 2021
A53: 192154 | B53: 70 | C53: =SUM(B53*5) -> 350 | D53: 0 | E53: 0 | F53: 0 | G53: 0 | H53: 0 | I53: 0 | J53: =SUM(D53:I53) -> 0 | K53: =SUM(D53:H53) -> 0 | L53: =B53*K53 -> 0 | M53: FEB 02 2019 | N53: FEB 02 2021
A54: 192155 | B54: 70 | C54: =SUM(B54*5) -> 350 | D54: 0 | E54: 0 | F54: 0 | G54: 0 | H54: 0 | I54: 0 | J54: =SUM(D54:I54) -> 0 | K54: =SUM(D54:H54) -> 0 | L54: =B54*K54 -> 0 | M54: FEB 02 2019 | N54: FEB 02 2021
A55: 192156 | B55: 50 | C55: =SUM(B55*5) -> 250 | D55: 0 | E55: 1 | F55: 1 | G55: 1 | H55: 1 | I55: 1 | J55: =SUM(D55:I55) -> 5 | K55: =SUM(D55:H55) -> 4 | L55: =B55*K55 -> 200 | M55: FEB 03 2019 | N55: FEB 03 2021
... A61: 192162 | B61: 45 | C61: =SUM(B61*5) -> 225 | D61: 0 | E61: 0 | F61: 0 | G61: 0 | H61: 0 | I61: 0 | J61: =SUM(D61:I61) -> 0 | K61: =SUM(D61:H61) -> 0 | L61: =B61*K61 -> 0 | M61: FEB 06 2019 | N61: FEB 06 2021
A62: 192163 | B62: 45 | C62: =SUM(B62*5) -> 225 | D62: 0 | E62: 0 | F62: 0 | G62: 0 | H62: 0 | I62: 0 | J62: =SUM(D62:I62) -> 0 | K62: =SUM(D62:H62) -> 0 | L62: =B62*K62 -> 0 | M62: FEB 07 2019 | N62: FEB 07 2021 | O62: TRANSFERRED ONE DLX FROM OLD GV
A63: 192164 | B63: 90 | C63: =SUM(B63*5) -> 450 | D63: 0 | E63: 0 | F63: 0 | G63: 0 | H63: 1 | I63: 1 | J63: =SUM(D63:I63) -> 2 | K63: =SUM(D63:H63) -> 1 | L63: =B63*K63 -> 90 | M63: FEB 07 2019 | N63: FEB 07 2021
A64: 192165 | B64: 60 | C64: =SUM(B64*5) -> 300 | D64: 0 | E64: 0 | F64: 0 | G64: 0 | H64: 0 | I64: 0 | J64: =SUM(D64:I64) -> 0 | K64: =SUM(D64:H64) -> 0 | L64: =B64*K64 -> 0 | M64: FEB 08 2019 | N64: FEB 08 2021
A65: 192166 | B65: 60 | C65: =SUM(B65*5) -> 300 | D65: 0 | E65: 0 | F65: 0 | G65: 1 | H65: 1 | I65: 1 | J65: =SUM(D65:I65) -> 3 | K65: =SUM(D65:H65) -> 2 | L65: =B65*K65 -> 120 | M65: FEB 08 2019 | N65: FEB 08 2021
A66: 192167 | B66: 50 | C66: =SUM(B66*5) -> 250 | D66: 0 | E66: 0 | F66: 0 | G66: 0 | H66: 0 | I66: 0 | J66: =SUM(D66:I66) -> 0 | K66: =SUM(D66:H66) -> 0 | L66: =B66*K66 -> 0 | M66: FEB 09 2019 | N66: FEB 09 2021
A67: 192168 | B67: 45 | C67: =SUM(B67*5) -> 225 | D67: 0 | E67: 0 | F67: 0 | G67: 0 | H67: 0 | I67: 0 | J67: =SUM(D67:I67) -> 0 | K67: =SUM(D67:H67) -> 0 | L67: =B67*K67 -> 0 | M67: FEB 09 2019 | N67: FEB 09 2021
...

Sheet 2020
C1: Amount | L1: Amount | N1: UNCLAIMED
A2: Numbers | C2: sold | L2: Unclaimed | N2: Percentage
C3: =SUM(C6:C222) -> 55735 | L3: =SUM(L6:L2550) -> 14434
A4: No | B4: Unit | C4: Sales | J4: Service(s) | K4: Value | L4: $ | M4: issued on | N4: expires at
B5: Price | C5: Price | D5: (USED) | J5: left | K5: left | L5: left
A6: 202718 | B6: 45 | C6: =SUM(B6*5) -> 225 | D6: 0 | E6: 0 | F6: 0 | G6: 0 | H6: 0 | I6: 0 | J6: =SUM(D6:I6) -> 0 | K6: =SUM(D6:H6) -> 0 | L6: =B6*K6 -> 0 | M6: JAN 02 2020 | N6: JAN 02 2022
A7: 202719 | B7: 45 | C7: =SUM(B7*5) -> 225 | D7: 0 | E7: 0 | F7: 0 | G7: 0 | H7: 1 | I7: 1 | J7: =SUM(D7:I7) -> 2 | K7: =SUM(D7:H7) -> 1 | L7: =B7*K7 -> 45 | M7: JAN 02 2020 | N7: JAN 02 2022
