Workbook

Sheet MON
A1: B2 Daily Report
A2: 44991 | H2: WEATHER | J2: SUNNY | L2: REPORT BY | O2: HENDRA | R2: TOTAL STAFF | T2: 5 | X2: Merchant machine usage at B2 | AA2: Settle amount | AI2: Merchant machine usage at GA | AL2: Settle amount
A4: No | B4: Docket No | C4: Reg No | D4: Mobile | E4: Gender | F4: TIME | G4: Service | H4: CASH | I4: CARD | J4: RSL | K4: GV | L4: GV CASH | M4: GV CARD | N4: O/Taker | O4: Comment | R4: NAME | S4: Time In | T4: Time out | U4: Total Hours | Z4: B2 machine | AA4: BLH machine | AB4: Wongo | AE4: B2 machine | AF4: BLH machine | AG4: Wongo | AK4: GA machine | AL4: BLH machine | AM4: Wongo | AP4: GA machine | AQ4: BLH machine | AR4: Wongo
A5: 1 | B5: 14125 | C5: KEN838 | D5: 0412038383 | E5: M | F5: 905 | G5: PCL | J5: =IF(G5="RSL","55","0") -> 0 | K5: 79 | N5: HENDRA | O5: 22012 (6/6) | R5: HENDRA | S5: 0.33333333 | T5: 0.70833333 | U5: =(T5-S5)*24 -> 9 | X5: NOV | Y5: 1 | AD5: 16 | AI5: NOV | AJ5: 1 | AO5: 16
A6: 2 | B6: 14126 | C6: ENA66S | D6: 0416951959 | E6: F | F6: 915 | G6: PCL | J6: =IF(G6="RSL","55","0") -> 0 | K6: 79 | M6: 475 | N6: HENDRA | O6: 23225 (1/6) | R6: SHIVAM | S6: 0.33333333 | T6: 0.70833333 | U6: =(T6-S6)*24 -> 9 | W6: M | Y6: 2 | AD6: 17 | AJ6: 2 | AO6: 17
A7: 3 | B7: 14127 | C7: EEY61G | D7: 0401995714 | E7: F | F7: 930 | G7: X | H7: 95 | J7: =IF(G7="RSL","55","0") -> 0 | K7: =IF(G7="GVS","37.5",IF(G7="GVM","41.5",IF(G7="GVL","50",IF(G7="PCS","45.8",IF(G7="PCM","50",IF(G7="PCL","58.3","0")))))) -> 0 | N7: HENDRA | R7: JAMES | S7: 0.35416667 | T7: 0.70833333 | U7: =(T7-S7)*24 -> 8.5 | W7: F | Y7: 3 | AD7: 18 | AJ7: 3 | AO7: 18
A8: 4 | B8: 14128 | C8: CN800 | D8: 0418882000 | E8: F | F8: 935 | G8: D | I8: 75 | J8: =IF(G8="RSL","55","0") -> 0 | K8: =IF(G8="GVS","37.5",IF(G8="GVM","41.5",IF(G8="GVL","50",IF(G8="PCS","45.8",IF(G8="PCM","50",IF(G8="PCL","58.3","0")))))) -> 0 | N8: HENDRA | R8: ARIANTO | S8: 0.375 | T8: 0.625 | U8: =(T8-S8)*24 -> 6 | Y8: 4 | AD8: 19 | AJ8: 4 | AO8: 19
A9: 5 | B9: 14129 | C9: JH2211 | D9: 0412771876 | E9: F | F9: 945 | G9: X | I9: 95 | J9: =IF(G9="RSL","55","0") -> 0 | K9: =IF(G9="GVS","37.5",IF(G9="GVM","41.5",IF(G9="GVL","50",IF(G9="PCS","45.8",IF(G9="PCM","50",IF(G9="PCL","58.3","0")))))) -> 0 | N9: HENDRA | R9: VINNY | S9: 0.45833333 | T9: 0.70833333 | U9: =(T9-S9)*24 -> 6 | X9: EXCL RSL | Y9: 5 | AD9: 20 | AJ9: 5 | AO9: 20
A10: 6 | B10: 14130 | C10: CE32DD | D10: 0416155783 | E10: F | F10: 1010 | G10: D | I10: 75 | J10: =IF(G10="RSL","55","0") -> 0 | K10: =IF(G10="GVS","37.5",IF(G10="GVM","41.5",IF(G10="GVL","50",IF(G10="PCS","45.8",IF(G10="PCM","50",IF(G10="PCL","58.3","0")))))) -> 0 | N10: SHIVAM | U10: =(T10-S10)*24 -> 0 | Y10: 6 | AD10: 21 | AJ10: 6 | AO10: 21
A11: 7 | B11: 14131 | C11: EVU18U | D11: 0499080777 | E11: F | F11: 1030 | G11: GV | J11: =IF(G11="RSL","55","0") -> 0 | K11: 0 | L11: 300 | N11: SHIVAM | O11: XD-50-176 TO 181 | U11: =(T11-S11)*24 -> 0 | Y11: 7 | AD11: 22 | AJ11: 7 | AO11: 22
A12: 8 | B12: 14132 | C12: EXD61Y | D12: 0407213067 | E12: F | F12: 1050 | G12: D | I12: 75 | J12: =IF(G12="RSL","55","0") -> 0 | K12: =IF(G12="GVS","37.5",IF(G12="GVM","41.5",IF(G12="GVL","50",IF(G12="PCS","45.8",IF(G12="PCM","50",IF(G12="PCL","58.3","0")))))) -> 0 | N12: SHIVAM | U12: =(T12-S12)*24 -> 0 | V12: + | Y12: 8 | AD12: 23 | AJ12: 8 | AO12: 23
A13: 9 | B13: 14133 | C13: DTY90V | D13: 0439592230 | E13: M | F13: 1100 | G13: H | I13: 100 | J13: =IF(G13="RSL","55","0") -> 0 | K13: =IF(G13="GVS","37.5",IF(G13="GVM","41.5",IF(G13="GVL","50",IF(G13="PCS","45.8",IF(G13="PCM","50",IF(G13="PCL","58.3","0")))))) -> 0 | N13: SHIVAM | U13: =(T13-S13)*24 -> 0 | Y13: 9 | AD13: 24 | AJ13: 9 | AO13: 24
A14: 10 | B14: 14134 | C14: NXQ74D | D14: 0408518552 | E14: F | F14: 1100 | G14: X | H14: 75 | J14: =IF(G14="RSL","55","0") -> 0 | K14: =IF(G14="GVS","37.5",IF(G14="GVM","41.5",IF(G14="GVL","50",IF(G14="PCS","45.8",IF(G14="PCM","50",IF(G14="PCL","58.3","0")))))) -> 0 | N14: SHIVAM | U14: =(T14-S14)*24 -> 0 | Y14: 10 | AD14: 25 | AJ14: 10 | AO14: 25
A15: 11 | B15: 14135 | C15: ERF78A | D15: 0432015255 | E15: F | F15: 1100 | G15: PCL | J15: =IF(G15="RSL","55","0") -> 0 | K15: 125 | N15: SHIVAM | O15: 22044 (4/6) H | U15: =(T15-S15)*24 -> 0 | Y15: 11 | AD15: 26 | AJ15: 11 | AO15: 26
A16: 12 | B16: 14136 | C16: EUP53B | D16: 0410043981 | E16: F | F16: 1115 | G16: X | I16: 75 | J16: =IF(G16="RSL","55","0") -> 0 | K16: =IF(G16="GVS","37.5",IF(G16="GVM","41.5",IF(G16="GVL","50",IF(G16="PCS","45.8",IF(G16="PCM","50",IF(G16="PCL","58.3","0")))))) -> 0 | N16: SHIVAM | R16: =H32/U16 -> 0.54545455 | S16: =H32/(U16-U5) -> 0.71186441 | T16: =C32/U16 -> 43.116883 | U16: =SUM(U5:U15) -> 38.5 | Y16: 12 | AD16: 27 | AJ16: 12 | AO16: 27
A17: 13 | B17: 14137 | C17: EKR80D | D17: 0414337002 | E17: M | F17: 1145 | G17: W/O | I17: 65 | J17: =IF(G17="RSL","55","0") -> 0 | K17: =IF(G17="GVS","37.5",IF(G17="GVM","41.5",IF(G17="GVL","50",IF(G17="PCS","45.8",IF(G17="PCM","50",IF(G17="PCL","58.3","0")))))) -> 0 | N17: SHIVAM | R17: Cars/T Hr ① | S17: Cars/T Hr ② | T17: Sales/T Hr | U17: Total Hours | Y17: 13 | AD17: 28 | AJ17: 13 | AO17: 28
A18: 14 | B18: 14138 | C18: EBT61V | D18: 0416281895 | E18: F | F18: 1145 | G18: D | I18: 55 | J18: =IF(G18="RSL","55","0") -> 0 | K18: =IF(G18="GVS","37.5",IF(G18="GVM","41.5",IF(G18="GVL","50",IF(G18="PCS","45.8",IF(G18="PCM","50",IF(G18="PCL","58.3","0")))))) -> 0 | N18: SHIVAM | R18: ITEM | S18: QTY | T18: AMT | U18: RMKS | Y18: 14 | AD18: 29 | AJ18: 14 | AO18: 29
A19: 15 | B19: 14139 | C19: VW278 | D19: 0417674600 | E19: F | F19: 1205 | G19: H | H19: 115 | J19: =IF(G19="RSL","55","0") -> 0 | K19: =IF(G19="GVS","37.5",IF(G19="GVM","41.5",IF(G19="GVL","50",IF(G19="PCS","45.8",IF(G19="PCM","50",IF(G19="PCL","58.3","0")))))) -> 0 | N19: HENDRA | O19: $5 OFF | R19: GV | S19: =COUNT(L5:M29,L37:M61,L69:M93) -> 2 | T19: =SUM(L5:M29,L37:M61,L69:M93) -> 775 | Y19: 15 | AD19: 30 | AJ19: 15 | AO19: 30
A20: 16 | B20: 14140 | C20: C1092M | D20: 0423229668 | E20: F | F20: 1325 | G20: X | I20: 120 | J20: =IF(G20="RSL","55","0") -> 0 | K20: =IF(G20="GVS","37.5",IF(G20="GVM","41.5",IF(G20="GVL","50",IF(G20="PCS","45.8",IF(G20="PCM","50",IF(G20="PCL","58.3","0")))))) -> 0 | N20: HENDRA | O20: DUST | AD20: 31 | AO20: 31
A21: 17 | B21: 14141 | C21: JKD988 | D21: 0412822216 | E21: M | F21: 1330 | G21: PCL | J21: =IF(G21="RSL","55","0") -> 0 | K21: 79 | N21: SHIVAM | O21: 22186(2/6)
A22: 18 | B22: 14142 | C22: DLY25Y | D22: 0421050164 | E22: M | F22: 1400 | G22: W/O | I22: 65 | J22: =IF(G22="RSL","55","0") -> 0 | K22: =IF(G22="GVS","37.5",IF(G22="GVM","41.5",IF(G22="GVL","50",IF(G22="PCS","45.8",IF(G22="PCM","50",IF(G22="PCL","58.3","0")))))) -> 0 | N22: SHIVAM | AD22: Total | AE22: =SUM(Z5:Z19,AE5:AE20) -> 0 | AF22: =SUM(AA5:AA19,AF5:AF20,) -> 0 | AG22: =SUM(AB5:AB19,AG5:AG20) -> 0 | AO22: Total | AP22: =SUM(AK5:AK19,AP5:AP20) -> 0 | AQ22: =SUM(AL5:AL19,AQ5:AQ20,) -> 0 | AR22: =SUM(AM5:AM19,AR5:AR20) -> 0
A23: 19 | B23: 14143 | C23: CV57AO | D23: 0435117046 | E23: F | F23: 1415 | G23: D | I23: 55 | J23: =IF(G23="RSL","55","0") -> 0 | K23: =IF(G23="GVS","37.5",IF(G23="GVM","41.5",IF(G23="GVL","50",IF(G23="PCS","45.8",IF(G23="PCM","50",IF(G23="PCL","58.3","0")))))) -> 0 | N23: HENDRA
A24: 20 | B24: 14144 | C24: DYZ80J | D24: 0481215048 | E24: F | F24: 1420 | G24: PCS | J24: =IF(G24="RSL","55","0") -> 0 | K24: 63 | N24: HENDRA | O24: 22056(1/6) | R24: SMALL | S24: MEDIUM | T24: LARGE | U24: TOTAL | AD24: B2/GA TOTAL | AE24: B2 machine | AF24: GA machine | AG24: BLH machine | AH24: Wongo machine | AI24: Sub total
A25: 21 | B25: 14145 | C25: DWR91W | D25: 0411724816 | E25: M | F25: 1500 | G25: X | I25: 95 | J25: =IF(G25="RSL","55","0") -> 0 | K25: =IF(G25="GVS","37.5",IF(G25="GVM","41.5",IF(G25="GVL","50",IF(G25="PCS","45.8",IF(G25="PCM","50",IF(G25="PCL","58.3","0")))))) -> 0 | N25: VINNY | R25: =COUNTIF(G5:G29,"GV1")+COUNTIF(G37:G61,"GV1")+COUNTIF(G69:G93,"GV1") -> 0 | S25: =COUNTIF(G5:G29,"GV2")+COUNTIF(G37:G61,"GV2")+COUNTIF(G69:G93,"GV2") -> 0 | T25: =COUNTIF(G5:G29,"GV3")+COUNTIF(G37:G61,"GV3")+COUNTIF(G69:G93,"GV3") -> 0 | U25: =((C32+(R26+S26+T26)*0.5)) -> 1660 | AD25: =SUM(AE25:AF25) -> 0 | AE25: =SUM(AE22) -> 0 | AF25: =SUM(AP22) -> 0 | AG25: =SUM(AF22+AQ22) -> 0 | AH25: =AG22+AR22 -> 0 | AI25: =SUM(AE25:AH25) -> 0
A26: 22 | J26: =IF(G26="RSL","55","0") -> 0 | K26: =IF(G26="GVS","37.5",IF(G26="GVM","41.5",IF(G26="GVL","50",IF(G26="PCS","45.8",IF(G26="PCM","50",IF(G26="PCL","58.3","0")))))) -> 0 | R26: =R25*37.5 -> 0 | S26: =S25*41.5 -> 0 | T26: =T25*50 -> 0 | X26: Branch cards
A27: 23 | J27: =IF(G27="RSL","55","0") -> 0 | K27: =IF(G27="GVS","37.5",IF(G27="GVM","41.5",IF(G27="GVL","50",IF(G27="PCS","45.8",IF(G27="PCM","50",IF(G27="PCL","58.3","0")))))) -> 0 | R27: Expense | X27: 1 | Z27: -2745
A28: 24 | J28: =IF(G28="RSL","55","0") -> 0 | K28: =IF(G28="GVS","37.5",IF(G28="GVM","41.5",IF(G28="GVL","50",IF(G28="PCS","45.8",IF(G28="PCM","50",IF(G28="PCL","58.3","0")))))) -> 0 | X28: 2
A29: 25 | J29: =IF(G29="RSL","55","0") -> 0 | K29: =IF(G29="GVS","37.5",IF(G29="GVM","41.5",IF(G29="GVL","50",IF(G29="PCS","45.8",IF(G29="PCM","50",IF(G29="PCL","58.3","0")))))) -> 0 | X29: 3
A30: Page total | H30: =SUM(H5:H29) -> 285 | I30: =SUM(I5:I29) -> 950 | J30: =J5+J6+J7+J8+J9+J10+J11+J12+J13+J14+J15+J16+J18+J19+J17+J20+J22+J23+J21+J24+J25+J26+J27+J28+J29 -> 0 | K30: =K5+K6+K7+K8+K9+K10+K11+K12+K13+K14+K15+K16+K18+K19+K17+K20+K22+K23+K21+K24+K25+K26+K27+K28+K29 -> 425 | L30: =SUM(L5:L29) -> 300 | M30: =SUM(M5:M29) -> 475 | N30: CASH | O30: CARD | P30: GV | Q30: RSL | X30: 4
A31: Daily Total | H31: =H30+H62+H94 -> 285 | I31: =I30+I62+I94 -> 950 | J31: =J30+J62+J94 -> 0 | K31: =K30+K62+K94 -> 425 | L31: =L30+L62+L94 -> 300 | M31: =M30+M62+M94 -> 475 | N31: =COUNT(H5:H29,H37:H61,H69:H93) -> 3 | O31: =COUNT(I5:I29,I37:I61,I69:I93) -> 12 | P31: =COUNTIF(G5:G29,"G*")+COUNTIF(G37:G61,"G*")+COUNTIF(G69:G93,"G*")+COUNTIF(G5:G29,"P*")+COUNTIF(G37:G61,"P*")+COUNTIF(G69:G93,"P*") -> 6 | Q31: =COUNTIF(G5:G29,"RSL")+COUNTIF(G37:G61,"RSL")+COUNTIF(G69:G93,"RSL") -> 0 | R31: CASH CLOSING | S31: =H31+L31-U28-U29-U30 -> 585 | T31: =H31+I31+L31+M31 -> 2010 | X31: Subtotal | Z31: =SUM(Z27:Z30) -> -2745
A32: TOTAL SALES | C32: =H31+I31+J31+K31 -> 1660 | F32: No of Cars | H32: =COUNT(B5:B29,B37:B61,B69:B93) -> 21 | I32: Average | K32: =C32/H32 -> 79.047619 | N32: =H31/C32 -> 0.17168675 | O32: =I31/C32 -> 0.57228916 | P32: =K31/C32 -> 0.2560241 | Q32: =J31/C32 -> 0 | R32: CARD CLOSING | S32: =I31+M31 -> 1425 | X32: B2 card | Z32: =I31 -> 950
A33: Daily Report | X33: Settlement | Z33: =SUM(Z31:Z32) -> -1795
A34: =A2 -> 44991 | H34: WEATHER | J34: =J2 -> SUNNY | L34: REPORT by | O34: =O2 -> HENDRA | R34: TOTAL STAFF | T34: =T2 -> 5
A36: No | B36: Docket No | C36: Reg No | D36: Mobile | E36: Gender | F36: TIME | G36: Service | H36: CASH | I36: CARD | J36: RSL | K36: GV | L36: GV CASH | M36: GV CARD | N36: O/Taker | O36: Comment | R36: NAME | S36: Time In | T36: Time out | U36: Total Hours
A37: =A29+1 -> 26 | J37: =IF(G37="RSL","55","0") -> 0 | K37: =IF(G37="GVS","37.5",IF(G37="GVM","41.5",IF(G37="GVL","50",IF(G37="PCS","45.8",IF(G37="PCM","50",IF(G37="PCL","58.3","0")))))) -> 0
A38: =A37+1 -> 27 | J38: =IF(G38="RSL","55","0") -> 0 | K38: =IF(G38="GVS","37.5",IF(G38="GVM","41.5",IF(G38="GVL","50",IF(G38="PCS","45.8",IF(G38="PCM","50",IF(G38="PCL","58.3","0")))))) -> 0
A39: =A38+1 -> 28 | J39: =IF(G39="RSL","55","0") -> 0 | K39: =IF(G39="GVS","37.5",IF(G39="GVM","41.5",IF(G39="GVL","50",IF(G39="PCS","45.8",IF(G39="PCM","50",IF(G39="PCL","58.3","0")))))) -> 0
A40: =A39+1 -> 29 | J40: =IF(G40="RSL","55","0") -> 0 | K40: =IF(G40="GVS","37.5",IF(G40="GVM","41.5",IF(G40="GVL","50",IF(G40="PCS","45.8",IF(G40="PCM","50",IF(G40="PCL","58.3","0")))))) -> 0
A41: =A40+1 -> 30 | J41: =IF(G41="RSL","55","0") -> 0 | K41: =IF(G41="GVS","37.5",IF(G41="GVM","41.5",IF(G41="GVL","50",IF(G41="PCS","45.8",IF(G41="PCM","50",IF(G41="PCL","58.3","0")))))) -> 0
A42: =A41+1 -> 31 | J42: =IF(G42="RSL","55","0") -> 0 | K42: =IF(G42="GVS","37.5",IF(G42="GVM","41.5",IF(G42="GVL","50",IF(G42="PCS","45.8",IF(G42="PCM","50",IF(G42="PCL","58.3","0")))))) -> 0
...

Sheet TUE
A1: B2 Daily Report
A2: 45110 | H2: WEATHER | J2: SUNNY | L2: REPORT BY | O2: HENDRA | R2: TOTAL STAFF | T2: 4 | X2: Merchant machine usage at B2 | AA2: Settle amount | AI2: Merchant machine usage at GA | AL2: Settle amount
A4: No | B4: Docket No | C4: Reg No | D4: Mobile | E4: Gender | F4: TIME | G4: Service | H4: CASH | I4: CARD | J4: RSL | K4: GV | L4: GV CASH | M4: GV CARD | N4: O/Taker | O4: Comment | R4: NAME | S4: Time In | T4: Time out | U4: Total Hours | Z4: B2 machine | AA4: BLH machine | AB4: Wongo | AE4: B2 machine | AF4: BLH machine | AG4: Wongo | AK4: GA machine | AL4: BLH machine | AM4: Wongo | AP4: GA machine | AQ4: BLH machine | AR4: Wongo
A5: 1 | B5: 14146 | C5: BZL35W | D5: 0466576221 | E5: F | F5: 915 | G5: D | I5: 55 | J5: =IF(G5="RSL","55","0") -> 0 | K5: =IF(G5="GVS","37.5",IF(G5="GVM","41.5",IF(G5="GVL","50",IF(G5="PCS","45.8",IF(G5="PCM","50",IF(G5="PCL","58.3","0")))))) -> 0 | N5: HENDRA | R5: HENDRA | S5: 0.33333333 | T5: 0.70833333 | U5: =(T5-S5)*24 -> 9 | X5: NOV | Y5: 1 | AD5: 16 | AI5: NOV | AJ5: 1 | AO5: 16
A6: 2 | B6: 14147 | C6: DAJ33N | D6: 0450070773 | E6: M | F6: 950 | G6: PCL | J6: =IF(G6="RSL","55","0") -> 0 | K6: 79.16 | N6: HENDRA | O6: 22194(2/6) | R6: ARIANTO | S6: 0.35416667 | T6: 0.48958333 | U6: =(T6-S6)*24 -> 3.25 | W6: M | Y6: 2 | AD6: 17 | AJ6: 2 | AO6: 17
A7: 3 | B7: 14148 | C7: NCB66C | D7: 0419696360 | E7: F | F7: 1000 | G7: X | H7: 75 | J7: =IF(G7="RSL","55","0") -> 0 | K7: =IF(G7="GVS","37.5",IF(G7="GVM","41.5",IF(G7="GVL","50",IF(G7="PCS","45.8",IF(G7="PCM","50",IF(G7="PCL","58.3","0")))))) -> 0 | N7: HENDRA | S7: 0.53125 | T7: 0.625 | U7: =(T7-S7)*24 -> 2.25 | W7: F | Y7: 3 | AD7: 18 | AJ7: 3 | AO7: 18
A8: 4 | B8: 14149 | C8: BXC81W | D8: 0407015117 | E8: F | F8: 1140 | G8: X | I8: 95 | J8: =IF(G8="RSL","55","0") -> 0 | K8: =IF(G8="GVS","37.5",IF(G8="GVM","41.5",IF(G8="GVL","50",IF(G8="PCS","45.8",IF(G8="PCM","50",IF(G8="PCL","58.3","0")))))) -> 0 | N8: HENDRA | R8: JAMES | S8: 0.375 | T8: 0.70833333 | U8: =(T8-S8)*24 -> 8 | Y8: 4 | AD8: 19 | AJ8: 4 | AO8: 19
A9: 5 | B9: 14150 | C9: LP127 | D9: 0408417669 | E9: M | F9: 1145 | G9: PCS | J9: =IF(G9="RSL","55","0") -> 0 | K9: 62.5 | N9: HENDRA | O9: 22090(1/6) | R9: VINNY | S9: 0.4375 | T9: 0.70833333 | U9: =(T9-S9)*24 -> 6.5 | X9: EXCL RSL | Y9: 5 | AD9: 20 | AJ9: 5 | AO9: 20
A10: 6 | B10: 14151 | C10: EEU68B | D10: 0422673942 | E10: M | F10: 1200 | G10: D | I10: 75 | J10: =IF(G10="RSL","55","0") -> 0 | K10: =IF(G10="GVS","37.5",IF(G10="GVM","41.5",IF(G10="GVL","50",IF(G10="PCS","45.8",IF(G10="PCM","50",IF(G10="PCL","58.3","0")))))) -> 0 | N10: HENDRA | R10: MONA | S10: 0.625 | T10: 0.70833333 | U10: =(T10-S10)*24 -> 2 | Y10: 6 | AD10: 21 | AJ10: 6 | AO10: 21
A11: 7 | B11: 14152 | C11: KLF723 | D11: 0425777003 | E11: M | F11: 1200 | G11: PCL | J11: =IF(G11="RSL","55","0") -> 0 | K11: 79.16 | N11: HENDRA | O11: 22006(4/6) | U11: =(T11-S11)*24 -> 0 | Y11: 7 | AD11: 22 | AJ11: 7 | AO11: 22
A12: 8 | B12: 14153 | C12: DQJ24H | D12: 0404076130 | E12: F | F12: 1235 | G12: D/CLAY | I12: 200 | J12: =IF(G12="RSL","55","0") -> 0 | K12: =IF(G12="GVS","37.5",IF(G12="GVM","41.5",IF(G12="GVL","50",IF(G12="PCS","45.8",IF(G12="PCM","50",IF(G12="PCL","58.3","0")))))) -> 0 | N12: HENDRA | U12: =(T12-S12)*24 -> 0 | Y12: 8 | AD12: 23 | AJ12: 8 | AO12: 23
A13: 9 | B13: 14154 | C13: RC8866 | D13: 0409709697 | E13: F | F13: 1240 | G13: PCL | J13: =IF(G13="RSL","55","0") -> 0 | K13: 79.16 | N13: HENDRA | O13: 22097(2/6) | U13: =(T13-S13)*24 -> 0 | Y13: 9 | AD13: 24 | AJ13: 9 | AO13: 24
A14: 10 | B14: 14155 | C14: 27KWH | D14: 0433612258 | E14: F | F14: 1245 | G14: X | I14: 75 | J14: =IF(G14="RSL","55","0") -> 0 | K14: =IF(G14="GVS","37.5",IF(G14="GVM","41.5",IF(G14="GVL","50",IF(G14="PCS","45.8",IF(G14="PCM","50",IF(G14="PCL","58.3","0")))))) -> 0 | N14: HENDRA | O14: BOOKING ONLINE | U14: =(T14-S14)*24 -> 0 | Y14: 10 | AD14: 25 | AJ14: 10 | AO14: 25
A15: 11 | B15: 14156 | C15: CNI28W | D15: 0425661609 | E15: M | F15: 1300 | G15: PCL | J15: =IF(G15="RSL","55","0") -> 0 | K15: 125 | N15: HENDRA | O15: 22118(2/6) H | U15: =(T15-S15)*24 -> 0 | Y15: 11 | AD15: 26 | AJ15: 11 | AO15: 26
A16: 12 | B16: 14157 | C16: EUH08U | D16: 0414158733 | E16: F | F16: 1300 | G16: X | I16: 75 | J16: =IF(G16="RSL","55","0") -> 0 | K16: =IF(G16="GVS","37.5",IF(G16="GVM","41.5",IF(G16="GVL","50",IF(G16="PCS","45.8",IF(G16="PCM","50",IF(G16="PCL","58.3","0")))))) -> 0 | N16: HENDRA | R16: =H32/U16 -> 0.51612903 | S16: =H32/(U16-U5) -> 0.72727273 | T16: =C32/U16 -> 45.644516 | U16: =SUM(U5:U15) -> 31 | Y16: 12 | AD16: 27 | AJ16: 12 | AO16: 27
A17: 13 | B17: 14158 | C17: DGA98Z | D17: 0413996557 | E17: F | F17: 1420 | G17: GV | J17: =IF(G17="RSL","55","0") -> 0 | K17: 0 | M17: 300 | N17: HENDRA | O17: XD-50-182-187 (D) | R17: Cars/T Hr ① | S17: Cars/T Hr ② | T17: Sales/T Hr | U17: Total Hours | Y17: 13 | AD17: 28 | AJ17: 13 | AO17: 28
A18: 14 | B18: 14159 | C18: DDC10C | D18: 0438775937 | E18: F | F18: 1445 | G18: X | I18: 95 | J18: =IF(G18="RSL","55","0") -> 0 | K18: =IF(G18="GVS","37.5",IF(G18="GVM","41.5",IF(G18="GVL","50",IF(G18="PCS","45.8",IF(G18="PCM","50",IF(G18="PCL","58.3","0")))))) -> 0 | N18: HENDRA | R18: ITEM | S18: QTY | T18: AMT | U18: RMKS | Y18: 14 | AD18: 29 | AJ18: 14 | AO18: 29
A19: 15 | B19: 14160 | C19: 522 | D19: 0430206670 | E19: M | F19: 1450 | G19: H | H19: 150 | J19: =IF(G19="RSL","55","0") -> 0 | K19: =IF(G19="GVS","37.5",IF(G19="GVM","41.5",IF(G19="GVL","50",IF(G19="PCS","45.8",IF(G19="PCM","50",IF(G19="PCL","58.3","0")))))) -> 0 | N19: HENDRA | R19: GV | S19: =COUNT(L5:M29,L37:M61,L69:M93) -> 1 | T19: =SUM(L5:M29,L37:M61,L69:M93) -> 300 | Y19: 15 | AD19: 30 | AJ19: 15 | AO19: 30
A20: 16 | B20: 14161 | C20: EHI64P | D20: 0431431944 | E20: F | F20: 1510 | G20: X | H20: 95 | J20: =IF(G20="RSL","55","0") -> 0 | K20: =IF(G20="GVS","37.5",IF(G20="GVM","41.5",IF(G20="GVL","50",IF(G20="PCS","45.8",IF(G20="PCM","50",IF(G20="PCL","58.3","0")))))) -> 0 | N20: HENDRA | AD20: 31 | AO20: 31
A21: 17 | J21: =IF(G21="RSL","55","0") -> 0 | K21: =IF(G21="GVS","37.5",IF(G21="GVM","41.5",IF(G21="GVL","50",IF(G21="PCS","45.8",IF(G21="PCM","50",IF(G21="PCL","58.3","0")))))) -> 0
A22: 18 | J22: =IF(G22="RSL","55","0") -> 0 | K22: =IF(G22="GVS","37.5",IF(G22="GVM","41.5",IF(G22="GVL","50",IF(G22="PCS","45.8",IF(G22="PCM","50",IF(G22="PCL","58.3","0")))))) -> 0 | AD22: Total | AE22: =SUM(Z5:Z19,AE5:AE20) -> 0 | AF22: =SUM(AA5:AA19,AF5:AF20,) -> 0 | AG22: =SUM(AB5:AB19,AG5:AG20) -> 0 | AO22: Total | AP22: =SUM(AK5:AK19,AP5:AP20) -> 0 | AQ22: =SUM(AL5:AL19,AQ5:AQ20,) -> 0 | AR22: =SUM(AM5:AM19,AR5:AR20) -> 0
A23: 19 | J23: =IF(G23="RSL","55","0") -> 0 | K23: =IF(G23="GVS","37.5",IF(G23="GVM","41.5",IF(G23="GVL","50",IF(G23="PCS","45.8",IF(G23="PCM","50",IF(G23="PCL","58.3","0")))))) -> 0
A24: 20 | J24: =IF(G24="RSL","55","0") -> 0 | K24: =IF(G24="GVS","37.5",IF(G24="GVM","41.5",IF(G24="GVL","50",IF(G24="PCS","45.8",IF(G24="PCM","50",IF(G24="PCL","58.3","0")))))) -> 0 | R24: SMALL | S24: MEDIUM | T24: LARGE | U24: TOTAL | AD24: B2/GA TOTAL | AE24: B2 machine | AF24: GA machine | AG24: BLH machine | AH24: Wongo machine | AI24: Sub total
A25: 21 | J25: =IF(G25="RSL","55","0") -> 0 | K25: =IF(G25="GVS","37.5",IF(G25="GVM","41.5",IF(G25="GVL","50",IF(G25="PCS","45.8",IF(G25="PCM","50",IF(G25="PCL","58.3","0")))))) -> 0 | R25: =COUNTIF(G5:G29,"GV1")+COUNTIF(G37:G61,"GV1")+COUNTIF(G69:G93,"GV1") -> 0 | S25: =COUNTIF(G5:G29,"GV2")+COUNTIF(G37:G61,"GV2")+COUNTIF(G69:G93,"GV2") -> 0 | T25: =COUNTIF(G5:G29,"GV3")+COUNTIF(G37:G61,"GV3")+COUNTIF(G69:G93,"GV3") -> 0 | U25: =((C32+(R26+S26+T26)*0.5)) -> 1414.98 | AD25: =SUM(AE25:AF25) -> 0 | AE25: =SUM(AE22) -> 0 | AF25: =SUM(AP22) -> 0 | AG25: =SUM(AF22+AQ22) -> 0 | AH25: =AG22+AR22 -> 0 | AI25: =SUM(AE25:AH25) -> 0
A26: 22 | J26: =IF(G26="RSL","55","0") -> 0 | K26: =IF(G26="GVS","37.5",IF(G26="GVM","41.5",IF(G26="GVL","50",IF(G26="PCS","45.8",IF(G26="PCM","50",IF(G26="PCL","58.3","0")))))) -> 0 | R26: =R25*37.5 -> 0 | S26: =S25*41.5 -> 0 | T26: =T25*50 -> 0 | X26: Branch cards
A27: 23 | J27: =IF(G27="RSL","55","0") -> 0 | K27: =IF(G27="GVS","37.5",IF(G27="GVM","41.5",IF(G27="GVL","50",IF(G27="PCS","45.8",IF(G27="PCM","50",IF(G27="PCL","58.3","0")))))) -> 0 | R27: Expense | X27: 1 | Z27: -2745
A28: 24 | J28: =IF(G28="RSL","55","0") -> 0 | K28: =IF(G28="GVS","37.5",IF(G28="GVM","41.5",IF(G28="GVL","50",IF(G28="PCS","45.8",IF(G28="PCM","50",IF(G28="PCL","58.3","0")))))) -> 0 | X28: 2
A29: 25 | J29: =IF(G29="RSL","55","0") -> 0 | K29: =IF(G29="GVS","37.5",IF(G29="GVM","41.5",IF(G29="GVL","50",IF(G29="PCS","45.8",IF(G29="PCM","50",IF(G29="PCL","58.3","0")))))) -> 0 | X29: 3
A30: Page total | H30: =SUM(H5:H29) -> 320 | I30: =SUM(I5:I29) -> 670 | J30: =J5+J6+J7+J8+J9+J10+J11+J12+J13+J14+J15+J16+J18+J19+J17+J20+J22+J23+J21+J24+J25+J26+J27+J28+J29 -> 0 | K30: =K5+K6+K7+K8+K9+K10+K11+K12+K13+K14+K15+K16+K18+K19+K17+K20+K22+K23+K21+K24+K25+K26+K27+K28+K29 -> 424.98 | L30: =SUM(L5:L29) -> 0 | M30: =SUM(M5:M29) -> 300 | N30: CASH | O30: CARD | P30: GV | Q30: RSL | X30: 4
A31: Daily Total | H31: =H30+H62+H94 -> 320 | I31: =I30+I62+I94 -> 670 | J31: =J30+J62+J94 -> 0 | K31: =K30+K62+K94 -> 424.98 | L31: =L30+L62+L94 -> 0 | M31: =M30+M62+M94 -> 300 | N31: =COUNT(H5:H29,H37:H61,H69:H93) -> 3 | O31: =COUNT(I5:I29,I37:I61,I69:I93) -> 7 | P31: =COUNTIF(G5:G29,"G*")+COUNTIF(G37:G61,"G*")+COUNTIF(G69:G93,"G*")+COUNTIF(G5:G29,"P*")+COUNTIF(G37:G61,"P*")+COUNTIF(G69:G93,"P*") -> 6 | Q31: =COUNTIF(G5:G29,"RSL")+COUNTIF(G37:G61,"RSL")+COUNTIF(G69:G93,"RSL") -> 0 | R31: CASH CLOSING | S31: =H31+L31-U28-U29-U30 -> 320 | T31: =H31+I31+L31+M31 -> 1290 | X31: Subtotal | Z31: =SUM(Z27:Z30) -> -2745
A32: TOTAL SALES | C32: =H31+I31+J31+K31 -> 1414.98 | F32: No of Cars | H32: =COUNT(B5:B29,B37:B61,B69:B93) -> 16 | I32: Average | K32: =C32/H32 -> 88.43625 | N32: =H31/C32 -> 0.22615161 | O32: =I31/C32 -> 0.47350493 | P32: =K31/C32 -> 0.30034347 | Q32: =J31/C32 -> 0 | R32: CARD CLOSING | S32: =I31+M31 -> 970 | X32: B2 card | Z32: =I31 -> 670
A33: Daily Report | X33: Settlement | Z33: =SUM(Z31:Z32) -> -2075
A34: =A2 -> 45110 | H34: WEATHER | J34: =J2 -> SUNNY | L34: REPORT by | O34: =O2 -> HENDRA | R34: TOTAL STAFF | T34: =T2 -> 4
A36: No | B36: Docket No | C36: Reg No | D36: Mobile | E36: Gender | F36: TIME | G36: Service | H36: CASH | I36: CARD | J36: RSL | K36: GV | L36: GV CASH | M36: GV CARD | N36: O/Taker | O36: Comment | R36: NAME | S36: Time In | T36: Time out | U36: Total Hours
A37: =A29+1 -> 26 | J37: =IF(G37="RSL","55","0") -> 0 | K37: =IF(G37="GVS","37.5",IF(G37="GVM","41.5",IF(G37="GVL","50",IF(G37="PCS","45.8",IF(G37="PCM","50",IF(G37="PCL","58.3","0")))))) -> 0
A38: =A37+1 -> 27 | J38: =IF(G38="RSL","55","0") -> 0 | K38: =IF(G38="GVS","37.5",IF(G38="GVM","41.5",IF(G38="GVL","50",IF(G38="PCS","45.8",IF(G38="PCM","50",IF(G38="PCL","58.3","0")))))) -> 0
A39: =A38+1 -> 28 | J39: =IF(G39="RSL","55","0") -> 0 | K39: =IF(G39="GVS","37.5",IF(G39="GVM","41.5",IF(G39="GVL","50",IF(G39="PCS","45.8",IF(G39="PCM","50",IF(G39="PCL","58.3","0")))))) -> 0
A40: =A39+1 -> 29 | J40: =IF(G40="RSL","55","0") -> 0 | K40: =IF(G40="GVS","37.5",IF(G40="GVM","41.5",IF(G40="GVL","50",IF(G40="PCS","45.8",IF(G40="PCM","50",IF(G40="PCL","58.3","0")))))) -> 0
A41: =A40+1 -> 30 | J41: =IF(G41="RSL","55","0") -> 0 | K41: =IF(G41="GVS","37.5",IF(G41="GVM","41.5",IF(G41="GVL","50",IF(G41="PCS","45.8",IF(G41="PCM","50",IF(G41="PCL","58.3","0")))))) -> 0
A42: =A41+1 -> 31 | J42: =IF(G42="RSL","55","0") -> 0 | K42: =IF(G42="GVS","37.5",IF(G42="GVM","41.5",IF(G42="GVL","50",IF(G42="PCS","45.8",IF(G42="PCM","50",IF(G42="PCL","58.3","0")))))) -> 0
...

Sheet WED
A1: B2 Daily Report
A2: 44993 | H2: WEATHER | J2: SUNNY | L2: REPORT BY | O2: HENDRA | R2: TOTAL STAFF | T2: 5 | X2: Merchant machine usage at B2 | AA2: Settle amount | AI2: Merchant machine usage at GA | AL2: Settle amount
A4: No | B4: Docket No | C4: Reg No | D4: Mobile | E4: Gender | F4: TIME | G4: Service | H4: CASH | I4: CARD | J4: RSL | K4: GV | L4: GV CASH | M4: GV CARD | N4: O/Taker | O4: Comment | R4: NAME | S4: Time In | T4: Time out | U4: Total Hours | Z4: B2 machine | AA4: BLH machine | AB4: Wongo | AE4: B2 machine | AF4: BLH machine | AG4: Wongo | AK4: GA machine | AL4: BLH machine | AM4: Wongo | AP4: GA machine | AQ4: BLH machine | AR4: Wongo
A5: 1 | B5: 14162 | C5: EPW65B | D5: 0432565750 | E5: M | F5: 800 | G5: PCS | J5: =IF(G5="RSL","55","0") -> 0 | K5: 125 | N5: HENDRA | O5: 22070(4-5/6) | R5: HENDRA | S5: 0.33333333 | T5: 0.70833333 | U5: =(T5-S5)*24 -> 9 | X5: NOV | Y5: 1 | AD5: 16 | AI5: NOV | AJ5: 1 | AO5: 16
A6: 2 | B6: 14163 | C6: EGQ53M | D6: 0433818333 | E6: F | F6: 915 | G6: X | H6: 70 | J6: =IF(G6="RSL","55","0") -> 0 | K6: =IF(G6="GVS","37.5",IF(G6="GVM","41.5",IF(G6="GVL","50",IF(G6="PCS","45.8",IF(G6="PCM","50",IF(G6="PCL","58.3","0")))))) -> 0 | N6: HENDRA | O6: $5 OFF | R6: ATET | S6: 0.33333333 | T6: 0.70833333 | U6: =(T6-S6)*24 -> 9 | W6: M | Y6: 2 | AD6: 17 | AJ6: 2 | AO6: 17
A7: 3 | B7: 14164 | C7: BXA63C | D7: 0450656856 | E7: F | F7: 930 | G7: GV | J7: =IF(G7="RSL","55","0") -> 0 | K7: 0 | M7: 350 | N7: ATET | O7: XD50-188-191/337-340 | R7: ARIANTO | S7: 0.35416667 | T7: 0.625 | U7: =(T7-S7)*24 -> 6.5 | W7: F | Y7: 3 | AD7: 18 | AJ7: 3 | AO7: 18
A8: 4 | B8: 14165 | C8: KING9 | D8: 0488891999 | E8: M | F8: 930 | G8: PCL | J8: =IF(G8="RSL","55","0") -> 0 | K8: 79.16 | M8: 475 | N8: HENDRA | O8: 22101(6/6) X, 23226(NEW) X | R8: VINNY | S8: 0.42708333 | T8: 0.70833333 | U8: =(T8-S8)*24 -> 6.75 | Y8: 4 | AD8: 19 | AJ8: 4 | AO8: 19
A9: 5 | B9: 14166 | C9: CAF83J | D9: 0410688507 | E9: M | F9: 930 | G9: X | I9: 95 | J9: =IF(G9="RSL","55","0") -> 0 | K9: =IF(G9="GVS","37.5",IF(G9="GVM","41.5",IF(G9="GVL","50",IF(G9="PCS","45.8",IF(G9="PCM","50",IF(G9="PCL","58.3","0")))))) -> 0 | N9: ATET | R9: KUROSH | S9: 0.41666667 | T9: 0.70833333 | U9: =(T9-S9)*24 -> 7 | X9: EXCL RSL | Y9: 5 | AD9: 20 | AJ9: 5 | AO9: 20
A10: 6 | B10: 14167 | C10: CRR97J | D10: 0410857808 | E10: M | F10: 930 | G10: GV | J10: =IF(G10="RSL","55","0") -> 0 | K10: 0 | M10: 350 | N10: ATET | O10: XD50-341-347 (TAX) | U10: =(T10-S10)*24 -> 0 | Y10: 6 | AD10: 21 | AJ10: 6 | AO10: 21
A11: 7 | B11: 14168 | C11: LAW885 | D11: 0423237896 | E11: M | F11: 1030 | G11: S/D | I11: 250 | J11: =IF(G11="RSL","55","0") -> 0 | K11: =IF(G11="GVS","37.5",IF(G11="GVM","41.5",IF(G11="GVL","50",IF(G11="PCS","45.8",IF(G11="PCM","50",IF(G11="PCL","58.3","0")))))) -> 0 | N11: ATET | U11: =(T11-S11)*24 -> 0 | Y11: 7 | AD11: 22 | AJ11: 7 | AO11: 22
A12: 8 | B12: 14169 | C12: EWU34D | D12: 0478966933 | E12: F | F12: 1030 | G12: F/D | H12: 295 | J12: =IF(G12="RSL","55","0") -> 0 | K12: =IF(G12="GVS","37.5",IF(G12="GVM","41.5",IF(G12="GVL","50",IF(G12="PCS","45.8",IF(G12="PCM","50",IF(G12="PCL","58.3","0")))))) -> 0 | N12: ATET | O12: TAX | U12: =(T12-S12)*24 -> 0 | Y12: 8 | AD12: 23 | AJ12: 8 | AO12: 23
A13: 9 | B13: 14170 | C13: CJL828 | D13: 0400127856 | E13: F | F13: 1045 | G13: PCL | J13: =IF(G13="RSL","55","0") -> 0 | K13: 79.16 | N13: ATET | O13: 22103(3/6) | U13: =(T13-S13)*24 -> 0 | Y13: 9 | AD13: 24 | AJ13: 9 | AO13: 24
A14: 10 | B14: 14171 | C14: DCB24N | D14: 0416026587 | E14: F | F14: 1045 | G14: W/O (GV) | H14: 15 | J14: =IF(G14="RSL","55","0") -> 0 | K14: 50 | N14: ATET | O14: XD50-137 | U14: =(T14-S14)*24 -> 0 | Y14: 10 | AD14: 25 | AJ14: 10 | AO14: 25
A15: 11 | B15: 14172 | C15: NCA15F | D15: 0411139378 | E15: M | F15: 1100 | G15: PCL | J15: =IF(G15="RSL","55","0") -> 0 | K15: 79.16 | N15: ATET | O15: 22126(1/6) | U15: =(T15-S15)*24 -> 0 | Y15: 11 | AD15: 26 | AJ15: 11 | AO15: 26
A16: 12 | B16: 14173 | C16: SBO212 | D16: 0401704628 | E16: F | F16: 1130 | G16: D | I16: 75 | J16: =IF(G16="RSL","55","0") -> 0 | K16: =IF(G16="GVS","37.5",IF(G16="GVM","41.5",IF(G16="GVL","50",IF(G16="PCS","45.8",IF(G16="PCM","50",IF(G16="PCL","58.3","0")))))) -> 0 | N16: ATET | R16: =H32/U16 -> 0.52287582 | S16: =H32/(U16-U5) -> 0.68376068 | T16: =C32/U16 -> 47.058301 | U16: =SUM(U5:U15) -> 38.25 | Y16: 12 | AD16: 27 | AJ16: 12 | AO16: 27
A17: 13 | B17: 14174 | C17: PAA333 | D17: 0414337333 | E17: F | F17: 1130 | G17: X | I17: 95 | J17: =IF(G17="RSL","55","0") -> 0 | K17: =IF(G17="GVS","37.5",IF(G17="GVM","41.5",IF(G17="GVL","50",IF(G17="PCS","45.8",IF(G17="PCM","50",IF(G17="PCL","58.3","0")))))) -> 0 | N17: ATET | R17: Cars/T Hr ① | S17: Cars/T Hr ② | T17: Sales/T Hr | U17: Total Hours | Y17: 13 | AD17: 28 | AJ17: 13 | AO17: 28
A18: 14 | B18: 14175 | C18: EKW89F | D18: 0434622861 | E18: F | F18: 1200 | G18: GV | J18: =IF(G18="RSL","55","0") -> 0 | K18: 0 | M18: 350 | N18: ATET | O18: XD50-348-354 | R18: ITEM | S18: QTY | T18: AMT | U18: RMKS | Y18: 14 | AD18: 29 | AJ18: 14 | AO18: 29
A19: 15 | B19: 14176 | C19: ERT75C | D19: 0411642270 | E19: F | F19: 1200 | G19: X | I19: 75 | J19: =IF(G19="RSL","55","0") -> 0 | K19: =IF(G19="GVS","37.5",IF(G19="GVM","41.5",IF(G19="GVL","50",IF(G19="PCS","45.8",IF(G19="PCM","50",IF(G19="PCL","58.3","0")))))) -> 0 | N19: ATET | R19: GV | S19: =COUNT(L5:M29,L37:M61,L69:M93) -> 4 | T19: =SUM(L5:M29,L37:M61,L69:M93) -> 1525 | Y19: 15 | AD19: 30 | AJ19: 15 | AO19: 30
A20: 16 | B20: 14177 | C20: NCZ87M | D20: 0402505402 | E20: F | F20: 1230 | G20: X | I20: 75 | J20: =IF(G20="RSL","55","0") -> 0 | K20: =IF(G20="GVS","37.5",IF(G20="GVM","41.5",IF(G20="GVL","50",IF(G20="PCS","45.8",IF(G20="PCM","50",IF(G20="PCL","58.3","0")))))) -> 0 | N20: ATET | AD20: 31 | AO20: 31
A21: 17 | B21: 14178 | C21: EKC89S | D21: 0438354090 | E21: F | F21: 1315 | G21: D | I21: 55 | J21: =IF(G21="RSL","55","0") -> 0 | K21: =IF(G21="GVS","37.5",IF(G21="GVM","41.5",IF(G21="GVL","50",IF(G21="PCS","45.8",IF(G21="PCM","50",IF(G21="PCL","58.3","0")))))) -> 0 | N21: ATET
A22: 18 | B22: 14179 | C22: ANZ53F | D22: 0419482011 | E22: F | F22: 1330 | G22: X | H22: 95 | J22: =IF(G22="RSL","55","0") -> 0 | K22: =IF(G22="GVS","37.5",IF(G22="GVM","41.5",IF(G22="GVL","50",IF(G22="PCS","45.8",IF(G22="PCM","50",IF(G22="PCL","58.3","0")))))) -> 0 | N22: ATET | AD22: Total | AE22: =SUM(Z5:Z19,AE5:AE20) -> 0 | AF22: =SUM(AA5:AA19,AF5:AF20,) -> 0 | AG22: =SUM(AB5:AB19,AG5:AG20) -> 0 | AO22: Total | AP22: =SUM(AK5:AK19,AP5:AP20) -> 0 | AQ22: =SUM(AL5:AL19,AQ5:AQ20,) -> 0 | AR22: =SUM(AM5:AM19,AR5:AR20) -> 0
A23: 19 | B23: 14180 | C23: EPO91D | D23: 0419460470 | E23: F | F23: 1400 | G23: PCS | J23: =IF(G23="RSL","55","0") -> 0 | K23: 62.5 | N23: ATET | O23: 22051(6/6)
A24: 20 | B24: 14181 | C24: EBQ17K | D24: 0422661161 | E24: F | F24: 1545 | G24: H | I24: 130 | J24: =IF(G24="RSL","55","0") -> 0 | K24: =IF(G24="GVS","37.5",IF(G24="GVM","41.5",IF(G24="GVL","50",IF(G24="PCS","45.8",IF(G24="PCM","50",IF(G24="PCL","58.3","0")))))) -> 0 | N24: ATET | R24: SMALL | S24: MEDIUM | T24: LARGE | U24: TOTAL | AD24: B2/GA TOTAL | AE24: B2 machine | AF24: GA machine | AG24: BLH machine | AH24: Wongo machine | AI24: Sub total
A25: 21 | J25: =IF(G25="RSL","55","0") -> 0 | K25: =IF(G25="GVS","37.5",IF(G25="GVM","41.5",IF(G25="GVL","50",IF(G25="PCS","45.8",IF(G25="PCM","50",IF(G25="PCL","58.3","0")))))) -> 0 | R25: =COUNTIF(G5:G29,"GV1")+COUNTIF(G37:G61,"GV1")+COUNTIF(G69:G93,"GV1") -> 0 | S25: =COUNTIF(G5:G29,"GV2")+COUNTIF(G37:G61,"GV2")+COUNTIF(G69:G93,"GV2") -> 0 | T25: =COUNTIF(G5:G29,"GV3")+COUNTIF(G37:G61,"GV3")+COUNTIF(G69:G93,"GV3") -> 0 | U25: =((C32+(R26+S26+T26)*0.5)) -> 1799.98 | AD25: =SUM(AE25:AF25) -> 0 | AE25: =SUM(AE22) -> 0 | AF25: =SUM(AP22) -> 0 | AG25: =SUM(AF22+AQ22) -> 0 | AH25: =AG22+AR22 -> 0 | AI25: =SUM(AE25:AH25) -> 0
A26: 22 | J26: =IF(G26="RSL","55","0") -> 0 | K26: =IF(G26="GVS","37.5",IF(G26="GVM","41.5",IF(G26="GVL","50",IF(G26="PCS","45.8",IF(G26="PCM","50",IF(G26="PCL","58.3","0")))))) -> 0 | R26: =R25*37.5 -> 0 | S26: =S25*41.5 -> 0 | T26: =T25*50 -> 0 | X26: Branch cards
A27: 23 | J27: =IF(G27="RSL","55","0") -> 0 | K27: =IF(G27="GVS","37.5",IF(G27="GVM","41.5",IF(G27="GVL","50",IF(G27="PCS","45.8",IF(G27="PCM","50",IF(G27="PCL","58.3","0")))))) -> 0 | R27: Expense | X27: 1 | Z27: -2745
A28: 24 | J28: =IF(G28="RSL","55","0") -> 0 | K28: =IF(G28="GVS","37.5",IF(G28="GVM","41.5",IF(G28="GVL","50",IF(G28="PCS","45.8",IF(G28="PCM","50",IF(G28="PCL","58.3","0")))))) -> 0 | R28: 14164 "NO WASH" | X28: 2
A29: 25 | J29: =IF(G29="RSL","55","0") -> 0 | K29: =IF(G29="GVS","37.5",IF(G29="GVM","41.5",IF(G29="GVL","50",IF(G29="PCS","45.8",IF(G29="PCM","50",IF(G29="PCL","58.3","0")))))) -> 0 | X29: 3
A30: Page total | H30: =SUM(H5:H29) -> 475 | I30: =SUM(I5:I29) -> 850 | J30: =J5+J6+J7+J8+J9+J10+J11+J12+J13+J14+J15+J16+J18+J19+J17+J20+J22+J23+J21+J24+J25+J26+J27+J28+J29 -> 0 | K30: =K5+K6+K7+K8+K9+K10+K11+K12+K13+K14+K15+K16+K18+K19+K17+K20+K22+K23+K21+K24+K25+K26+K27+K28+K29 -> 474.98 | L30: =SUM(L5:L29) -> 0 | M30: =SUM(M5:M29) -> 1525 | N30: CASH | O30: CARD | P30: GV | Q30: RSL | X30: 4
A31: Daily Total | H31: =H30+H62+H94 -> 475 | I31: =I30+I62+I94 -> 850 | J31: =J30+J62+J94 -> 0 | K31: =K30+K62+K94 -> 474.98 | L31: =L30+L62+L94 -> 0 | M31: =M30+M62+M94 -> 1525 | N31: =COUNT(H5:H29,H37:H61,H69:H93) -> 4 | O31: =COUNT(I5:I29,I37:I61,I69:I93) -> 8 | P31: =COUNTIF(G5:G29,"G*")+COUNTIF(G37:G61,"G*")+COUNTIF(G69:G93,"G*")+COUNTIF(G5:G29,"P*")+COUNTIF(G37:G61,"P*")+COUNTIF(G69:G93,"P*") -> 8 | Q31: =COUNTIF(G5:G29,"RSL")+COUNTIF(G37:G61,"RSL")+COUNTIF(G69:G93,"RSL") -> 0 | R31: CASH CLOSING | S31: =H31+L31-U28-U29-U30 -> 475 | T31: =H31+I31+L31+M31 -> 2850 | X31: Subtotal | Z31: =SUM(Z27:Z30) -> -2745
A32: TOTAL SALES | C32: =H31+I31+J31+K31 -> 1799.98 | F32: No of Cars | H32: =COUNT(B5:B29,B37:B61,B69:B93) -> 20 | I32: Average | K32: =C32/H32 -> 89.999 | N32: =H31/C32 -> 0.26389182 | O32: =I31/C32 -> 0.47222747 | P32: =K31/C32 -> 0.26388071 | Q32: =J31/C32 -> 0 | R32: CARD CLOSING | S32: =I31+M31 -> 2375 | X32: B2 card | Z32: =I31 -> 850
A33: Daily Report | X33: Settlement | Z33: =SUM(Z31:Z32) -> -1895
A34: =A2 -> 44993 | H34: WEATHER | J34: =J2 -> SUNNY | L34: REPORT by | O34: =O2 -> HENDRA | R34: TOTAL STAFF | T34: =T2 -> 5
A36: No | B36: Docket No | C36: Reg No | D36: Mobile | E36: Gender | F36: TIME | G36: Service | H36: CASH | I36: CARD | J36: RSL | K36: GV | L36: GV CASH | M36: GV CARD | N36: O/Taker | O36: Comment | R36: NAME | S36: Time In | T36: Time out | U36: Total Hours
A37: =A29+1 -> 26 | J37: =IF(G37="RSL","55","0") -> 0 | K37: =IF(G37="GVS","37.5",IF(G37="GVM","41.5",IF(G37="GVL","50",IF(G37="PCS","45.8",IF(G37="PCM","50",IF(G37="PCL","58.3","0")))))) -> 0
A38: =A37+1 -> 27 | J38: =IF(G38="RSL","55","0") -> 0 | K38: =IF(G38="GVS","37.5",IF(G38="GVM","41.5",IF(G38="GVL","50",IF(G38="PCS","45.8",IF(G38="PCM","50",IF(G38="PCL","58.3","0")))))) -> 0
A39: =A38+1 -> 28 | J39: =IF(G39="RSL","55","0") -> 0 | K39: =IF(G39="GVS","37.5",IF(G39="GVM","41.5",IF(G39="GVL","50",IF(G39="PCS","45.8",IF(G39="PCM","50",IF(G39="PCL","58.3","0")))))) -> 0
A40: =A39+1 -> 29 | J40: =IF(G40="RSL","55","0") -> 0 | K40: =IF(G40="GVS","37.5",IF(G40="GVM","41.5",IF(G40="GVL","50",IF(G40="PCS","45.8",IF(G40="PCM","50",IF(G40="PCL","58.3","0")))))) -> 0
A41: =A40+1 -> 30 | J41: =IF(G41="RSL","55","0") -> 0 | K41: =IF(G41="GVS","37.5",IF(G41="GVM","41.5",IF(G41="GVL","50",IF(G41="PCS","45.8",IF(G41="PCM","50",IF(G41="PCL","58.3","0")))))) -> 0
A42: =A41+1 -> 31 | J42: =IF(G42="RSL","55","0") -> 0 | K42: =IF(G42="GVS","37.5",IF(G42="GVM","41.5",IF(G42="GVL","50",IF(G42="PCS","45.8",IF(G42="PCM","50",IF(G42="PCL","58.3","0")))))) -> 0
...

Sheet THU
A1: B2 Daily Report
A2: 44994 | H2: WEATHER | J2: SUNNY | L2: REPORT BY | O2: HENDRA | R2: TOTAL STAFF | T2: 6 | X2: Merchant machine usage at B2 | AA2: Settle amount | AI2: Merchant machine usage at GA | AL2: Settle amount
A4: No | B4: Docket No | C4: Reg No | D4: Mobile | E4: Gender | F4: TIME | G4: Service | H4: CASH | I4: CARD | J4: RSL | K4: GV | L4: GV CASH | M4: GV CARD | N4: O/Taker | O4: Comment | R4: NAME | S4: Time In | T4: Time out | U4: Total Hours | Z4: B2 machine | AA4: BLH machine | AB4: Wongo | AE4: B2 machine | AF4: BLH machine | AG4: Wongo | AK4: GA machine | AL4: BLH machine | AM4: Wongo | AP4: GA machine | AQ4: BLH machine | AR4: Wongo
A5: 1 | B5: 14182 | C5: BE11EW | D5: 0410626003 | E5: F | F5: 900 | G5: PCS | J5: =IF(G5="RSL","55","0") -> 0 | K5: 62.5 | N5: HENDRA | O5: 22080(2/6) | R5: HENDRA | S5: 0.33333333 | T5: 0.77083333 | U5: =(T5-S5)*24 -> 10.5 | X5: NOV | Y5: 1 | AD5: 16 | AI5: NOV | AJ5: 1 | AO5: 16
A6: 2 | B6: 14183 | C6: GBI | D6: 0415888891 | E6: M | F6: 910 | G6: H | H6: 150 | J6: =IF(G6="RSL","55","0") -> 0 | K6: =IF(G6="GVS","37.5",IF(G6="GVM","41.5",IF(G6="GVL","50",IF(G6="PCS","45.8",IF(G6="PCM","50",IF(G6="PCL","58.3","0")))))) -> 0 | N6: HENDRA | O6: GEORGE CAR | R6: ATET | S6: 0.375 | T6: 0.70833333 | U6: =(T6-S6)*24 -> 8 | W6: M | Y6: 2 | AD6: 17 | AJ6: 2 | AO6: 17
A7: 3 | B7: 14184 | C7: CRQ96X | D7: 0408062082 | E7: F | F7: 920 | G7: D | H7: 75 | J7: =IF(G7="RSL","55","0") -> 0 | K7: =IF(G7="GVS","37.5",IF(G7="GVM","41.5",IF(G7="GVL","50",IF(G7="PCS","45.8",IF(G7="PCM","50",IF(G7="PCL","58.3","0")))))) -> 0 | N7: ATET | R7: ARIANTO | S7: 0.35416667 | T7: 0.66666667 | U7: =(T7-S7)*24 -> 7.5 | W7: F | Y7: 3 | AD7: 18 | AJ7: 3 | AO7: 18
A8: 4 | B8: 14185 | C8: 88 LIAM | D8: 0401795858 | E8: M | F8: 1000 | G8: GV | J8: =IF(G8="RSL","55","0") -> 0 | K8: 0 | L8: 350 | N8: ATET | O8: XD50-355 -361 | R8: MODI | S8: 0.41666667 | T8: 0.64583333 | U8: =(T8-S8)*24 -> 5.5 | Y8: 4 | AD8: 19 | AJ8: 4 | AO8: 19
A9: 5 | B9: 14186 | C9: EOK70F | D9: 0419236787 | E9: F | F9: 1015 | G9: X | I9: 95 | J9: =IF(G9="RSL","55","0") -> 0 | K9: =IF(G9="GVS","37.5",IF(G9="GVM","41.5",IF(G9="GVL","50",IF(G9="PCS","45.8",IF(G9="PCM","50",IF(G9="PCL","58.3","0")))))) -> 0 | N9: ATET | R9: TONY ENKHBAT | S9: 0.54166667 | T9: 0.70833333 | U9: =(T9-S9)*24 -> 4 | X9: EXCL RSL | Y9: 5 | AD9: 20 | AJ9: 5 | AO9: 20
A10: 6 | B10: 14187 | C10: EMJ32S | D10: 0478844282 | E10: F | F10: 1030 | G10: D | I10: 75 | J10: =IF(G10="RSL","55","0") -> 0 | K10: =IF(G10="GVS","37.5",IF(G10="GVM","41.5",IF(G10="GVL","50",IF(G10="PCS","45.8",IF(G10="PCM","50",IF(G10="PCL","58.3","0")))))) -> 0 | N10: ATET | R10: ANDREW OCTEC | S10: 0.5 | T10: 0.70833333 | U10: =(T10-S10)*24 -> 5 | Y10: 6 | AD10: 21 | AJ10: 6 | AO10: 21
A11: 7 | B11: 14188 | C11: 13013 | D11: 0433216826 | E11: F | F11: 1100 | G11: X | H11: 75 | J11: =IF(G11="RSL","55","0") -> 0 | K11: =IF(G11="GVS","37.5",IF(G11="GVM","41.5",IF(G11="GVL","50",IF(G11="PCS","45.8",IF(G11="PCM","50",IF(G11="PCL","58.3","0")))))) -> 0 | N11: ATET | U11: =(T11-S11)*24 -> 0 | Y11: 7 | AD11: 22 | AJ11: 7 | AO11: 22
A12: 8 | B12: 14189 | C12: NCA82M | D12: 0439988228 | E12: F | F12: 1115 | G12: PCL | J12: =IF(G12="RSL","55","0") -> 0 | K12: 108.33 | L12: 650 | N12: ATET | O12: 22079(6/6),23227(NEW) | U12: =(T12-S12)*24 -> 0 | Y12: 8 | AD12: 23 | AJ12: 8 | AO12: 23
A13: 9 | B13: 14190 | C13: TT3388 | D13: 0418679112 | E13: M | F13: 1130 | G13: PCS | J13: =IF(G13="RSL","55","0") -> 0 | K13: 62.5 | N13: ATET | O13: 22059(4/6) | U13: =(T13-S13)*24 -> 0 | Y13: 9 | AD13: 24 | AJ13: 9 | AO13: 24
A14: 10 | B14: 14191 | C14: BFY92W | D14: 0411464642 | E14: M | F14: 1130 | G14: D | I14: 75 | J14: =IF(G14="RSL","55","0") -> 0 | K14: =IF(G14="GVS","37.5",IF(G14="GVM","41.5",IF(G14="GVL","50",IF(G14="PCS","45.8",IF(G14="PCM","50",IF(G14="PCL","58.3","0")))))) -> 0 | N14: ATET | U14: =(T14-S14)*24 -> 0 | Y14: 10 | AD14: 25 | AJ14: 10 | AO14: 25
A15: 11 | B15: 14192 | C15: DZS82K | D15: 0411277388 | E15: M | F15: 1145 | G15: D | H15: 75 | J15: =IF(G15="RSL","55","0") -> 0 | K15: =IF(G15="GVS","37.5",IF(G15="GVM","41.5",IF(G15="GVL","50",IF(G15="PCS","45.8",IF(G15="PCM","50",IF(G15="PCL","58.3","0")))))) -> 0 | N15: ATET | U15: =(T15-S15)*24 -> 0 | Y15: 11 | AD15: 26 | AJ15: 11 | AO15: 26
A16: 12 | B16: 14193 | C16: SL6666 | D16: 0415190683 | E16: M | F16: 1230 | G16: PCL | J16: =IF(G16="RSL","55","0") -> 0 | K16: 79.16 | N16: ATET | O16: 22099(2/6) | R16: =H32/U16 -> 0.51851852 | S16: =H32/(U16-U5) -> 0.7 | T16: =C32/U16 -> 40.802222 | U16: =SUM(U5:U15) -> 40.5 | Y16: 12 | AD16: 27 | AJ16: 12 | AO16: 27
A17: 13 | B17: 14194 | C17: EPE21C | D17: 0438354090 | E17: F | F17: 1200 | G17: GV | J17: =IF(G17="RSL","55","0") -> 0 | K17: 0 | M17: 300 | N17: ATET | O17: XD50-362-367 | R17: Cars/T Hr ① | S17: Cars/T Hr ② | T17: Sales/T Hr | U17: Total Hours | Y17: 13 | AD17: 28 | AJ17: 13 | AO17: 28
A18: 14 | B18: 14195 | C18: ECV02N | D18: 0439645062 | E18: M | F18: 1300 | G18: S/D | I18: 250 | J18: =IF(G18="RSL","55","0") -> 0 | K18: =IF(G18="GVS","37.5",IF(G18="GVM","41.5",IF(G18="GVL","50",IF(G18="PCS","45.8",IF(G18="PCM","50",IF(G18="PCL","58.3","0")))))) -> 0 | N18: ATET | R18: ITEM | S18: QTY | T18: AMT | U18: RMKS | Y18: 14 | AD18: 29 | AJ18: 14 | AO18: 29
A19: 15 | B19: 14196 | C19: DTN05N | D19: 0404889042 | E19: F | F19: 1300 | G19: X | I19: 75 | J19: =IF(G19="RSL","55","0") -> 0 | K19: =IF(G19="GVS","37.5",IF(G19="GVM","41.5",IF(G19="GVL","50",IF(G19="PCS","45.8",IF(G19="PCM","50",IF(G19="PCL","58.3","0")))))) -> 0 | N19: ATET | R19: GV | S19: =COUNT(L5:M29,L37:M61,L69:M93) -> 5 | T19: =SUM(L5:M29,L37:M61,L69:M93) -> 1950 | Y19: 15 | AD19: 30 | AJ19: 15 | AO19: 30
A20: 16 | B20: 14197 | C20: CSQ63P | D20: 0415915465 | E20: F | F20: 1300 | G20: D | I20: 75 | J20: =IF(G20="RSL","55","0") -> 0 | K20: =IF(G20="GVS","37.5",IF(G20="GVM","41.5",IF(G20="GVL","50",IF(G20="PCS","45.8",IF(G20="PCM","50",IF(G20="PCL","58.3","0")))))) -> 0 | N20: ATET | AD20: 31 | AO20: 31
A21: 17 | B21: 14198 | C21: NRM058 | D21: 0448441099 | E21: F | F21: 1315 | G21: GV | J21: =IF(G21="RSL","55","0") -> 0 | K21: 125 | M21: 350 | N21: ATET | O21: XD50-368-374
A22: 18 | B22: 14199 | C22: BKO36F | D22: 0411757862 | E22: F | F22: 1330 | G22: D | I22: 55 | J22: =IF(G22="RSL","55","0") -> 0 | K22: =IF(G22="GVS","37.5",IF(G22="GVM","41.5",IF(G22="GVL","50",IF(G22="PCS","45.8",IF(G22="PCM","50",IF(G22="PCL","58.3","0")))))) -> 0 | N22: ATET | AD22: Total | AE22: =SUM(Z5:Z19,AE5:AE20) -> 0 | AF22: =SUM(AA5:AA19,AF5:AF20,) -> 0 | AG22: =SUM(AB5:AB19,AG5:AG20) -> 0 | AO22: Total | AP22: =SUM(AK5:AK19,AP5:AP20) -> 0 | AQ22: =SUM(AL5:AL19,AQ5:AQ20,) -> 0 | AR22: =SUM(AM5:AM19,AR5:AR20) -> 0
A23: 19 | B23: 14200 | C23: CDP596 | D23: 0408228252 | E23: F | F23: 1415 | G23: D | I23: 65 | J23: =IF(G23="RSL","55","0") -> 0 | K23: =IF(G23="GVS","37.5",IF(G23="GVM","41.5",IF(G23="GVL","50",IF(G23="PCS","45.8",IF(G23="PCM","50",IF(G23="PCL","58.3","0")))))) -> 0 | N23: ATET | O23: B2809-810 $10 OFF
A24: 20 | B24: 14201 | C24: CRV58P | D24: 0402018402 | E24: F | F24: 1415 | G24: GV | J24: =IF(G24="RSL","55","0") -> 0 | K24: 0 | M24: 300 | N24: ATET | O24: XD50-375-380 | R24: SMALL | S24: MEDIUM | T24: LARGE | U24: TOTAL | AD24: B2/GA TOTAL | AE24: B2 machine | AF24: GA machine | AG24: BLH machine | AH24: Wongo machine | AI24: Sub total
A25: 21 | B25: 14202 | C25: AY63UN | D25: 0431366591 | E25: M | F25: 1430 | G25: X | I25: 75 | J25: =IF(G25="RSL","55","0") -> 0 | K25: =IF(G25="GVS","37.5",IF(G25="GVM","41.5",IF(G25="GVL","50",IF(G25="PCS","45.8",IF(G25="PCM","50",IF(G25="PCL","58.3","0")))))) -> 0 | N25: ATET | O25: BOOKING ONLINE | R25: =COUNTIF(G5:G29,"GV1")+COUNTIF(G37:G61,"GV1")+COUNTIF(G69:G93,"GV1") -> 0 | S25: =COUNTIF(G5:G29,"GV2")+COUNTIF(G37:G61,"GV2")+COUNTIF(G69:G93,"GV2") -> 0 | T25: =COUNTIF(G5:G29,"GV3")+COUNTIF(G37:G61,"GV3")+COUNTIF(G69:G93,"GV3") -> 0 | U25: =((C32+(R26+S26+T26)*0.5)) -> 1652.49 | AD25: =SUM(AE25:AF25) -> 0 | AE25: =SUM(AE22) -> 0 | AF25: =SUM(AP22) -> 0 | AG25: =SUM(AF22+AQ22) -> 0 | AH25: =AG22+AR22 -> 0 | AI25: =SUM(AE25:AH25) -> 0
A26: 22 | J26: =IF(G26="RSL","55","0") -> 0 | K26: =IF(G26="GVS","37.5",IF(G26="GVM","41.5",IF(G26="GVL","50",IF(G26="PCS","45.8",IF(G26="PCM","50",IF(G26="PCL","58.3","0")))))) -> 0 | R26: =R25*37.5 -> 0 | S26: =S25*41.5 -> 0 | T26: =T25*50 -> 0 | X26: Branch cards
A27: 23 | J27: =IF(G27="RSL","55","0") -> 0 | K27: =IF(G27="GVS","37.5",IF(G27="GVM","41.5",IF(G27="GVL","50",IF(G27="PCS","45.8",IF(G27="PCM","50",IF(G27="PCL","58.3","0")))))) -> 0 | R27: Expense | X27: 1 | Z27: -2745
A28: 24 | J28: =IF(G28="RSL","55","0") -> 0 | K28: =IF(G28="GVS","37.5",IF(G28="GVM","41.5",IF(G28="GVL","50",IF(G28="PCS","45.8",IF(G28="PCM","50",IF(G28="PCL","58.3","0")))))) -> 0 | R28: 14198 : XD50-368 USE | X28: 2
A29: 25 | J29: =IF(G29="RSL","55","0") -> 0 | K29: =IF(G29="GVS","37.5",IF(G29="GVM","41.5",IF(G29="GVL","50",IF(G29="PCS","45.8",IF(G29="PCM","50",IF(G29="PCL","58.3","0")))))) -> 0 | X29: 3
A30: Page total | H30: =SUM(H5:H29) -> 375 | I30: =SUM(I5:I29) -> 840 | J30: =J5+J6+J7+J8+J9+J10+J11+J12+J13+J14+J15+J16+J18+J19+J17+J20+J22+J23+J21+J24+J25+J26+J27+J28+J29 -> 0 | K30: =K5+K6+K7+K8+K9+K10+K11+K12+K13+K14+K15+K16+K18+K19+K17+K20+K22+K23+K21+K24+K25+K26+K27+K28+K29 -> 437.49 | L30: =SUM(L5:L29) -> 1000 | M30: =SUM(M5:M29) -> 950 | N30: CASH | O30: CARD | P30: GV | Q30: RSL | X30: 4
A31: Daily Total | H31: =H30+H62+H94 -> 375 | I31: =I30+I62+I94 -> 840 | J31: =J30+J62+J94 -> 0 | K31: =K30+K62+K94 -> 437.49 | L31: =L30+L62+L94 -> 1000 | M31: =M30+M62+M94 -> 950 | N31: =COUNT(H5:H29,H37:H61,H69:H93) -> 4 | O31: =COUNT(I5:I29,I37:I61,I69:I93) -> 9 | P31: =COUNTIF(G5:G29,"G*")+COUNTIF(G37:G61,"G*")+COUNTIF(G69:G93,"G*")+COUNTIF(G5:G29,"P*")+COUNTIF(G37:G61,"P*")+COUNTIF(G69:G93,"P*") -> 8 | Q31: =COUNTIF(G5:G29,"RSL")+COUNTIF(G37:G61,"RSL")+COUNTIF(G69:G93,"RSL") -> 0 | R31: CASH CLOSING | S31: =H31+L31-U28-U29-U30 -> 1375 | T31: =H31+I31+L31+M31 -> 3165 | X31: Subtotal | Z31: =SUM(Z27:Z30) -> -2745
A32: TOTAL SALES | C32: =H31+I31+J31+K31 -> 1652.49 | F32: No of Cars | H32: =COUNT(B5:B29,B37:B61,B69:B93) -> 21 | I32: Average | K32: =C32/H32 -> 78.69 | N32: =H31/C32 -> 0.22693027 | O32: =I31/C32 -> 0.5083238 | P32: =K31/C32 -> 0.26474593 | Q32: =J31/C32 -> 0 | R32: CARD CLOSING | S32: =I31+M31 -> 1790 | X32: B2 card | Z32: =I31 -> 840
A33: Daily Report | X33: Settlement | Z33: =SUM(Z31:Z32) -> -1905
A34: =A2 -> 44994 | H34: WEATHER | J34: =J2 -> SUNNY | L34: REPORT by | O34: =O2 -> HENDRA | R34: TOTAL STAFF | T34: =T2 -> 6
A36: No | B36: Docket No | C36: Reg No | D36: Mobile | E36: Gender | F36: TIME | G36: Service | H36: CASH | I36: CARD | J36: RSL | K36: GV | L36: GV CASH | M36: GV CARD | N36: O/Taker | O36: Comment | R36: NAME | S36: Time In | T36: Time out | U36: Total Hours
A37: =A29+1 -> 26 | J37: =IF(G37="RSL","55","0") -> 0 | K37: =IF(G37="GVS","37.5",IF(G37="GVM","41.5",IF(G37="GVL","50",IF(G37="PCS","45.8",IF(G37="PCM","50",IF(G37="PCL","58.3","0")))))) -> 0
A38: =A37+1 -> 27 | J38: =IF(G38="RSL","55","0") -> 0 | K38: =IF(G38="GVS","37.5",IF(G38="GVM","41.5",IF(G38="GVL","50",IF(G38="PCS","45.8",IF(G38="PCM","50",IF(G38="PCL","58.3","0")))))) -> 0
A39: =A38+1 -> 28 | J39: =IF(G39="RSL","55","0") -> 0 | K39: =IF(G39="GVS","37.5",IF(G39="GVM","41.5",IF(G39="GVL","50",IF(G39="PCS","45.8",IF(G39="PCM","50",IF(G39="PCL","58.3","0")))))) -> 0
A40: =A39+1 -> 29 | J40: =IF(G40="RSL","55","0") -> 0 | K40: =IF(G40="GVS","37.5",IF(G40="GVM","41.5",IF(G40="GVL","50",IF(G40="PCS","45.8",IF(G40="PCM","50",IF(G40="PCL","58.3","0")))))) -> 0
A41: =A40+1 -> 30 | J41: =IF(G41="RSL","55","0") -> 0 | K41: =IF(G41="GVS","37.5",IF(G41="GVM","41.5",IF(G41="GVL","50",IF(G41="PCS","45.8",IF(G41="PCM","50",IF(G41="PCL","58.3","0")))))) -> 0
A42: =A41+1 -> 31 | J42: =IF(G42="RSL","55","0") -> 0 | K42: =IF(G42="GVS","37.5",IF(G42="GVM","41.5",IF(G42="GVL","50",IF(G42="PCS","45.8",IF(G42="PCM","50",IF(G42="PCL","58.3","0")))))) -> 0
...

Sheet FRI
A1: B2 Daily Report
A2: 45202 | H2: WEATHER | J2: SUNNY | L2: REPORT BY | O2: HENDRA | R2: TOTAL STAFF | T2: 5 | X2: Merchant machine usage at B2 | AA2: Settle amount | AI2: Merchant machine usage at GA | AL2: Settle amount
A4: No | B4: Docket No | C4: Reg No | D4: Mobile | E4: Gender | F4: TIME | G4: Service | H4: CASH | I4: CARD | J4: RSL | K4: GV | L4: GV CASH | M4: GV CARD | N4: O/Taker | O4: Comment | R4: NAME | S4: Time In | T4: Time out | U4: Total Hours | Z4: B2 machine | AA4: BLH machine | AB4: Wongo | AE4: B2 machine | AF4: BLH machine | AG4: Wongo | AK4: GA machine | AL4: BLH machine | AM4: Wongo | AP4: GA machine | AQ4: BLH machine | AR4: Wongo
A5: 1 | B5: 14203 | C5: EUH92M | D5: 0413723556 | E5: F | F5: 815 | G5: X | H5: 95 | J5: =IF(G5="RSL","55","0") -> 0 | K5: =IF(G5="GVS","37.5",IF(G5="GVM","41.5",IF(G5="GVL","50",IF(G5="PCS","45.8",IF(G5="PCM","50",IF(G5="PCL","58.3","0")))))) -> 0 | N5: HENDRA | R5: HENDRA | S5: 0.33333333 | T5: 0.70833333 | U5: =(T5-S5)*24 -> 9 | X5: NOV | Y5: 1 | AD5: 16 | AI5: NOV | AJ5: 1 | AO5: 16
A6: 2 | B6: 14204 | C6: YGH59W | D6: 0409714867 | E6: F | F6: 850 | G6: H | H6: 120 | J6: =IF(G6="RSL","55","0") -> 0 | K6: =IF(G6="GVS","37.5",IF(G6="GVM","41.5",IF(G6="GVL","50",IF(G6="PCS","45.8",IF(G6="PCM","50",IF(G6="PCL","58.3","0")))))) -> 0 | N6: HENDRA | R6: KUROSH | S6: 0.375 | T6: 0.70833333 | U6: =(T6-S6)*24 -> 8 | W6: M | Y6: 2 | AD6: 17 | AJ6: 2 | AO6: 17
A7: 3 | B7: 14205 | C7: DYM17V | D7: 0409246512 | E7: F | F7: 900 | G7: X | I7: 95 | J7: =IF(G7="RSL","55","0") -> 0 | K7: =IF(G7="GVS","37.5",IF(G7="GVM","41.5",IF(G7="GVL","50",IF(G7="PCS","45.8",IF(G7="PCM","50",IF(G7="PCL","58.3","0")))))) -> 0 | N7: HENDRA | R7: KADAM | S7: 0.375 | T7: 0.70833333 | U7: =(T7-S7)*24 -> 8 | W7: F | Y7: 3 | AD7: 18 | AJ7: 3 | AO7: 18
A8: 4 | B8: 14206 | C8: COM84M | D8: 0405232880 | E8: F | F8: 930 | G8: PCL | J8: =IF(G8="RSL","55","0") -> 0 | K8: 79.16 | M8: 475 | N8: HENDRA | O8: 22022(5/6), 23228(NEW) | R8: VINNY | S8: 0.41666667 | T8: 0.70833333 | U8: =(T8-S8)*24 -> 7 | Y8: 4 | AD8: 19 | AJ8: 4 | AO8: 19
A9: 5 | B9: 14207 | C9: EHV664 | D9: 0425774597 | E9: F | F9: 930 | G9: H | I9: 120 | J9: =IF(G9="RSL","55","0") -> 0 | K9: =IF(G9="GVS","37.5",IF(G9="GVM","41.5",IF(G9="GVL","50",IF(G9="PCS","45.8",IF(G9="PCM","50",IF(G9="PCL","58.3","0")))))) -> 0 | N9: HENDRA | R9: MODI | S9: 0.41666667 | T9: 0.70833333 | U9: =(T9-S9)*24 -> 7 | X9: EXCL RSL | Y9: 5 | AD9: 20 | AJ9: 5 | AO9: 20
A10: 6 | B10: 14208 | C10: ENI61G | D10: 0451513051 | E10: M | F10: 950 | G10: D | I10: 75 | J10: =IF(G10="RSL","55","0") -> 0 | K10: =IF(G10="GVS","37.5",IF(G10="GVM","41.5",IF(G10="GVL","50",IF(G10="PCS","45.8",IF(G10="PCM","50",IF(G10="PCL","58.3","0")))))) -> 0 | N10: HENDRA | O10: TAX | R10: ANDREW OCTEC | S10: 0.54166667 | T10: 0.70833333 | U10: =(T10-S10)*24 -> 4 | Y10: 6 | AD10: 21 | AJ10: 6 | AO10: 21
A11: 7 | B11: 14209 | C11: BZB84A | D11: 0408969223 | E11: F | F11: 1015 | G11: D | H11: 55 | J11: =IF(G11="RSL","55","0") -> 0 | K11: =IF(G11="GVS","37.5",IF(G11="GVM","41.5",IF(G11="GVL","50",IF(G11="PCS","45.8",IF(G11="PCM","50",IF(G11="PCL","58.3","0")))))) -> 0 | N11: HENDRA | U11: =(T11-S11)*24 -> 0 | Y11: 7 | AD11: 22 | AJ11: 7 | AO11: 22
A12: 8 | B12: 14210 | C12: NBU59C | D12: 0433818333 | E12: F | F12: 1030 | G12: X | H12: 90 | J12: =IF(G12="RSL","55","0") -> 0 | K12: =IF(G12="GVS","37.5",IF(G12="GVM","41.5",IF(G12="GVL","50",IF(G12="PCS","45.8",IF(G12="PCM","50",IF(G12="PCL","58.3","0")))))) -> 0 | N12: HENDRA | O12: $5 OFF | U12: =(T12-S12)*24 -> 0 | Y12: 8 | AD12: 23 | AJ12: 8 | AO12: 23
A13: 9 | B13: 14211 | C13: BVS27Y | D13: 0434979126 | E13: F | F13: 1100 | G13: H | H13: 120 | J13: =IF(G13="RSL","55","0") -> 0 | K13: =IF(G13="GVS","37.5",IF(G13="GVM","41.5",IF(G13="GVL","50",IF(G13="PCS","45.8",IF(G13="PCM","50",IF(G13="PCL","58.3","0")))))) -> 0 | N13: HENDRA | O13: TAX | U13: =(T13-S13)*24 -> 0 | Y13: 9 | AD13: 24 | AJ13: 9 | AO13: 24
A14: 10 | B14: 14212 | C14: DBF89P | D14: 0419694780 | E14: F | F14: 1115 | G14: X | I14: 75 | J14: =IF(G14="RSL","55","0") -> 0 | K14: =IF(G14="GVS","37.5",IF(G14="GVM","41.5",IF(G14="GVL","50",IF(G14="PCS","45.8",IF(G14="PCM","50",IF(G14="PCL","58.3","0")))))) -> 0 | N14: HENDRA | U14: =(T14-S14)*24 -> 0 | Y14: 10 | AD14: 25 | AJ14: 10 | AO14: 25
A15: 11 | B15: 14213 | C15: BGS53V | D15: ???? | E15: F | F15: 1115 | G15: GV | J15: =IF(G15="RSL","55","0") -> 0 | K15: 0 | L15: 350 | N15: VINNY | O15: XD50-381-387 | U15: =(T15-S15)*24 -> 0 | Y15: 11 | AD15: 26 | AJ15: 11 | AO15: 26
A16: 12 | B16: 14214 | C16: EOT07F | D16: 0425337813 | E16: F | F16: 1130 | G16: D | I16: 75 | J16: =IF(G16="RSL","55","0") -> 0 | K16: =IF(G16="GVS","37.5",IF(G16="GVM","41.5",IF(G16="GVL","50",IF(G16="PCS","45.8",IF(G16="PCM","50",IF(G16="PCL","58.3","0")))))) -> 0 | N16: HENDRA | R16: =H32/U16 -> 0.44186047 | S16: =H32/(U16-U5) -> 0.55882353 | T16: =C32/U16 -> 35.852558 | U16: =SUM(U5:U15) -> 43 | Y16: 12 | AD16: 27 | AJ16: 12 | AO16: 27
A17: 13 | B17: 14215 | C17: DDH59A | D17: 0403878036 | E17: F | F17: 1145 | G17: H | I17: 100 | J17: =IF(G17="RSL","55","0") -> 0 | K17: =IF(G17="GVS","37.5",IF(G17="GVM","41.5",IF(G17="GVL","50",IF(G17="PCS","45.8",IF(G17="PCM","50",IF(G17="PCL","58.3","0")))))) -> 0 | N17: HENDRA | R17: Cars/T Hr ① | S17: Cars/T Hr ② | T17: Sales/T Hr | U17: Total Hours | Y17: 13 | AD17: 28 | AJ17: 13 | AO17: 28
A18: 14 | B18: 14216 | C18: WSC44P | D18: 0414130777 | E18: F | F18: 1145 | G18: PCS | J18: =IF(G18="RSL","55","0") -> 0 | K18: 62.5 | N18: HENDRA | O18: 22063(2/6) | R18: ITEM | S18: QTY | T18: AMT | U18: RMKS | Y18: 14 | AD18: 29 | AJ18: 14 | AO18: 29
A19: 15 | B19: 14217 | C19: EIF04E | D19: 0406751366 | E19: F | F19: 1220 | G19: X | H19: 95 | J19: =IF(G19="RSL","55","0") -> 0 | K19: =IF(G19="GVS","37.5",IF(G19="GVM","41.5",IF(G19="GVL","50",IF(G19="PCS","45.8",IF(G19="PCM","50",IF(G19="PCL","58.3","0")))))) -> 0 | N19: VINNY | R19: GV | S19: =COUNT(L5:M29,L37:M61,L69:M93) -> 2 | T19: =SUM(L5:M29,L37:M61,L69:M93) -> 825 | Y19: 15 | AD19: 30 | AJ19: 15 | AO19: 30
A20: 16 | B20: 14218 | C20: DVF41S | D20: 0410742080 | E20: F | F20: 1235 | G20: RSL | J20: 60 | K20: =IF(G20="GVS","37.5",IF(G20="GVM","41.5",IF(G20="GVL","50",IF(G20="PCS","45.8",IF(G20="PCM","50",IF(G20="PCL","58.3","0")))))) -> 0 | N20: HENDRA | O20: CRSL20-011/016/039 (X) | AD20: 31 | AO20: 31
A21: 17 | B21: 14219 | C21: KBS888 | D21: 0431448778 | E21: M | F21: 1345 | G21: D | I21: 55 | J21: =IF(G21="RSL","55","0") -> 0 | K21: =IF(G21="GVS","37.5",IF(G21="GVM","41.5",IF(G21="GVL","50",IF(G21="PCS","45.8",IF(G21="PCM","50",IF(G21="PCL","58.3","0")))))) -> 0 | N21: HENDRA
A22: 18 | B22: 14220 | C22: EMB75G | D22: 0425973686 | E22: F | F22: 1510 | G22: X | I22: 95 | J22: =IF(G22="RSL","55","0") -> 0 | K22: =IF(G22="GVS","37.5",IF(G22="GVM","41.5",IF(G22="GVL","50",IF(G22="PCS","45.8",IF(G22="PCM","50",IF(G22="PCL","58.3","0")))))) -> 0 | N22: VINNY | AD22: Total | AE22: =SUM(Z5:Z19,AE5:AE20) -> 0 | AF22: =SUM(AA5:AA19,AF5:AF20,) -> 0 | AG22: =SUM(AB5:AB19,AG5:AG20) -> 0 | AO22: Total | AP22: =SUM(AK5:AK19,AP5:AP20) -> 0 | AQ22: =SUM(AL5:AL19,AQ5:AQ20,) -> 0 | AR22: =SUM(AM5:AM19,AR5:AR20) -> 0
A23: 19 | B23: 14221 | C23: CDF80J | D23: 0413809541 | E23: F | F23: 1515 | G23: X | I23: 75 | J23: =IF(G23="RSL","55","0") -> 0 | K23: =IF(G23="GVS","37.5",IF(G23="GVM","41.5",IF(G23="GVL","50",IF(G23="PCS","45.8",IF(G23="PCM","50",IF(G23="PCL","58.3","0")))))) -> 0 | N23: HENDRA
A24: 20 | J24: =IF(G24="RSL","55","0") -> 0 | K24: =IF(G24="GVS","37.5",IF(G24="GVM","41.5",IF(G24="GVL","50",IF(G24="PCS","45.8",IF(G24="PCM","50",IF(G24="PCL","58.3","0")))))) -> 0 | R24: SMALL | S24: MEDIUM | T24: LARGE | U24: TOTAL | AD24: B2/GA TOTAL | AE24: B2 machine | AF24: GA machine | AG24: BLH machine | AH24: Wongo machine | AI24: Sub total
A25: 21 | J25: =IF(G25="RSL","55","0") -> 0 | K25: =IF(G25="GVS","37.5",IF(G25="GVM","41.5",IF(G25="GVL","50",IF(G25="PCS","45.8",IF(G25="PCM","50",IF(G25="PCL","58.3","0")))))) -> 0 | R25: =COUNTIF(G5:G29,"GV1")+COUNTIF(G37:G61,"GV1")+COUNTIF(G69:G93,"GV1") -> 0 | S25: =COUNTIF(G5:G29,"GV2")+COUNTIF(G37:G61,"GV2")+COUNTIF(G69:G93,"GV2") -> 0 | T25: =COUNTIF(G5:G29,"GV3")+COUNTIF(G37:G61,"GV3")+COUNTIF(G69:G93,"GV3") -> 0 | U25: =((C32+(R26+S26+T26)*0.5)) -> 1541.66 | AD25: =SUM(AE25:AF25) -> 0 | AE25: =SUM(AE22) -> 0 | AF25: =SUM(AP22) -> 0 | AG25: =SUM(AF22+AQ22) -> 0 | AH25: =AG22+AR22 -> 0 | AI25: =SUM(AE25:AH25) -> 0
A26: 22 | J26: =IF(G26="RSL","55","0") -> 0 | K26: =IF(G26="GVS","37.5",IF(G26="GVM","41.5",IF(G26="GVL","50",IF(G26="PCS","45.8",IF(G26="PCM","50",IF(G26="PCL","58.3","0")))))) -> 0 | R26: =R25*37.5 -> 0 | S26: =S25*41.5 -> 0 | T26: =T25*50 -> 0 | X26: Branch cards
A27: 23 | J27: =IF(G27="RSL","55","0") -> 0 | K27: =IF(G27="GVS","37.5",IF(G27="GVM","41.5",IF(G27="GVL","50",IF(G27="PCS","45.8",IF(G27="PCM","50",IF(G27="PCL","58.3","0")))))) -> 0 | R27: Expense | X27: 1 | Z27: -2745
A28: 24 | J28: =IF(G28="RSL","55","0") -> 0 | K28: =IF(G28="GVS","37.5",IF(G28="GVM","41.5",IF(G28="GVL","50",IF(G28="PCS","45.8",IF(G28="PCM","50",IF(G28="PCL","58.3","0")))))) -> 0 | X28: 2
A29: 25 | J29: =IF(G29="RSL","55","0") -> 0 | K29: =IF(G29="GVS","37.5",IF(G29="GVM","41.5",IF(G29="GVL","50",IF(G29="PCS","45.8",IF(G29="PCM","50",IF(G29="PCL","58.3","0")))))) -> 0 | X29: 3
A30: Page total | H30: =SUM(H5:H29) -> 575 | I30: =SUM(I5:I29) -> 765 | J30: =J5+J6+J7+J8+J9+J10+J11+J12+J13+J14+J15+J16+J18+J19+J17+J20+J22+J23+J21+J24+J25+J26+J27+J28+J29 -> 60 | K30: =K5+K6+K7+K8+K9+K10+K11+K12+K13+K14+K15+K16+K18+K19+K17+K20+K22+K23+K21+K24+K25+K26+K27+K28+K29 -> 141.66 | L30: =SUM(L5:L29) -> 350 | M30: =SUM(M5:M29) -> 475 | N30: CASH | O30: CARD | P30: GV | Q30: RSL | X30: 4
A31: Daily Total | H31: =H30+H62+H94 -> 575 | I31: =I30+I62+I94 -> 765 | J31: =J30+J62+J94 -> 60 | K31: =K30+K62+K94 -> 141.66 | L31: =L30+L62+L94 -> 350 | M31: =M30+M62+M94 -> 475 | N31: =COUNT(H5:H29,H37:H61,H69:H93) -> 6 | O31: =COUNT(I5:I29,I37:I61,I69:I93) -> 9 | P31: =COUNTIF(G5:G29,"G*")+COUNTIF(G37:G61,"G*")+COUNTIF(G69:G93,"G*")+COUNTIF(G5:G29,"P*")+COUNTIF(G37:G61,"P*")+COUNTIF(G69:G93,"P*") -> 3 | Q31: =COUNTIF(G5:G29,"RSL")+COUNTIF(G37:G61,"RSL")+COUNTIF(G69:G93,"RSL") -> 1 | R31: CASH CLOSING | S31: =H31+L31-U28-U29-U30 -> 925 | T31: =H31+I31+L31+M31 -> 2165 | X31: Subtotal | Z31: =SUM(Z27:Z30) -> -2745
A32: TOTAL SALES | C32: =H31+I31+J31+K31 -> 1541.66 | F32: No of Cars | H32: =COUNT(B5:B29,B37:B61,B69:B93) -> 19 | I32: Average | K32: =C32/H32 -> 81.14 | N32: =H31/C32 -> 0.37297459 | O32: =I31/C32 -> 0.49621836 | P32: =K31/C32 -> 0.091887965 | Q32: =J31/C32 -> 0.038919087 | R32: CARD CLOSING | S32: =I31+M31 -> 1240 | X32: B2 card | Z32: =I31 -> 765
A33: Daily Report | X33: Settlement | Z33: =SUM(Z31:Z32) -> -1980
A34: =A2 -> 45202 | H34: WEATHER | J34: =J2 -> SUNNY | L34: REPORT by | O34: =O2 -> HENDRA | R34: TOTAL STAFF | T34: =T2 -> 5
A36: No | B36: Docket No | C36: Reg No | D36: Mobile | E36: Gender | F36: TIME | G36: Service | H36: CASH | I36: CARD | J36: RSL | K36: GV | L36: GV CASH | M36: GV CARD | N36: O/Taker | O36: Comment | R36: NAME | S36: Time In | T36: Time out | U36: Total Hours
A37: =A29+1 -> 26 | J37: =IF(G37="RSL","55","0") -> 0 | K37: =IF(G37="GVS","37.5",IF(G37="GVM","41.5",IF(G37="GVL","50",IF(G37="PCS","45.8",IF(G37="PCM","50",IF(G37="PCL","58.3","0")))))) -> 0
A38: =A37+1 -> 27 | J38: =IF(G38="RSL","55","0") -> 0 | K38: =IF(G38="GVS","37.5",IF(G38="GVM","41.5",IF(G38="GVL","50",IF(G38="PCS","45.8",IF(G38="PCM","50",IF(G38="PCL","58.3","0")))))) -> 0
A39: =A38+1 -> 28 | J39: =IF(G39="RSL","55","0") -> 0 | K39: =IF(G39="GVS","37.5",IF(G39="GVM","41.5",IF(G39="GVL","50",IF(G39="PCS","45.8",IF(G39="PCM","50",IF(G39="PCL","58.3","0")))))) -> 0
A40: =A39+1 -> 29 | J40: =IF(G40="RSL","55","0") -> 0 | K40: =IF(G40="GVS","37.5",IF(G40="GVM","41.5",IF(G40="GVL","50",IF(G40="PCS","45.8",IF(G40="PCM","50",IF(G40="PCL","58.3","0")))))) -> 0
A41: =A40+1 -> 30 | J41: =IF(G41="RSL","55","0") -> 0 | K41: =IF(G41="GVS","37.5",IF(G41="GVM","41.5",IF(G41="GVL","50",IF(G41="PCS","45.8",IF(G41="PCM","50",IF(G41="PCL","58.3","0")))))) -> 0
A42: =A41+1 -> 31 | J42: =IF(G42="RSL","55","0") -> 0 | K42: =IF(G42="GVS","37.5",IF(G42="GVM","41.5",IF(G42="GVL","50",IF(G42="PCS","45.8",IF(G42="PCM","50",IF(G42="PCL","58.3","0")))))) -> 0
...

Sheet SAT
A1: B2 Daily Report
A2: 45233 | H2: WEATHER | J2: SUNNY | L2: REPORT BY | O2: HENDRA | R2: TOTAL STAFF | T2: 7 | X2: Merchant machine usage at B2 | AA2: Settle amount | AI2: Merchant machine usage at GA | AL2: Settle amount
